Workbook

Sheet GAS FURNACES
B1: GAS FURNACES
E2: 46000
B3: Part Number | C3: Ferguson Part Number | D3: Price | E3: Product Category
A4: EVOLUTION 98% VARIABLE SPEED MODULATING FURNACE | B4: 987MC42060C17 | C4: B987MC42060C17 | D4: =VLOOKUP(C4,'Paste bid here'!A:F,4,FALSE) -> #N/A | E4: BEST
B5: 987MC42080C17 | C5: B987MC42080C17 | D5: =VLOOKUP(C5,'Paste bid here'!A:F,4,FALSE) -> #N/A
B6: 987MC60060C21 | C6: B987MC60060C21 | D6: =VLOOKUP(C6,'Paste bid here'!A:F,4,FALSE) -> #N/A
B7: 987MC60080C21 | C7: B987MC60080C21 | D7: =VLOOKUP(C7,'Paste bid here'!A:F,4,FALSE) -> #N/A
B8: 987MC66100C21 | C8: B987MC66100C21 | D8: =VLOOKUP(C8,'Paste bid here'!A:F,4,FALSE) -> #N/A
B9: 987MC66120C24 | C9: B987MC66120C24 | D9: =VLOOKUP(C9,'Paste bid here'!A:F,4,FALSE) -> #N/A
A10: EVOLUTION 97% VARIABLE SPEED 2-STAGE FURNACE | B10: 987TA48060C17 | C10: B987TA48060C17 | D10: =VLOOKUP(C10,'Paste bid here'!A:F,4,FALSE) -> #N/A
B11: 987TA48080C17 | C11: B987TA48080C17 | D11: =VLOOKUP(C11,'Paste bid here'!A:F,4,FALSE) -> #N/A
B12: 987TA60080C21 | C12: B987TA60080C21 | D12: =VLOOKUP(C12,'Paste bid here'!A:F,4,FALSE) -> #N/A
B13: 987TA66100C21 | C13: B987TA66100C21 | D13: =VLOOKUP(C13,'Paste bid here'!A:F,4,FALSE) -> #N/A
B14: 987TA66120C24 | C14: B987TA66120C24 | D14: =VLOOKUP(C14,'Paste bid here'!A:F,4,FALSE) -> #N/A
A15: EVOLUTION 96% VARIABLE SPEED 2-STAGE FURNACE (SELL THESE FIRST) | B15: 986TD30040C14 | C15: B986TD30040C14 | D15: =VLOOKUP(C15,'Paste bid here'!A:F,4,FALSE) -> #N/A
B16: 986TD42060C17 | C16: B986TD42060C17 | D16: =VLOOKUP(C16,'Paste bid here'!A:F,4,FALSE) -> #N/A
B17: 986TD42080C17 | C17: B986TD42080C17 | D17: =VLOOKUP(C17,'Paste bid here'!A:F,4,FALSE) -> #N/A
B18: 986TD60080C21 | C18: B986TD60080C21 | D18: =VLOOKUP(C18,'Paste bid here'!A:F,4,FALSE) -> #N/A
B19: 986TD66100C21 | C19: B986TD66100C21 | D19: =VLOOKUP(C19,'Paste bid here'!A:F,4,FALSE) -> #N/A
B20: 986TD66120C24 | C20: B986TD66120C24 | D20: =VLOOKUP(C20,'Paste bid here'!A:F,4,FALSE) -> #N/A
A21: PREFERRED 97% 2-STAGE VARIABLE SPEED FURNACE W/ INTELISENSE | B21: 927TA48060V17 | C21: B927TA48060V17 | D21: =VLOOKUP(C21,'Paste bid here'!A:F,4,FALSE) -> #N/A | E21: BETTER
B22: 927TA48080V17 | C22: B927TA48080V17 | D22: =VLOOKUP(C22,'Paste bid here'!A:F,4,FALSE) -> #N/A
B23: 927TA60080V21 | C23: B927TA60080V21 | D23: =VLOOKUP(C23,'Paste bid here'!A:F,4,FALSE) -> #N/A
B24: 927TA60100V21 | C24: B927TA60100V21 | D24: =VLOOKUP(C24,'Paste bid here'!A:F,4,FALSE) -> #N/A
B25: 927TA66120V24 | C25: B927TA66120V24 | D25: =VLOOKUP(C25,'Paste bid here'!A:F,4,FALSE) -> #N/A
A26: PREFERRED 96% 2-STAGE VARIABLE SPEED FURNACE W/ INTELISENSE (SELL THESE FIRST) | B26: 926TC30040V14 | C26: B926TC30040V14 | D26: =VLOOKUP(C26,'Paste bid here'!A:F,4,FALSE) -> #N/A
B27: 926TC36040V17 | C27: B926TC36040V17 | D27: =VLOOKUP(C27,'Paste bid here'!A:F,4,FALSE) -> #N/A
B28: 926TC36060V14 | C28: B926TC36060V14 | D28: =VLOOKUP(C28,'Paste bid here'!A:F,4,FALSE) -> #N/A
B29: 926TC48060V17 | C29: B926TC48060V17 | D29: =VLOOKUP(C29,'Paste bid here'!A:F,4,FALSE) -> #N/A
B30: 926TC48080V17 | C30: B926TC48080V17 | D30: =VLOOKUP(C30,'Paste bid here'!A:F,4,FALSE) -> #N/A
B31: 926TC60080V21 | C31: B926TC60080V21 | D31: =VLOOKUP(C31,'Paste bid here'!A:F,4,FALSE) -> #N/A
B32: 926TC60100V21 | C32: B926TC60100V21 | D32: =VLOOKUP(C32,'Paste bid here'!A:F,4,FALSE) -> #N/A
B33: 926TC66100V21 | C33: B926TC66100V21 | D33: =VLOOKUP(C33,'Paste bid here'!A:F,4,FALSE) -> #N/A
B34: 926TC66120V24 | C34: B926TC66120V24 | D34: =VLOOKUP(C34,'Paste bid here'!A:F,4,FALSE) -> #N/A
A35: LEGACY 96% 1-STAGE FURNACE | B35: 916SA30026M14 | C35: B916SA30026M14 | D35: =VLOOKUP(C35,'Paste bid here'!A:F,4,FALSE) -> #N/A | E35: GOOD
B36: 916SA30040M14 | C36: B916SA30040M14 | D36: =VLOOKUP(C36,'Paste bid here'!A:F,4,FALSE) -> #N/A
B37: 916SA36040M17 | C37: B916SA36040M17 | D37: =VLOOKUP(C37,'Paste bid here'!A:F,4,FALSE) -> #N/A
B38: 916SA36060M14 | C38: B916SA36060M14 | D38: =VLOOKUP(C38,'Paste bid here'!A:F,4,FALSE) -> #N/A
B39: 916SA48060M17 | C39: B916SA48060M17 | D39: =VLOOKUP(C39,'Paste bid here'!A:F,4,FALSE) -> #N/A
B40: 916SA48080M17 | C40: B916SA48080M17 | D40: =VLOOKUP(C40,'Paste bid here'!A:F,4,FALSE) -> #N/A
...

Sheet FAN COILS & HEAT STRIPS
B1: FAN COILS
E2: 46000
B3: Part Number | C3: Ferguson Part Number | D3: Price | E3: Product Category
A4: R454B EVOLUTION SERIES COMMUNICATING FAN COIL | B4: FE5BNXB24L00 | C4: CFE5BNXB24L00 | D4: =VLOOKUP(C6,'Paste bid here'!A:F,4,FALSE) -> #N/A | E4: BEST
B5: FE5BNXC36L00 | C5: CFE5BNXC36L00 | D5: =VLOOKUP(C8,'Paste bid here'!A:F,4,FALSE) -> #N/A | E5: *Use Slope Coil Downflow Kit
B6: FE5BNBC36L00 | C6: CFE5BNBC36L00 | D6: =VLOOKUP(C9,'Paste bid here'!A:F,4,FALSE) -> #N/A | E6: *FE5BNB MODELS ARE MODULAR 2-PIECE CABINET DESIGN
B7: FE5BNXC48L00 | C7: CFE5BNXC48L00 | D7: =VLOOKUP(C4,'Paste bid here'!A:F,4,FALSE) -> #N/A | E7: *FE5BNX MODELS ARE 1-PIECE CABINET DESIGN
B8: FE5BNBC48L00 | C8: CFE5BNBC48L00 | D8: =VLOOKUP(C5,'Paste bid here'!A:F,4,FALSE) -> #N/A
B9: FE5BNBD60L00 | C9: CFE5BNBD60L00 | D9: =VLOOKUP(C7,'Paste bid here'!A:F,4,FALSE) -> #N/A
A10: R454B PREFERRED SERIES VARIABLE SPEED FAN COIL | B10: FT5ANXB24L00 | C10: CFT5ANXB24L00 | D10: =VLOOKUP(C10,'Paste bid here'!A:F,4,FALSE) -> #N/A | E10: BETTER
B11: FT5ANBC36L00 | C11: CFT5ANBC36L00 | D11: =VLOOKUP(C11,'Paste bid here'!A:F,4,FALSE) -> #N/A | E11: *Use Slope Coil Downflow Kit
B12: FT5ANBC48L00 | C12: CFT5ANBC48L00 | D12: =VLOOKUP(C12,'Paste bid here'!A:F,4,FALSE) -> #N/A | E12: *FT5ANB MODELS ARE MODULAR 2-PIECE CABINET DESIGN
B13: FT5ANBD60L00 | C13: CFT5ANBD60L00 | D13: =VLOOKUP(C13,'Paste bid here'!A:F,4,FALSE) -> #N/A | E13: *FT5ANX MODELS ARE 1-PIECE CABINET DESIGN
A14: R454B LEGACY SERIES FAN COIL | B14: FJ5ANXA18L00 | C14: CFJ5ANXA18L00 | D14: =VLOOKUP(C14,'Paste bid here'!A:F,4,FALSE) -> #N/A | E14: GOOD
B15: FJ5ANXB24L00 | C15: CFJ5ANXB24L00 | D15: =VLOOKUP(C15,'Paste bid here'!A:F,4,FALSE) -> #N/A | E15: *Use Slope Coil Downflow Kit
B16: FJ5ANXB30L00 | C16: CFJ5ANXB30L00 | D16: =VLOOKUP(C16,'Paste bid here'!A:F,4,FALSE) -> #N/A
B17: FJ5ANXB36L00 | C17: CFJ5ANXB36L00 | D17: =VLOOKUP(C17,'Paste bid here'!A:F,4,FALSE) -> #N/A
B18: FJ5ANXC42L00 | C18: CFJ5ANXC42L00 | D18: =VLOOKUP(C18,'Paste bid here'!A:F,4,FALSE) -> #N/A
B19: FJ5ANXC48L00 | C19: CFJ5ANXC48L00 | D19: =VLOOKUP(C19,'Paste bid here'!A:F,4,FALSE) -> #N/A
B20: FJ5ANXD60L00 | C20: CFJ5ANXD60L00 | D20: =VLOOKUP(C20,'Paste bid here'!A:F,4,FALSE) -> #N/A
A21: UNITARY STRIP HEAT FOR FJ, FT, FE4 & FE5 FAN COILS | B21: FF-2401C05 | C21: TFF2401C05 | D21: =VLOOKUP(C21,'Paste bid here'!A:F,4,FALSE) -> #N/A | E21: 5kW sizes 24-60
B22: FF-2501C08 | C22: TFF2501C08 | D22: =VLOOKUP(C22,'Paste bid here'!A:F,4,FALSE) -> #N/A | E22: 8kW sizes 24-60
B23: FF-2601C10 | C23: TFF2601C10 | D23: =VLOOKUP(C23,'Paste bid here'!A:F,4,FALSE) -> #N/A | E23: 10kW sizes 24-60
B24: FF-3101C15 | C24: TFF3101C15 | D24: =VLOOKUP(C24,'Paste bid here'!A:F,4,FALSE) -> #N/A | E24: 15kW sizes 24-60
B25: FF-3301C20 | C25: TFF3301C20 | D25: =VLOOKUP(C25,'Paste bid here'!A:F,4,FALSE) -> #N/A | E25: 20kW sizes 30-60
B26: FF-8401C05 | C26: TFF8401C05 | D26: =VLOOKUP(C26,'Paste bid here'!A:F,4,FALSE) -> #N/A | E26: 5kW size 18 ONLY
B27: FF-8501C08 | C27: TFF8501C08 | D27: =VLOOKUP(C27,'Paste bid here'!A:F,4,FALSE) -> #N/A | E27: 10kW size 18 ONLY
B28: FF-8601C10 | C28: TFF8601C10 | D28: =VLOOKUP(C28,'Paste bid here'!A:F,4,FALSE) -> #N/A | E28: 15kW size 18 ONLY
A29: Downflow Kits - Unitary Fan Coils | B29: KFADC0201SLP | C29: CKFADC0201SLP | D29: =VLOOKUP(C29,'Paste bid here'!A:F,4,FALSE) -> #N/A | E29: Downflow Kit - Slope Coil, FJ5 18-24, FE5/FT5 36
B30: KFADC0401ACL | C30: CKFADC0401ACL | D30: =VLOOKUP(C30,'Paste bid here'!A:F,4,FALSE) -> #N/A | E30: Downflow Kit - A Coil, FJ5 30-60, FE5/FT5 24,48,60
A31: CROSSOVER FAN COILS & HEAT STRIP KITS
A32: R454B CROSSOVER FAN COIL FOR USE W/ 37MUHA | B32: 45MUHAQ24XX3 | C32: C45MUHAQ24XX3 | D32: =VLOOKUP(C32,'Paste bid here'!A:F,4,FALSE) -> #N/A | E32: *Use EHKMD model heat strips
B33: 45MUHAQ36XX3 | C33: C45MUHAQ36XX3 | D33: =VLOOKUP(C33,'Paste bid here'!A:F,4,FALSE) -> #N/A | E33: *MODULAR 2 PIECE CABINET DESIGN
B34: 45MUHAQ60XX3 | C34: C45MUHAQ60XX3 | D34: =VLOOKUP(C34,'Paste bid here'!A:F,4,FALSE) -> #N/A | E34: *4" MEDIA FILTER RACK INCLUDED
E35: *5 TON FAN COIL IS 21" WIDTH
A36: R454B CROSSOVER FAN COIL FOR USE W/ 37MURA/37MUHA | B36: 45MUAAQ18XX3 | C36: C45MUAAQ18XX3 | D36: =VLOOKUP(C36,'Paste bid here'!A:F,4,FALSE) -> #N/A | E36: *SINGLE PIECE CABINET DESIGN
B37: 45MUAAQ24XX3 | C37: C45MUAAQ24XX3 | D37: =VLOOKUP(C37,'Paste bid here'!A:F,4,FALSE) -> #N/A | E37: *Use EHKMC model heat strips
B38: 45MUAAQ30XX3 | C38: C45MUAAQ30XX3 | D38: =VLOOKUP(C38,'Paste bid here'!A:F,4,FALSE) -> #N/A
B39: 45MUAAQ36XX3 | C39: C45MUAAQ36XX3 | D39: =VLOOKUP(C39,'Paste bid here'!A:F,4,FALSE) -> #N/A
B40: 45MUAAQ48XX3 | C40: C45MUAAQ48XX3 | D40: =VLOOKUP(C40,'Paste bid here'!A:F,4,FALSE) -> #N/A
...

Sheet EVAP COILS
B1: EVAP COILS
E2: 46000
B3: Part Number | C3: Ferguson Part Number | D3: Price
A4: R454B UPFLOW / DOWNFLOW CASED V COIL | B4: CVAVA1814XMA | C4: CCVAVA1814XMA | D4: =VLOOKUP(C4,'Paste bid here'!A:F,4,FALSE) -> #N/A
B5: CVAVA1917XMA | C5: CCVAVA1917XMA | D5: =VLOOKUP(C5,'Paste bid here'!A:F,4,FALSE) -> #N/A
B6: CVAVA2414XMA | C6: CCVAVA2414XMA | D6: =VLOOKUP(C6,'Paste bid here'!A:F,4,FALSE) -> #N/A
B7: CVAVA2417XMA | C7: CCVAVA2417XMA | D7: =VLOOKUP(C7,'Paste bid here'!A:F,4,FALSE) -> #N/A
B8: CVAVA2514XMA | C8: CCVAVA2514XMA | D8: =VLOOKUP(C8,'Paste bid here'!A:F,4,FALSE) -> #N/A
B9: CVAVA2517XMA | C9: CCVAVA2517XMA | D9: =VLOOKUP(C9,'Paste bid here'!A:F,4,FALSE) -> #N/A
B10: CVAVA3014XMA | C10: CCVAVA3014XMA | D10: =VLOOKUP(C10,'Paste bid here'!A:F,4,FALSE) -> #N/A
B11: CVAVA3017XMA | C11: CCVAVA3017XMA | D11: =VLOOKUP(C11,'Paste bid here'!A:F,4,FALSE) -> #N/A
B12: CVAVA3117XMA | C12: CCVAVA3117XMA | D12: =VLOOKUP(C12,'Paste bid here'!A:F,4,FALSE) -> #N/A
B13: CVAVA3617XMA | C13: CCVAVA3617XMA | D13: =VLOOKUP(C13,'Paste bid here'!A:F,4,FALSE) -> #N/A
B14: CVAVA3621XMA | C14: CCVAVA3621XMA | D14: =VLOOKUP(C14,'Paste bid here'!A:F,4,FALSE) -> #N/A
B15: CVAVA3721XMA | C15: CCVAVA3721XMA | D15: =VLOOKUP(C15,'Paste bid here'!A:F,4,FALSE) -> #N/A
B16: CVAVA3817XMA | C16: CCVAVA3817XMA | D16: =VLOOKUP(C16,'Paste bid here'!A:F,4,FALSE) -> #N/A
... B26: CVAVA6124XMA | C26: CCVAVA6124XMA | D26: =VLOOKUP(C26,'Paste bid here'!A:F,4,FALSE) -> #N/A
A27: R454B MULTIPOISE CASED V COIL | B27: CVAMA2414XMA | C27: CCVAMA2414XMA | D27: =VLOOKUP(C27,'Paste bid here'!A:F,4,FALSE) -> #N/A
B28: CVAMA2417XMA | C28: CCVAMA2417XMA | D28: =VLOOKUP(C28,'Paste bid here'!A:F,4,FALSE) -> #N/A
B29: CVAMA2517XMA | C29: CCVAMA2517XMA | D29: =VLOOKUP(C29,'Paste bid here'!A:F,4,FALSE) -> #N/A
B30: CVAMA3017XMA | C30: CCVAMA3017XMA | D30: =VLOOKUP(C30,'Paste bid here'!A:F,4,FALSE) -> #N/A
B31: CVAMA3117XMA | C31: CCVAMA3117XMA | D31: =VLOOKUP(C31,'Paste bid here'!A:F,4,FALSE) -> #N/A
B32: CVAMA3217XMA | C32: CCVAMA3217XMA | D32: =VLOOKUP(C32,'Paste bid here'!A:F,4,FALSE) -> #N/A
B33: CVAMA3617XMA | C33: CCVAMA3617XMA | D33: =VLOOKUP(C33,'Paste bid here'!A:F,4,FALSE) -> #N/A
B34: CVAMA4221XMA | C34: CCVAMA4221XMA | D34: =VLOOKUP(C34,'Paste bid here'!A:F,4,FALSE) -> #N/A
B35: CVAMA4321XMA | C35: CCVAMA4321XMA | D35: =VLOOKUP(C35,'Paste bid here'!A:F,4,FALSE) -> #N/A
B36: CVAMA4421XMA | C36: CCVAMA4421XMA | D36: =VLOOKUP(C36,'Paste bid here'!A:F,4,FALSE) -> #N/A
B37: CVAMA4821XMA | C37: CCVAMA4821XMA | D37: =VLOOKUP(C37,'Paste bid here'!A:F,4,FALSE) -> #N/A
B38: CVAMA4921XMA | C38: CCVAMA4921XMA | D38: =VLOOKUP(C38,'Paste bid here'!A:F,4,FALSE) -> #N/A
B39: CVAMA6021XMA | C39: CCVAMA6021XMA | D39: =VLOOKUP(C39,'Paste bid here'!A:F,4,FALSE) -> #N/A
... B41: CVAMA6124XMA | C41: CCVAMA6124XMA | D41: =VLOOKUP(C41,'Paste bid here'!A:F,4,FALSE) -> #N/A
A42: R454B MULTIPOISE CASED A COIL | B42: CAAMP1917AMA | C42: CCAAMP1917AMA | D42: =VLOOKUP(C42,'Paste bid here'!A:F,4,FALSE) -> #N/A
B43: CAAMP2414AMA | C43: CCAAMP2414AMA | D43: =VLOOKUP(C43,'Paste bid here'!A:F,4,FALSE) -> #N/A
B44: CAAMP2417AMA | C44: CCAAMP2417AMA | D44: =VLOOKUP(C44,'Paste bid here'!A:F,4,FALSE) -> #N/A
B45: CAAMP2517AMA | C45: CCAAMP2517AMA | D45: =VLOOKUP(C45,'Paste bid here'!A:F,4,FALSE) -> #N/A
B46: CAAMP3014AMA | C46: CCAAMP3014AMA | D46: =VLOOKUP(C46,'Paste bid here'!A:F,4,FALSE) -> #N/A
B47: CAAMP3017AMA | C47: CCAAMP3017AMA | D47: =VLOOKUP(C47,'Paste bid here'!A:F,4,FALSE) -> #N/A
B48: CAAMP3617AMA | C48: CCAAMP3617AMA | D48: =VLOOKUP(C48,'Paste bid here'!A:F,4,FALSE) -> #N/A
B49: CAAMP3717AMA | C49: CCVAMA6021XMA | D49: =VLOOKUP(C49,'Paste bid here'!A:F,4,FALSE) -> #N/A
B50: CAAMP3721AMA | C50: CCAAMP3721AMA | D50: =VLOOKUP(C50,'Paste bid here'!A:F,4,FALSE) -> #N/A
...

Sheet AIR CONDITIONERS
B1: AIR CONDITIONERS
E3: 46000
B4: Part Number | C4: Ferguson Part Number | D4: Price | E4: Product Category
A5: R454B EVOLUTION EXTREME V/S 21 SEER2 AC | B5: 191VAN02400W | C5: B191VAN02400W | D5: =VLOOKUP(C5,'Paste bid here'!A:F,4,FALSE) -> #N/A | E5: BEST
B6: 191VAN03600W | C6: B191VAN03600W | D6: =VLOOKUP(C6,'Paste bid here'!A:F,4,FALSE) -> #N/A
B7: 191VAN04800W | C7: B191VAN04800W | D7: =VLOOKUP(C7,'Paste bid here'!A:F,4,FALSE) -> #N/A
B8: 191VAN06000W | C8: B191VAN06000W | D8: =VLOOKUP(C8,'Paste bid here'!A:F,4,FALSE) -> #N/A
A9: R454B PREFERRED 18 SEER2 2-STAGE AC | B9: 148TAN02400W | C9: B148TAN02400W | D9: =VLOOKUP(C9,'Paste bid here'!A:F,4,FALSE) -> #N/A | E9: BETTER
B10: 148TAN03600W | C10: B148TAN03600W | D10: =VLOOKUP(C10,'Paste bid here'!A:F,4,FALSE) -> #N/A
B11: 148TAN04800W | C11: B148TAN04800W | D11: =VLOOKUP(C11,'Paste bid here'!A:F,4,FALSE) -> #N/A
B12: 148TAN06000W | C12: B148TAN06000W | D12: =VLOOKUP(C12,'Paste bid here'!A:F,4,FALSE) -> #N/A
A13: R454B INTELISENSE PREFERRED SERIES 16 SEER2 / 1-STAGE AC | B13: 146SAN01800W | C13: B146SAN01800W | D13: =VLOOKUP(C13,'Paste bid here'!A:F,4,FALSE) -> #N/A
B14: 146SAN02400W | C14: B146SAN02400W | D14: =VLOOKUP(C14,'Paste bid here'!A:F,4,FALSE) -> #N/A
B15: 146SAN03000W | C15: B146SAN03000W | D15: =VLOOKUP(C15,'Paste bid here'!A:F,4,FALSE) -> #N/A
B16: 146SAN03600W | C16: B146SAN03600W | D16: =VLOOKUP(C16,'Paste bid here'!A:F,4,FALSE) -> #N/A
B17: 146SAN04200W | C17: B146SAN04200W | D17: =VLOOKUP(C17,'Paste bid here'!A:F,4,FALSE) -> #N/A
B18: 146SAN04800W | C18: B146SAN04800W | D18: =VLOOKUP(C18,'Paste bid here'!A:F,4,FALSE) -> #N/A
B19: 146SAN06000W | C19: B146SAN06000W | D19: =VLOOKUP(C19,'Paste bid here'!A:F,4,FALSE) -> #N/A
A20: R454B LEGACY SERIES 14 SEER / 1-STAGE AC | B20: 134SAN01800N | C20: B134SAN01800N | D20: =VLOOKUP(C20,'Paste bid here'!A:F,4,FALSE) -> #N/A | E20: GOOD
B21: 134SAN02400N | C21: B134SAN02400N | D21: =VLOOKUP(C21,'Paste bid here'!A:F,4,FALSE) -> #N/A
B22: 134SAN03000N | C22: B134SAN03000N | D22: =VLOOKUP(C22,'Paste bid here'!A:F,4,FALSE) -> #N/A
B23: 134SAN03600N | C23: B134SAN03600N | D23: =VLOOKUP(C23,'Paste bid here'!A:F,4,FALSE) -> #N/A
B24: 134SAN04200N | C24: B134SAN04200N | D24: =VLOOKUP(C24,'Paste bid here'!A:F,4,FALSE) -> #N/A
B25: 134SAN04800N | C25: B134SAN04800N | D25: =VLOOKUP(C25,'Paste bid here'!A:F,4,FALSE) -> #N/A
B26: 134SAN06000N | C26: B134SAN06000N | D26: =VLOOKUP(C26,'Paste bid here'!A:F,4,FALSE) -> #N/A

Sheet HEAT PUMPS
B1: HEAT PUMPS
E2: 46000
B3: Part Number | C3: Ferguson Part Number | D3: Price | E3: Product Category
A4: R454B EVOLUTION EXTREME 23 SEER2 / INVERTER HEAT PUMP | B4: 293VAN02400A | C4: B293VAN02400A | D4: =VLOOKUP(C4,'Paste bid here'!A:F,4,FALSE) -> #N/A | E4: BEST
B5: 293VAN03600A | C5: B293VAN03600A | D5: =VLOOKUP(C5,'Paste bid here'!A:F,4,FALSE) -> #N/A
B6: 293VAN04800A | C6: B293VAN04800A | D6: =VLOOKUP(C6,'Paste bid here'!A:F,4,FALSE) -> #N/A
B7: 293VAN06000A | C7: B293VAN06000A | D7: =VLOOKUP(C7,'Paste bid here'!A:F,4,FALSE) -> #N/A
A8: R454B EVOLUTION EXTREME 20 SEEER2 / VARIABLE INVERTER HEAT PUMP | B8: 290VAN02400A | C8: B290VAN02400A | D8: =VLOOKUP(C8,'Paste bid here'!A:F,4,FALSE) -> #N/A
B9: 290VAN03600A | C9: B290VAN03600A | D9: =VLOOKUP(C9,'Paste bid here'!A:F,4,FALSE) -> #N/A
B10: 290VAN04800A | C10: B290VAN04800A | D10: =VLOOKUP(C10,'Paste bid here'!A:F,4,FALSE) -> #N/A
B11: 290VAN06000A | C11: B290VAN06000A | D11: =VLOOKUP(C11,'Paste bid here'!A:F,4,FALSE) -> #N/A
A12: CROSSOVER HEAT PUMP R454B HIGH HEAT PREFERRED SERIES 18 SEER INVERTER | B12: 37MUHAQ18AA3 | C12: C37MUHAQ18AA3 | D12: =VLOOKUP(C12,'Paste bid here'!A:F,4,FALSE) -> #N/A | E12: BETTER
B13: 37MUHAQ24AA3 | C13: C37MUHAQ24AA3 | D13: =VLOOKUP(C13,'Paste bid here'!A:F,4,FALSE) -> #N/A
B14: 37MUHAQ30AA3 | C14: C37MUHAQ30AA3 | D14: =VLOOKUP(C14,'Paste bid here'!A:F,4,FALSE) -> #N/A
B15: 37MUHAQ36AA3 | C15: C37MUHAQ36AA3 | D15: =VLOOKUP(C15,'Paste bid here'!A:F,4,FALSE) -> #N/A
B16: 37MUHAQ48AA3 | C16: C37MUHAQ48AA3 | D16: =VLOOKUP(C16,'Paste bid here'!A:F,4,FALSE) -> #N/A
B17: 37MUHAQ60AA3 | C17: C37MUHAQ60AA3 | D17: =VLOOKUP(C17,'Paste bid here'!A:F,4,FALSE) -> #N/A
A18: R454B INTELISENSE PREFERRED SERIES 18 SEER2 / 2-STAGE HEAT PUMP | B18: 248TAN02400A | C18: B248TAN02400A | D18: =VLOOKUP(C18,'Paste bid here'!A:F,4,FALSE) -> #N/A
B19: 248TAN03600A | C19: B248TAN03600A | D19: =VLOOKUP(C19,'Paste bid here'!A:F,4,FALSE) -> #N/A
B20: 248TAN04800A | C20: B248TAN04800A | D20: =VLOOKUP(C20,'Paste bid here'!A:F,4,FALSE) -> #N/A
B21: 248TAN06000A | C21: B248TAN06000A | D21: =VLOOKUP(C21,'Paste bid here'!A:F,4,FALSE) -> #N/A
A22: R454B INTELISENSE PREFERRED SERIES 16 SEER2 / 1-STAGE HEAT PUMP | B22: 246SAN01800A | C22: B246SAN01800A | D22: =VLOOKUP(C22,'Paste bid here'!A:F,4,FALSE) -> #N/A
B23: 246SAN02400A | C23: B246SAN02400A | D23: =VLOOKUP(C23,'Paste bid here'!A:F,4,FALSE) -> #N/A
B24: 246SAN03000A | C24: B246SAN03000A | D24: =VLOOKUP(C24,'Paste bid here'!A:F,4,FALSE) -> #N/A
B25: 246SAN03600A | C25: B246SAN03600A | D25: =VLOOKUP(C25,'Paste bid here'!A:F,4,FALSE) -> #N/A
B26: 246SAN04200A | C26: B246SAN04200A | D26: =VLOOKUP(C26,'Paste bid here'!A:F,4,FALSE) -> #N/A
B27: 246SAN04800A | C27: B246SAN04800A | D27: =VLOOKUP(C27,'Paste bid here'!A:F,4,FALSE) -> #N/A
B28: 246SAN06000A | C28: B246SAN06000A | D28: =VLOOKUP(C28,'Paste bid here'!A:F,4,FALSE) -> #N/A
A29: CROSSOVER HEAT PUMP R454B REGULAR HEAT LEGACY SERIES 18 SEER INVERTER | B29: 37MURAQ18AA3 | C29: C37MURAQ18AA3 | D29: =VLOOKUP(C29,'Paste bid here'!A:F,4,FALSE) -> #N/A | E29: GOOD
B30: 37MURAQ24AA3 | C30: C37MURAQ24AA3 | D30: =VLOOKUP(C30,'Paste bid here'!A:F,4,FALSE) -> #N/A
B31: 37MURAQ30AA3 | C31: C37MURAQ30AA3 | D31: =VLOOKUP(C31,'Paste bid here'!A:F,4,FALSE) -> #N/A
B32: 37MURAQ36AA3 | C32: C37MURAQ36AA3 | D32: =VLOOKUP(C32,'Paste bid here'!A:F,4,FALSE) -> #N/A
B33: 37MURAQ48AA3 | C33: C37MURAQ48AA3 | D33: =VLOOKUP(C33,'Paste bid here'!A:F,4,FALSE) -> #N/A
B34: 37MURAQ60AA3 | C34: C37MURAQ60AA3 | D34: =VLOOKUP(C34,'Paste bid here'!A:F,4,FALSE) -> #N/A
A35: R454B LEGACY SERIES 16 SEER2 / 1-STAGE HEAT PUMP | B35: 235SAN01800A | C35: B235SAN01800A | D35: =VLOOKUP(C35,'Paste bid here'!A:F,4,FALSE) -> #N/A
B36: 235SAN02400A | C36: B235SAN02400A | D36: =VLOOKUP(C36,'Paste bid here'!A:F,4,FALSE) -> #N/A
B37: 235SAN03000A | C37: B235SAN03000A | D37: =VLOOKUP(C37,'Paste bid here'!A:F,4,FALSE) -> #N/A
B38: 235SAN03600A | C38: B235SAN03600A | D38: =VLOOKUP(C38,'Paste bid here'!A:F,4,FALSE) -> #N/A
B39: 235SAN04200A | C39: B235SAN04200A | D39: =VLOOKUP(C39,'Paste bid here'!A:F,4,FALSE) -> #N/A
B40: 235SAN04800A | C40: B235SAN04800A | D40: =VLOOKUP(C40,'Paste bid here'!A:F,4,FALSE) -> #N/A
...

Sheet ACCESSORIES
B1: ACCESSORIES
E3: 46000
B4: Part Number | C4: Ferguson Part Number | D4: Price | E4: Product Description
A5: Evolution System Controls | B5: SYSTXBBECC01-B | C5: BSYSTXBBECC01C | D5: =VLOOKUP(C5,'Paste bid here'!A:F,4,FALSE) -> #N/A | E5: Evolution Control - Black
B6: SYSTXBBWEC01-B | C6: BSYSTXBBWEC01C | D6: =VLOOKUP(C6,'Paste bid here'!A:F,4,FALSE) -> #N/A | E6: Evolution Control - White
B7: TSTATBBEWF01 | C7: BTSTATBBEWF01 | D7: =VLOOKUP(C7,'Paste bid here'!A:F,4,FALSE) -> #N/A | E7: Bryant Smart Wifi Non-Communicating Thermostat
B8: SYSTXBB4ZC01 | C8: BSYSTXBB4ZC01 | D8: =VLOOKUP(C8,'Paste bid here'!A:F,4,FALSE) -> #N/A | E8: Evolution Damper Control Module
B9: SYSTXBBNIM01 | C9: BSYSTXBBNIM01 | D9: =VLOOKUP(C9,'Paste bid here'!A:F,4,FALSE) -> #N/A | E9: Evolution NIM Module
B10: SYSTXZNSMS01 | C10: CSYSTXZNSMS01 | D10: =VLOOKUP(C10,'Paste bid here'!A:F,4,FALSE) -> #N/A | E10: Evolution Smart Sensor
A11: ECOBEE STATS | B11: EBSTATE7P-01 | C11: REBSTATE7P01 | D11: =VLOOKUP(C11,'Paste bid here'!A:F,4,FALSE) -> #N/A | E11: Ecobee 7 Lite Pro - Replaced Ecobee 3 Lite
B12: EB-BSTATE7IBR-01 | C12: BEBSTATE7IBR01 | D12: =VLOOKUP(C12,'Paste bid here'!A:F,4,FALSE) -> #N/A | E12: Ecobee 7 Lite Pro - Bryant Branded - Intellisense
B13: EB-STATE7PB01 | C13: EEBSTATE7PB01 | D13: =VLOOKUP(C13,'Paste bid here'!A:F,4,FALSE) -> #N/A | E13: Ecobee 7 Lite Pro - Builder Model
B14: EB-STATE3LTIBR-01 | C14: BEBSTATE3LTIBR01 | D14: =VLOOKUP(C14,'Paste bid here'!A:F,4,FALSE) -> #N/A | E14: Ecobee 3 Lite Pro Bryant Branded - Intellisense - (limited stock)
B15: EB-STATE6P-01 | C15: REBSTATE6P01 | D15: =VLOOKUP(C15,'Paste bid here'!A:F,4,FALSE) -> #N/A | E15: Ecboee Premium Control w/ Smart Sensor
B16: EB-STATE6IBR-01 | C16: BEBSTATE6IBR01 | D16: =VLOOKUP(C16,'Paste bid here'!A:F,4,FALSE) -> #N/A | E16: Ecobee Premium - Bryant Branded - Intellisense
B17: EB-STATE6LP-01 | C17: REBSTATE6LP01 | D17: =VLOOKUP(C17,'Paste bid here'!A:F,4,FALSE) -> #N/A | E17: Ecobee Enhanced Control
B18: EB-STATE6PB01 | C18: EEBSTATE6PB01 | D18: =VLOOKUP(C18,'Paste bid here'!A:F,4,FALSE) -> #N/A | E18: Ecobee Premium - Builder Model
B19: EB-RSHM2PK-01 | C19: REBRSHM2PK01 | D19: =VLOOKUP(C19,'Paste bid here'!A:F,4,FALSE) -> #N/A | E19: Ecobee Wireless Smart Sensors
A20: CARRIER EDGE 2-WIRE STATS | B20: 33CS2PP2S03 | C20: C33CS2PP2S03 | D20: =VLOOKUP(C20,'Paste bid here'!A:F,4,FALSE) -> #N/A | E20: EDGE PRO 2H/2C PROG. STAT
B21: 33CS2PPRH03 | C21: C33CS2PPRH03 | D21: =VLOOKUP(C21,'Paste bid here'!A:F,4,FALSE) -> #N/A | E21: EDGE PRO PROG. STAT WITH HUMIDITY CONTROL
A22: RGF AIR PURIFICATION | B22: REMELEDAS | C22: RREMELEDAS | D22: =VLOOKUP(C22,'Paste bid here'!A:F,4,FALSE) -> #N/A | E22: RGF LED AIR PURIFIER
B23: REMEH | C23: RREMEHT | D23: =VLOOKUP(C23,'Paste bid here'!A:F,4,FALSE) -> #N/A | E23: RGF UV AIR PURIFIER
B24: ZEROH4ACT | C24: RZEROH4ACT | D24: =VLOOKUP(C24,'Paste bid here'!A:F,4,FALSE) -> #N/A | E24: RGF ZERO OZONE AIR PURIFIER
B25: SPLITHVACPHI230 | C25: ARFSPLITHVACPHI230 | D25: =VLOOKUP(C25,'Paste bid here'!A:F,4,FALSE) -> #N/A | E25: RGF MINI SPLIT AIR PURIFIER
B26: CLEARSKYMS | C26: ARFCLEARSKYMS | D26: =VLOOKUP(C26,'Paste bid here'!A:F,4,FALSE) -> #N/A | E26: RGF MINI SPLIT AIR PURIFIER-BUDGET OPTION
B27: RPHIPKG524V | C27: RPHIPKG524V | D27: =VLOOKUP(C27,'Paste bid here'!A:F,4,FALSE) -> #N/A | E27: RGF DUCT MOUNTED 5" COMM AIR PURIFICATION SYSTEM
B28: RPHIPKG924V | C28: RPHIPKG924V | D28: =VLOOKUP(C28,'Paste bid here'!A:F,4,FALSE) -> #N/A | E28: RGF DUCT MOUNTED 9" COMM AIR PURIFICATION SYSTEM
B29: CLEARSKYDM | C29: RCLEARSKYDM | D29: =VLOOKUP(C29,'Paste bid here'!A:F,4,FALSE) -> #N/A | E29: RGF DUCT MOUNTED AIR PURIFIER-BUDGET OPTION
A30: AERUS AIR SCRUBBERS | B30: 9960051 | C30: A9960051 | D30: =VLOOKUP(C30,'Paste bid here'!A:F,4,FALSE) -> #N/A | E30: AIR SCRUBBER PURIFIER - OZONE
B31: 9960052 | C31: A9960052 | D31: =VLOOKUP(C31,'Paste bid here'!A:F,4,FALSE) -> #N/A | E31: AIR SCRUBBER PURIFIER - NO OZONE
B32: 00811 | C32: A00811 | D32: =VLOOKUP(C32,'Paste bid here'!A:F,4,FALSE) -> #N/A | E32: LAUNDRY PRO 3.0
B33: 00693 | C33: A00693 | D33: =VLOOKUP(C33,'Paste bid here'!A:F,4,FALSE) -> #N/A | E33: PLUG IN WALL OUTLET PURIFIER - 250 SQ FT
B34: 00746 | C34: A00746 | D34: =VLOOKUP(C34,'Paste bid here'!A:F,4,FALSE) -> #N/A | E34: PURE & CLEAN - STAND ALONE PURIFIER - 2000 SQ FT
A35: Evolution Air Purifiers | B35: DGAPAXX1620 | C35: CDGAPAXX1620 | D35: =VLOOKUP(C35,'Paste bid here'!A:F,4,FALSE) -> #N/A | E35: Evolution Air Purifier 16x20
B36: DGAPAXX1625 | C36: CDGAPAXX1625 | D36: =VLOOKUP(C36,'Paste bid here'!A:F,4,FALSE) -> #N/A | E36: Evolution Air Purifier 16x25
B37: DGAPAXX2020 | C37: CDGAPAXX2020 | D37: =VLOOKUP(C37,'Paste bid here'!A:F,4,FALSE) -> #N/A | E37: Evolution Air Purifier 20x20
B38: DGAPAXX2025 | C38: CDGAPAXX2025 | D38: =VLOOKUP(C38,'Paste bid here'!A:F,4,FALSE) -> #N/A | E38: Evolution Air Purifier 20x25
B39: DGAPAXX2420 | C39: CDGAPAXX2420 | D39: =VLOOKUP(C39,'Paste bid here'!A:F,4,FALSE) -> #N/A | E39: Evolution Air Purifier 24x20
A40: ELECTRONIC AIR CLEANERS | B40: F300E1001 | C40: HF300E1001 | D40: =VLOOKUP(C40,'Paste bid here'!A:F,4,FALSE) -> #N/A | E40: (16X20, 1200 CFM
A41: RGF AIR PURIFICATION | B41: F300E1019 | C41: HF300E1019 | D41: =VLOOKUP(C41,'Paste bid here'!A:F,4,FALSE) -> #N/A | E41: (16X25, 1400 CFM)
...

Sheet MOBILE HOME APPROVED
B1: MOBILE HOME APPROVED
E3: 46000
B4: Part Number | C4: Ferguson PN | D4: Price
A5: GAS FURNACES
A6: LEGACY 96% 1-STAGE FURNACE | B6: 916SA30026M14 | C6: B916SA30026M14 | D6: =VLOOKUP(C6,'Paste bid here'!A:F,4,FALSE) -> #N/A
B7: 916SA30040M14 | C7: B916SA30040M14 | D7: =VLOOKUP(C7,'Paste bid here'!A:F,4,FALSE) -> #N/A
B8: 916SA36040M17 | C8: B916SA36040M17 | D8: =VLOOKUP(C8,'Paste bid here'!A:F,4,FALSE) -> #N/A
B9: 916SA36060M14 | C9: B916SA36060M14 | D9: =VLOOKUP(C9,'Paste bid here'!A:F,4,FALSE) -> #N/A
B10: 916SA48060M17 | C10: B916SA48060M17 | D10: =VLOOKUP(C10,'Paste bid here'!A:F,4,FALSE) -> #N/A
B11: 916SA48080M17 | C11: B916SA48080M17 | D11: =VLOOKUP(C11,'Paste bid here'!A:F,4,FALSE) -> #N/A
B12: 916SA60080M21 | C12: B916SA60080M21 | D12: =VLOOKUP(C12,'Paste bid here'!A:F,4,FALSE) -> #N/A
B13: 916SA60100M21 | C13: B916SA60100M21 | D13: =VLOOKUP(C13,'Paste bid here'!A:F,4,FALSE) -> #N/A
B14: 916SA66100M21 | C14: B916SA66100M21 | D14: =VLOOKUP(C14,'Paste bid here'!A:F,4,FALSE) -> #N/A
B15: 916SA66120M24 | C15: B916SA66120M24 | D15: =VLOOKUP(C15,'Paste bid here'!A:F,4,FALSE) -> #N/A
B16: 916SA66140M24 | C16: B916SA66140M24 | D16: =VLOOKUP(C16,'Paste bid here'!A:F,4,FALSE) -> #N/A
A17: 90% LP CONVERSION KIT | B17: AGAGC9NPS01D | C17: RAGAGC9NPS01E | D17: =VLOOKUP(C17,'Paste bid here'!A:F,4,FALSE) -> #N/A
A18: FAN COILS
A19: R454B PREFERRED SERIES VARIABLE SPEED FAN COIL | B19: FT5ANXB24L00 | C19: CFT5ANXB24L00 | D19: =VLOOKUP(C19,'Paste bid here'!A:F,4,FALSE) -> #N/A | E19: BETTER
B20: FT5ANBC36L00 | C20: CFT5ANBC36L00 | D20: =VLOOKUP(C20,'Paste bid here'!A:F,4,FALSE) -> #N/A
B21: FT5ANBC48L00 | C21: CFT5ANBC48L00 | D21: =VLOOKUP(C21,'Paste bid here'!A:F,4,FALSE) -> #N/A
B22: FT5ANBD60L00 | C22: CFT5ANBD60L00 | D22: =VLOOKUP(C22,'Paste bid here'!A:F,4,FALSE) -> #N/A
A23: R454B LEGACY SERIES FAN COIL | B23: FJ5ANXA18L00 | C23: CFJ5ANXA18L00 | D23: =VLOOKUP(C23,'Paste bid here'!A:F,4,FALSE) -> #N/A | E23: GOOD
B24: FJ5ANXB24L00 | C24: CFJ5ANXB24L00 | D24: =VLOOKUP(C24,'Paste bid here'!A:F,4,FALSE) -> #N/A
B25: FJ5ANXB30L00 | C25: CFJ5ANXB30L00 | D25: =VLOOKUP(C25,'Paste bid here'!A:F,4,FALSE) -> #N/A
B26: FJ5ANXB36L00 | C26: CFJ5ANXB36L00 | D26: =VLOOKUP(C26,'Paste bid here'!A:F,4,FALSE) -> #N/A
B27: FJ5ANXC42L00 | C27: CFJ5ANXC42L00 | D27: =VLOOKUP(C27,'Paste bid here'!A:F,4,FALSE) -> #N/A
B28: FJ5ANXC48L00 | C28: CFJ5ANXC48L00 | D28: =VLOOKUP(C28,'Paste bid here'!A:F,4,FALSE) -> #N/A
B29: FJ5ANXD60L00 | C29: CFJ5ANXD60L00 | D29: =VLOOKUP(C29,'Paste bid here'!A:F,4,FALSE) -> #N/A
A30: UNITARY STRIP HEAT FOR FJ & FT FAN COILS | B30: FF-2401C05 | C30: TFF2401C05 | D30: =VLOOKUP(C30,'Paste bid here'!A:F,4,FALSE) -> #N/A | E30: 5kW sizes 24-60
B31: FF-2501C08 | C31: TFF2501C08 | D31: =VLOOKUP(C31,'Paste bid here'!A:F,4,FALSE) -> #N/A | E31: 8kW sizes 24-60
B32: FF-2601C10 | C32: TFF2601C10 | D32: =VLOOKUP(C32,'Paste bid here'!A:F,4,FALSE) -> #N/A | E32: 10kW sizes 24-60
B33: FF-3101C15 | C33: TFF3101C15 | D33: =VLOOKUP(C33,'Paste bid here'!A:F,4,FALSE) -> #N/A | E33: 15kW sizes 24-60
B34: FF-3301C20 | C34: TFF3301C20 | D34: =VLOOKUP(C34,'Paste bid here'!A:F,4,FALSE) -> #N/A | E34: 20kW sizes 30-60
B35: FF-8401C05 | C35: TFF8401C05 | D35: =VLOOKUP(C35,'Paste bid here'!A:F,4,FALSE) -> #N/A | E35: 5kW size 18 ONLY
B36: FF-8501C08 | C36: TFF8501C08 | D36: =VLOOKUP(C36,'Paste bid here'!A:F,4,FALSE) -> #N/A | E36: 10kW size 18 ONLY
B37: FF-8601C10 | C37: TFF8601C10 | D37: =VLOOKUP(C37,'Paste bid here'!A:F,4,FALSE) -> #N/A | E37: 15kW size 18 ONLY
A38: Downflow Kits - Unitary Fan Coils | B38: KFADC0201SLP | C38: CKFADC0201SLP | D38: =VLOOKUP(C38,'Paste bid here'!A:F,4,FALSE) -> #N/A | E38: Downflow Kit - Slope Coil, FJ5 18-24, FE5/FT5 36
B39: KFADC0401ACL | C39: CKFADC0401ACL | D39: =VLOOKUP(C39,'Paste bid here'!A:F,4,FALSE) -> #N/A | E39: Downflow Kit - A Coil, FJ5 30-60, FE5/FT5 24,48,60
A40: EVAPORATOR COILS
A41: R454B UPFLOW / DOWNFLOW CASED V COIL | B41: CVAVA1814XMA | C41: CCVAVA1814XMA | D41: =VLOOKUP(C41,'Paste bid here'!A:F,4,FALSE) -> #N/A
...

Sheet CROSSOVER SYSTEMS
C1: R454B Ducted Solutions Quick Reference Guide | R1: Ductless Systems
A2: AHRI Rated Btu's | E2: Indoor Unit w/ | I2: Line Set | K2: Additional | O2: Maximum | P2: Maximum | Q2: Maximum | R2: Maximum
A3: Cooling @ 95°F / | B3: SEER2 | C3: EER2 | D3: HSPF2 | E3: Factory Installed | F3: Indoor Unit | G3: Outdoor Unit With | H3: Outdoor Unit | I3: Liquid x | J3: Max. Line | K3: Charge | L3: Max. Lift | M3: MCA / MOCP | N3: Recommended | O3: Heating BTU's at | P3: Heating BTU's at | Q3: Cooling BTU's at | R3: Cooling BTU's at
A4: Heating @ 47°F | E4: 24V Interface | F4: Price | G4: Base Pan Heater | H4: Price | I4: Suction | J4: Length | K4: >25ft | N4: Fuse Size | O4: -5F [-20F] | P4: 5F [-15C] | Q4: 113⁰F | R4: 122⁰F
O5: At 69°F Indoor DB | Q5: At 75.2°F Indoor DB
A6: This Sheet is not intended to replace the Installation Instructions. It is a reference guide only. Always read through the Installation Instructions.
A7: Preferred Series AHU 1:1 Heat Pump Systems w/ Factory Installed 24V Interface
A8: 18,000/19,500 | B8: 18.2 | C8: 12 | D8: 10.1 | E8: C45MBAAQ18XB3 | F8: =INDEX('Ductless cross'!$E$8:$E$301,MATCH(E8,'Ductless cross'!$B$8:$B$301,0)) -> #N/A | G8: C37MAHAQ18AA3 | H8: =INDEX('Ductless cross'!$E$8:$E$301,MATCH(G8,'Ductless cross'!$B$8:$B$301,0)) -> #N/A | I8: 1/4" x 1/2" | J8: 98.42' | K8: .16 Oz/Ft | L8: 65.62' | M8: 19A / 20A | N8: 20A | O8: 15484 | P8: 18688 | Q8: 17391 | R8: 12157
A9: 23,000/26,000 | B9: 18.8 | C9: 12 | D9: 10 | E9: C45MBAAQ24XB3 | F9: =INDEX('Ductless cross'!$E$8:$E$301,MATCH(E9,'Ductless cross'!$B$8:$B$301,0)) -> #N/A | G9: C37MAHAQ24AA3 | H9: =INDEX('Ductless cross'!$E$8:$E$301,MATCH(G9,'Ductless cross'!$B$8:$B$301,0)) -> #N/A | I9: 3/8" x 5/8" | J9: 164.04' | K9: .32 Oz/Ft | L9: 82.02' | M9: 24.9A / 25A | N9: 25A | O9: 19483 | P9: 24689 | Q9: 25819 | R9: 16531
A10: 33,000/35,000 | B10: 16.7 | C10: 11.7 | D10: 10 | E10: C45MBAAQ36XB3 | F10: =INDEX('Ductless cross'!$E$8:$E$302,MATCH(E10,'Ductless cross'!$B$8:$B$302,0)) -> #N/A | G10: C37MAHAQ33AA3 | H10: =INDEX('Ductless cross'!$E$8:$E$301,MATCH(G10,'Ductless cross'!$B$8:$B$301,0)) -> #N/A | I10: 3/8" x 3/4" | J10: 164.04' | K10: .32 Oz/Ft | L10: 82.02' | M10: 38A / 40A | N10: 40A | O10: 29944 | P10: 35826 | Q10: 34216 | R10: 15385
A11: Preferred Horizontal Discharge AHU 1:1 Preferred Heat Pump Systems (Crossover Solutions)
A12: 18,000/18,000 | B12: 19 | C12: 12.5 | D12: 10.2 | E12: C45MUHAQ24XX3 | F12: =INDEX('Ductless cross'!$E$8:$E$301,MATCH(E12,'Ductless cross'!$B$8:$B$301,0)) -> #N/A | G12: C37MUHAQ18AA3 | H12: =INDEX('Ductless cross'!$E$8:$E$301,MATCH(G12,'Ductless cross'!$B$8:$B$301,0)) -> #N/A | I12: 3/8" x 3/4" | J12: 98.42' | K12: .70 Oz/ft | L12: 65.62' | M12: 16A / 20A | N12: 20A | O12: 16514 | P12: 19261 | Q12: 17916 | R12: 14214
A13: 24,000/24,000 | B13: 18.7 | C13: 12 | D13: 10 | E13: C45MUHAQ24XX3 | F13: =INDEX('Ductless cross'!$E$8:$E$301,MATCH(E13,'Ductless cross'!$B$8:$B$301,0)) -> #N/A | G13: C37MUHAQ24AA3 | H13: =INDEX('Ductless cross'!$E$8:$E$301,MATCH(G13,'Ductless cross'!$B$8:$B$301,0)) -> #N/A | I13: 3/8" x 3/4" | J13: 164.04' | K13: .70 Oz/ft | L13: 82.02' | M13: 19A / 20A | N13: 20A | O13: 17927 | P13: 21458 | Q13: 23751 | R13: 17725
A14: 30,000/33,000 | B14: 17.2 | C14: 12.1 | D14: 10.8 | E14: C45MUHAQ36XX3 | F14: =INDEX('Ductless cross'!$E$8:$E$301,MATCH(E14,'Ductless cross'!$B$8:$B$301,0)) -> #N/A | G14: C37MUHAQ30AA3 | H14: =INDEX('Ductless cross'!$E$8:$E$301,MATCH(G14,'Ductless cross'!$B$8:$B$301,0)) -> #N/A | I14: 3/8" x 3/4" | J14: 164.04' | K14: .70 Oz/ft | L14: 82.02' | M14: 29.5A / 30A | N14: 30A | O14: 27252 | P14: 33236 | Q14: 32779 | R14: 20649
A15: 36,000/37,000 | B15: 18 | C15: 12 | D15: 10 | E15: C45MUHAQ36XX3 | F15: =INDEX('Ductless cross'!$E$8:$E$301,MATCH(E15,'Ductless cross'!$B$8:$B$301,0)) -> #N/A | G15: C37MUHAQ36AA3 | H15: =INDEX('Ductless cross'!$E$8:$E$301,MATCH(G15,'Ductless cross'!$B$8:$B$301,0)) -> #N/A | I15: 3/8" x 3/4" | J15: 246' | K15: .70 Oz/ft | L15: 98.43' | M15: 29A / 30A | N15: 30A | O15: 37170 | P15: 38436 | Q15: 38525 | R15: 24495
A16: 48,000/48,000 | B16: 17.5 | C16: 12 | D16: 9.5 | E16: C45MUHAQ60XX3 | F16: =INDEX('Ductless cross'!$E$8:$E$301,MATCH(E16,'Ductless cross'!$B$8:$B$301,0)) -> #N/A | G16: C37MUHAQ48AA3 | H16: =INDEX('Ductless cross'!$E$8:$E$301,MATCH(G16,'Ductless cross'!$B$8:$B$301,0)) -> #N/A | I16: 3/8" x 3/4" | J16: 246' | K16: .70 Oz/ft | L16: 98.43' | M16: 38A / 40A | N16: 40A | O16: 43387 | P16: 48328 | Q16: 45560 | R16: 32789
A17: 54,000/55,000 | B17: 17.5 | C17: 12 | D17: 9.5 | E17: C45MUHAQ60XX3 | F17: =INDEX('Ductless cross'!$E$8:$E$301,MATCH(E17,'Ductless cross'!$B$8:$B$301,0)) -> #N/A | G17: C37MUHAQ60AA3 | H17: =INDEX('Ductless cross'!$E$8:$E$301,MATCH(G17,'Ductless cross'!$B$8:$B$301,0)) -> #N/A | I17: 3/8" x 3/4" | J17: 246' | K17: .70 Oz/ft | L17: 98.43' | M17: 40A / 40A | N17: 40A | O17: 49989 | P17: 56830 | Q17: 53125 | R17: 33738
A18: Preferred Horizontal Discharge AHU 1:1 Preferred Heat Pump Systems (Crossover Solutions)
A19: 18k/24k IDU Capacity select via dip switch and must match ODU size
A20: 18,000/19,000 | B20: 19 | C20: 12.5 | D20: 9.8 | E20: C45MUAAQ18XX3 | F20: =INDEX('Ductless cross'!$E$8:$E$301,MATCH(E20,'Ductless cross'!$B$8:$B$301,0)) -> #N/A | G20: C37MUHAQ18AA3 | H20: =INDEX('Ductless cross'!$E$8:$E$301,MATCH(G20,'Ductless cross'!$B$8:$B$301,0)) -> #N/A | I20: 3/8" x 3/4" | J20: 98.42' | K20: .70 Oz/ft | L20: 65.62' | M20: 16A / 20A | N20: 20A | O20: 16780 | P20: 19813 | Q20: 18855 | R20: 15316
A21: 23,000/24,000 | B21: 18.4 | C21: 11.7 | D21: 10 | E21: C45MUAAQ24XX3 | F21: =INDEX('Ductless cross'!$E$8:$E$301,MATCH(E21,'Ductless cross'!$B$8:$B$301,0)) -> #N/A | G21: C37MUHAQ24AA3 | H21: =INDEX('Ductless cross'!$E$8:$E$301,MATCH(G21,'Ductless cross'!$B$8:$B$301,0)) -> #N/A | I21: 3/8" x 3/4" | J21: 164.04' | K21: .70 Oz/ft | L21: 82.02' | M21: 19A / 20A | N21: 20A | O21: 17309 | P21: 22891 | Q21: 25051 | R21: 16371
A22: 30,000/34,000 | B22: 16.9 | C22: 11.7 | D22: 10 | E22: C45MUAAQ30XX3 | F22: =INDEX('Ductless cross'!$E$8:$E$301,MATCH(E22,'Ductless cross'!$B$8:$B$301,0)) -> #N/A | G22: C37MUHAQ30AA3 | H22: =INDEX('Ductless cross'!$E$8:$E$301,MATCH(G22,'Ductless cross'!$B$8:$B$301,0)) -> #N/A | I22: 3/8" x 3/4" | J22: 164.04' | K22: .70 Oz/ft | L22: 82.02' | M22: 29.5A / 30A | N22: 30A | O22: 28190 | P22: 33287 | Q22: 32404 | R22: 21287
A23: 36,000/37,000 | B23: 17.4 | C23: 11.7 | D23: 10.3 | E23: C45MUAAQ36XX3 | F23: =INDEX('Ductless cross'!$E$8:$E$301,MATCH(E23,'Ductless cross'!$B$8:$B$301,0)) -> #N/A | G23: C37MUHAQ36AA3 | H23: =INDEX('Ductless cross'!$E$8:$E$301,MATCH(G23,'Ductless cross'!$B$8:$B$301,0)) -> #N/A | I23: 3/8" x 3/4" | J23: 246' | K23: .70 Oz/ft | L23: 98.43' | M23: 29A / 30A | N23: 30A | O23: 35662 | P23: 41538 | Q23: 36996 | R23: 24959
A24: 48,000/50,000 | B24: 16.5 | C24: 10.5 | D24: 9.5 | E24: C45MUAAQ48XX3 | F24: =INDEX('Ductless cross'!$E$8:$E$301,MATCH(E24,'Ductless cross'!$B$8:$B$301,0)) -> #N/A | G24: C37MUHAQ48AA3 | H24: =INDEX('Ductless cross'!$E$8:$E$301,MATCH(G24,'Ductless cross'!$B$8:$B$301,0)) -> #N/A | I24: 3/8" x 3/4" | J24: 246' | K24: .70 Oz/ft | L24: 98.43' | M24: 38A / 40A | N24: 40A | O24: 40674 | P24: 46850 | Q24: 42234 | R24: 30465
A25: 54,000/56,000 | B25: 16 | C25: 10 | D25: 9 | E25: C45MUAAQ60XX3 | F25: =INDEX('Ductless cross'!$E$8:$E$301,MATCH(E25,'Ductless cross'!$B$8:$B$301,0)) -> #N/A | G25: C37MUHAQ60AA3 | H25: =INDEX('Ductless cross'!$E$8:$E$301,MATCH(G25,'Ductless cross'!$B$8:$B$301,0)) -> #N/A | I25: 3/8" x 3/4" | J25: 246' | K25: .70 Oz/ft | L25: 98.43' | M25: 40A / 40A | N25: 40A | O25: 46714 | P25: 54228 | Q25: 50848 | R25: 34671
A26: Legacy Tier Horizontal Discharge AHU 1:1 Heat Pump Systems (Crossover Solutions)
A27: 18k/24k IDU Capacity select via dip switch and must match ODU size
A28: 18,000/18,000 | B28: 18.8 | C28: 11 | D28: 9.2 | E28: C45MUAAQ18XX3 | F28: =INDEX('Ductless cross'!$E$8:$E$301,MATCH(E28,'Ductless cross'!$B$8:$B$301,0)) -> #N/A | G28: C37MURAQ18AA3 | H28: =INDEX('Ductless cross'!$E$8:$E$301,MATCH(G28,'Ductless cross'!$B$8:$B$301,0)) -> #N/A | I28: 3/8" x 3/4" | J28: 98.42' | K28: .70 Oz/ft | L28: 65.62' | M28: 16A / 20A | N28: 20A | O28: 9175 | P28: 11379 | Q28: 15815 | R28: 9543
A29: 24,000/26,000 | B29: 18.2 | C29: 11 | D29: 9.7 | E29: C45MUAAQ24XX3 | F29: =INDEX('Ductless cross'!$E$8:$E$301,MATCH(E29,'Ductless cross'!$B$8:$B$301,0)) -> #N/A | G29: C37MURAQ24AA3 | H29: =INDEX('Ductless cross'!$E$8:$E$301,MATCH(G29,'Ductless cross'!$B$8:$B$301,0)) -> #N/A | I29: 3/8" x 3/4" | J29: 164.04' | K29: .70 Oz/ft | L29: 82.02' | M29: 19A / 20A | N29: 20A | O29: 16963 | P29: 22433 | Q29: 24550 | R29: 16043
A30: 30,000/31,000 | B30: 17 | C30: 10.8 | D30: 8.5 | E30: C45MUAAQ30XX3 | F30: =INDEX('Ductless cross'!$E$8:$E$301,MATCH(E30,'Ductless cross'!$B$8:$B$301,0)) -> #N/A | G30: C37MURAQ30AA3 | H30: =INDEX('Ductless cross'!$E$8:$E$301,MATCH(G30,'Ductless cross'!$B$8:$B$301,0)) -> #N/A | I30: 3/8" x 3/4" | J30: 164.04' | K30: .70 Oz/ft | L30: 82.02' | M30: 22.5A / 25A | N30: 25A | O30: 15521 | P30: 19356 | Q30: 29603 | R30: 14498
A31: 36,000/36,000 | B31: 16.2 | C31: 10 | D31: 8.7 | E31: C45MUAAQ36XX3 | F31: =INDEX('Ductless cross'!$E$8:$E$301,MATCH(E31,'Ductless cross'!$B$8:$B$301,0)) -> #N/A | G31: C37MURAQ36AA3 | H31: =INDEX('Ductless cross'!$E$8:$E$301,MATCH(G31,'Ductless cross'!$B$8:$B$301,0)) -> #N/A | I31: 3/8" x 3/4" | J31: 246' | K31: .70 Oz/ft | L31: 98.42' | M31: 24A / 30A | N31: 30A | O31: 22765 | P31: 26515 | Q31: 32032 | R31: 18926
A32: 48,000/48,000 | B32: 16 | C32: 10 | D32: 8.5 | E32: C45MUAAQ48XX3 | F32: =INDEX('Ductless cross'!$E$8:$E$301,MATCH(E32,'Ductless cross'!$B$8:$B$301,0)) -> #N/A | G32: C37MURAQ48AA3 | H32: =INDEX('Ductless cross'!$E$8:$E$301,MATCH(G32,'Ductless cross'!$B$8:$B$301,0)) -> #N/A | I32: 3/8" x 3/4" | J32: 246' | K32: .70 Oz/ft | L32: 98.42' | M32: 36A / 40A | N32: 40A | O32: 35908 | P32: 43152 | Q32: 42022 | R32: 30316
A33: 54,000/54,000 | B33: 15.2 | C33: 8.7 | D33: 8.4 | E33: C45MUAAQ60XX3 | F33: =INDEX('Ductless cross'!$E$8:$E$301,MATCH(E33,'Ductless cross'!$B$8:$B$301,0)) -> #N/A | G33: C37MURAQ60AA3 | H33: =INDEX('Ductless cross'!$E$8:$E$301,MATCH(G33,'Ductless cross'!$B$8:$B$301,0)) -> #N/A | I33: 3/8" x 3/4" | J33: 246' | K33: .70 Oz/ft | L33: 98.42' | M33: 39A / 40A | N33: 40A | O33: 35597 | P33: 41473 | Q33: 41858 | R33: 32571
A34: Accessory Options:
A35: Accessory Electric Heater Kits for 45MBAA & 45MUAA | G35: ACCESSORY ELECTRIC HEATER KITS FOR 45MUHA | L35: Accessory Air Purifiers & Media Filters
A36: Model Number | B36: Size | C36: Size Used With | F36: Price | G36: Model Number | H36: Size | I36: Size Used With | K36: Price | L36: Model Number | N36: Description | P36: Size Used With | R36: Price
A37: CEHKMC05KN | B37: 5 kW | C37: 18k, 24k, 30k, 36k | F37: =INDEX('Ductless cross'!$E$8:$E$301,MATCH(A37,'Ductless cross'!$B$8:$B$301,0)) -> #N/A | G37: CEHKMD05KN | H37: 5 kW | I37: 24k, 36k | J37: 24k, 36k | K37: =INDEX('Ductless cross'!$E$8:$E$301,MATCH(G37,'Ductless cross'!$B$8:$B$301,0)) -> #N/A | L37: CDGAPAXX1620 | N37: Evolution® Air Purifier Size 1620 | P37: 18k, 24k | R37: =INDEX('Ductless cross'!$E$8:$E$301,MATCH(L37,'Ductless cross'!$B$8:$B$301,0)) -> #N/A
A38: CEHKMC08KN | B38: 8 kW | C38: 18k, 24k, 30k, 36k, 48k | F38: =INDEX('Ductless cross'!$E$8:$E$301,MATCH(A38,'Ductless cross'!$B$8:$B$301,0)) -> #N/A | G38: CEHKMD08KN | H38: 8 kW | I38: 24k, 36k | J38: 24k, 36k | K38: =INDEX('Ductless cross'!$E$8:$E$301,MATCH(G38,'Ductless cross'!$B$8:$B$301,0)) -> #N/A | L38: CDGAPAXX2020 | N38: Evolution® Air Purifier Size 2020 | P38: 30k, 36k, 48k | R38: =INDEX('Ductless cross'!$E$8:$E$301,MATCH(L38,'Ductless cross'!$B$8:$B$301,0)) -> #N/A
A39: CEHKMC10KN | B39: 10 kW | C39: 18k, 23k, 30k, 36k, 48k, 60k | F39: =INDEX('Ductless cross'!$E$8:$E$301,MATCH(A39,'Ductless cross'!$B$8:$B$301,0)) -> #N/A | G39: CEHKMD10KN | H39: 10 kW | I39: 24k, 36k, 60k | J39: 24k, 36k, 60k | K39: =INDEX('Ductless cross'!$E$8:$E$301,MATCH(G39,'Ductless cross'!$B$8:$B$301,0)) -> #N/A | L39: CDGAPAXX2420 | N39: Evolution® Air Purifier Size 2420 | P39: 60k | R39: =INDEX('Ductless cross'!$E$8:$E$301,MATCH(L39,'Ductless cross'!$B$8:$B$301,0)) -> #N/A
A40: CEHKMC15KN | B40: 15kW | C40: 24k, 30k, 36k, 48k, 60k | F40: =INDEX('Ductless cross'!$E$8:$E$301,MATCH(A40,'Ductless cross'!$B$8:$B$301,0)) -> #N/A | G40: CEHKMD15KN | H40: 15kW | I40: 24k, 36k, 60k | K40: =INDEX('Ductless cross'!$E$8:$E$301,MATCH(G40,'Ductless cross'!$B$8:$B$301,0)) -> #N/A | L40: HF100F1620 | N40: RESIDEO 4" MEDIA CABINET | P40: 1200cfm | R40: =INDEX('Ductless cross'!$E$8:$E$301,MATCH(L40,'Ductless cross'!$B$8:$B$301,0)) -> #N/A
...

Sheet DUCTLESS Single-Zone
E1: R454B Single Zone Quick Reference Guide | R1: Ductless Systems
A2: AHRI Rated Btu's | F2: Indoor Unit Price | G2: Outdoor Unit With Base Pan Heater | H2: Outdoor Unit Price | I2: Line Set | J2: Max. Line Length | K2: Additional | L2: Max. Lift | N2: Recommended Fuse Size | O2: Maximum | P2: Maximum | Q2: Maximum | R2: Maximum
A3: Cooling @ 95°F / | B3: SEER2 | C3: EER2 | D3: HSPF2 | E3: Indoor Unit With | I3: Liquid x | K3: Charge | M3: MCA / MOCP | O3: Heating BTU's | P3: Heating BTU's | Q3: Cooling BTU's | R3: Cooling BTU's
A4: Heating @ 47°F | E4: Wireless Remote | I4: Suction | K4: >25ft | O4: at -4⁰F | P4: at 5⁰F | Q4: at 110⁰F | R4: at 122⁰F
A5: This Sheet is not intended to replace the Installation Instructions. It is a reference guide only. Always read through the Installation Instructions.
A6: Evolution™ Series High Wall 1:1 Heat Pump Systems
A7: 6,000/9,000 | B7: 35.1 | C7: 17.5 | D7: 30 | E7: B615PHAQ06XA3 | F7: =INDEX('Ductless cross'!$E$8:$E$296,MATCH('DUCTLESS Single-Zone'!E7,'Ductless cross'!$B$8:$B$296,0)) -> #N/A | G7: C37MPRAQ06AA3 | H7: =INDEX('Ductless cross'!$E$8:$E$296,MATCH('DUCTLESS Single-Zone'!G7,'Ductless cross'!$B$8:$B$296,0)) -> #N/A | I7: 1/4" x 3/8" | J7: 82.02' | K7: .16 Oz/Ft | L7: 49.21' | M7: 16A / 20A | N7: 20A | O7: 10130 | P7: 13965 | Q7: 15085 | R7: 7892
A8: 9,000/12,000 | B8: 33.5 | C8: 17 | D8: 22 | E8: B615PHAQ09XA3 | F8: =INDEX('Ductless cross'!$E$8:$E$296,MATCH('DUCTLESS Single-Zone'!E8,'Ductless cross'!$B$8:$B$296,0)) -> #N/A | G8: C37MPRAQ09AA3 | H8: =INDEX('Ductless cross'!$E$8:$E$296,MATCH('DUCTLESS Single-Zone'!G8,'Ductless cross'!$B$8:$B$296,0)) -> #N/A | I8: 1/4" x 3/8" | J8: 82.02' | K8: .16 Oz/Ft | L8: 49.21' | M8: 16A / 20A | N8: 20A | O8: 10130 | P8: 13965 | Q8: 15085 | R8: 7892
A9: 12,000/12,000 | B9: 29.5 | C9: 14.3 | D9: 14.5 | E9: B615PHAQ12XA3 | F9: =INDEX('Ductless cross'!$E$8:$E$296,MATCH('DUCTLESS Single-Zone'!E9,'Ductless cross'!$B$8:$B$296,0)) -> #N/A | G9: C37MPRAQ12AA3 | H9: =INDEX('Ductless cross'!$E$8:$E$296,MATCH('DUCTLESS Single-Zone'!G9,'Ductless cross'!$B$8:$B$296,0)) -> #N/A | I9: 1/4" x 3/8" | J9: 82.02' | K9: .16 Oz/Ft | L9: 49.21' | M9: 16A / 20A | N9: 20A | O9: 10130 | P9: 13965 | Q9: 15085 | R9: 7892
A10: 18,000/20,000 | B10: 25.8 | C10: 15 | D10: 16.2 | E10: B615PHAQ18XA3 | F10: =INDEX('Ductless cross'!$E$8:$E$296,MATCH('DUCTLESS Single-Zone'!E10,'Ductless cross'!$B$8:$B$296,0)) -> #N/A | G10: C37MPRAQ18AA3 | H10: =INDEX('Ductless cross'!$E$8:$E$296,MATCH('DUCTLESS Single-Zone'!G10,'Ductless cross'!$B$8:$B$296,0)) -> #N/A | I10: 3/8" x 5/8" | J10: 164.04' | K10: .32 Oz/Ft | L10: 82.02' | M10: 24.9A / 25A | N10: 25A | O10: 20482 | P10: 24809 | Q10: 23263 | R10: 13286
A11: Preferred™ Series High Wall 1:1 Heat Pump Systems
A12: 6,000/7,000 | B12: 25.7 | C12: 18 | D12: 14.8 | E12: B615AHAQ06XA3 | F12: =INDEX('Ductless cross'!$E$8:$E$296,MATCH('DUCTLESS Single-Zone'!E12,'Ductless cross'!$B$8:$B$296,0)) -> #N/A | G12: C37MAHAQ06AA3 | H12: =INDEX('Ductless cross'!$E$8:$E$296,MATCH('DUCTLESS Single-Zone'!G12,'Ductless cross'!$B$8:$B$296,0)) -> #N/A | I12: 1/4" x 3/8" | J12: 82.02' | K12: .16 Oz/Ft | L12: 49.21' | M12: 12A / 15A | N12: 15A | O12: 5125 | P12: 7700 | Q12: 10717 | R12: 7571
A13: 9,000/12,000 | B13: 27.5 | C13: 15.5 | D13: 12.5 | E13: B615AHAQ09XA3 | F13: =INDEX('Ductless cross'!$E$8:$E$296,MATCH('DUCTLESS Single-Zone'!E13,'Ductless cross'!$B$8:$B$296,0)) -> #N/A | G13: C37MAHAQ09AA3 | H13: =INDEX('Ductless cross'!$E$8:$E$296,MATCH('DUCTLESS Single-Zone'!G13,'Ductless cross'!$B$8:$B$296,0)) -> #N/A | I13: 1/4" x 3/8" | J13: 82.02' | K13: .16 Oz/Ft | L13: 49.21' | M13: 15A / 15A | N13: 15A | O13: 8080 | P13: 11500 | Q13: 11215 | R13: 7447
A14: 12,000/12,000 | B14: 25.5 | C14: 13.5 | D14: 10.5 | E14: B615AHAQ12XA3 | F14: =INDEX('Ductless cross'!$E$8:$E$296,MATCH('DUCTLESS Single-Zone'!E14,'Ductless cross'!$B$8:$B$296,0)) -> #N/A | G14: C37MAHAQ12AA3 | H14: =INDEX('Ductless cross'!$E$8:$E$296,MATCH('DUCTLESS Single-Zone'!G14,'Ductless cross'!$B$8:$B$296,0)) -> #N/A | I14: 1/4" x 3/8" | J14: 82.02' | K14: .16 Oz/Ft | L14: 49.21' | M14: 15A / 15A | N14: 15A | O14: 9260 | P14: 11500 | Q14: 12194 | R14: 6490
A15: 18,000/18,000 | B15: 21.5 | C15: 12.5 | D15: 11 | E15: B615AHAQ18XA3 | F15: =INDEX('Ductless cross'!$E$8:$E$296,MATCH('DUCTLESS Single-Zone'!E15,'Ductless cross'!$B$8:$B$296,0)) -> #N/A | G15: C37MAHAQ18AA3 | H15: =INDEX('Ductless cross'!$E$8:$E$296,MATCH('DUCTLESS Single-Zone'!G15,'Ductless cross'!$B$8:$B$296,0)) -> #N/A | I15: 1/4" x 1/2" | J15: 98.42' | K15: .16 Oz/Ft | L15: 65.62' | M15: 19A / 20A | N15: 20A | O15: 15050 | P15: 18000 | Q15: 14794 | R15: 10590
A16: 24,000/29,000 | B16: 21.2 | C16: 13 | D16: 13.5 | E16: B615AHAQ24XA3 | F16: =INDEX('Ductless cross'!$E$8:$E$296,MATCH('DUCTLESS Single-Zone'!E16,'Ductless cross'!$B$8:$B$296,0)) -> #N/A | G16: C37MAHAQ24AA3 | H16: =INDEX('Ductless cross'!$E$8:$E$296,MATCH('DUCTLESS Single-Zone'!G16,'Ductless cross'!$B$8:$B$296,0)) -> #N/A | I16: 3/8" x 5/8" | J16: 164.04' | K16: .32 Oz/Ft | L16: 82.02' | M16: 24.9A / 25A | N16: 25A | O16: 20482 | P16: 24200 | Q16: 23263 | R16: 13286
A17: 33,000/36,000 | B17: 19.6 | C17: 12 | D17: 10.5 | E17: B615AHAQ33XA3 | F17: =INDEX('Ductless cross'!$E$8:$E$296,MATCH('DUCTLESS Single-Zone'!E17,'Ductless cross'!$B$8:$B$296,0)) -> #N/A | G17: C37MAHAQ33AA3 | H17: =INDEX('Ductless cross'!$E$8:$E$296,MATCH('DUCTLESS Single-Zone'!G17,'Ductless cross'!$B$8:$B$296,0)) -> #N/A | I17: 3/8" x 3/4" | J17: 164.04' | K17: .32 Oz/Ft | L17: 82.02' | M17: 34A / 35A | N17: 35A | O17: 29178 | P17: 35000 | Q17: 32895 | R17: 21554
A18: 12,000/12,000 | B18: 23.5 | C18: 13 | D18: 9.5 | E18: B615AHAQ12XA1 | F18: =INDEX('Ductless cross'!$E$8:$E$297,MATCH('DUCTLESS Single-Zone'!E18,'Ductless cross'!$B$8:$B$297,0)) -> #N/A | G18: C37MARAQ12AA1 | H18: =INDEX('Ductless cross'!$E$8:$E$298,MATCH('DUCTLESS Single-Zone'!G18,'Ductless cross'!$B$8:$B$298,0)) -> #N/A | I18: 1/4" x 3/8" | J18: 82.02' | K18: .16 Oz/Ft | L18: 49.21' | M18: 18A / 20A | N18: 20A | O18: 4374 | P18: 7700 | Q18: 11229 | R18: 6401
A19: Preferred™ Series 4-Way Ceiling Cassette 1:1 Heat Pump Systems
A20: 9,000/10,000 | B20: 22.7 | C20: 14 | D20: 12.2 | E20: C45MBCAQ12XA3 | F20: =INDEX('Ductless cross'!$E$8:$E$296,MATCH('DUCTLESS Single-Zone'!E20,'Ductless cross'!$B$8:$B$296,0)) -> #N/A | G20: C37MAHAQ09AA3 | H20: =INDEX('Ductless cross'!$E$8:$E$296,MATCH('DUCTLESS Single-Zone'!G20,'Ductless cross'!$B$8:$B$296,0)) -> #N/A | I20: 1/4" x 3/8" | J20: 82.02' | K20: .16 Oz/Ft | L20: 49.21' | M20: 15A / 15A | N20: 15A | O20: 7400 | P20: 11000 | Q20: 11100 | R20: 6483
A21: 12,000/12,000 | B21: 23.7 | C21: 12.7 | D21: 11.6 | E21: C45MBCAQ12XA3 | F21: =INDEX('Ductless cross'!$E$8:$E$296,MATCH('DUCTLESS Single-Zone'!E21,'Ductless cross'!$B$8:$B$296,0)) -> #N/A | G21: C37MAHAQ12AA3 | H21: =INDEX('Ductless cross'!$E$8:$E$296,MATCH('DUCTLESS Single-Zone'!G21,'Ductless cross'!$B$8:$B$296,0)) -> #N/A | I21: 1/4" x 3/8" | J21: 82.02' | K21: .16 Oz/Ft | L21: 49.21' | M21: 15A / 15A | N21: 15A | O21: 7500 | P21: 11500 | Q21: 11700 | R21: 6558
A22: 16,000/19,000 | B22: 20 | C22: 12.5 | D22: 12.4 | E22: C45MBCAQ18XA3 | F22: =INDEX('Ductless cross'!$E$8:$E$296,MATCH('DUCTLESS Single-Zone'!E22,'Ductless cross'!$B$8:$B$296,0)) -> #N/A | G22: C37MAHAQ18AA3 | H22: =INDEX('Ductless cross'!$E$8:$E$296,MATCH('DUCTLESS Single-Zone'!G22,'Ductless cross'!$B$8:$B$296,0)) -> #N/A | I22: 1/4" x 1/2" | J22: 98.42' | K22: .16 Oz/Ft | L22: 65.62' | M22: 19A / 20A | N22: 20A | O22: 14000 | P22: 17000 | Q22: 14000 | R22: 9879
A23: 23,500/25,000 | B23: 20.8 | C23: 12 | D23: 11.6 | E23: C45MBCAQ24XA3 | F23: =INDEX('Ductless cross'!$E$8:$E$296,MATCH('DUCTLESS Single-Zone'!E23,'Ductless cross'!$B$8:$B$296,0)) -> #N/A | G23: C37MAHAQ24AA3 | H23: =INDEX('Ductless cross'!$E$8:$E$296,MATCH('DUCTLESS Single-Zone'!G23,'Ductless cross'!$B$8:$B$296,0)) -> #N/A | I23: 3/8" x 5/8" | J23: 164.04' | K23: .32 Oz/Ft | L23: 82.02' | M23: 24.9A / 25A | N23: 25A | O23: 17300 | P23: 23800 | Q23: 21000 | R23: 13293
A24: Ceiling Cassette Grille for 9K, 12K & 18K BTU | F24: C45MBCQ01XXX3 | G24: =INDEX('Ductless cross'!$E$8:$E$296,MATCH('DUCTLESS Single-Zone'!F24,'Ductless cross'!$B$8:$B$296,0)) -> #N/A | H24: Ceiling Cassette Grille for 24K, 36K & 48K BTU | M24: C45MBCQ02XXX4 | N24: =INDEX('Ductless cross'!$E$8:$E$296,MATCH('DUCTLESS Single-Zone'!M24,'Ductless cross'!$B$8:$B$296,0)) -> #N/A | R24: [Required on all sizes and Sold Separately]
A25: Preferred™ Series One-Way Ceiling Cassette 1:1 Heat Pump Systems
A26: 6,500 / 7,100 | B26: 22 | C26: 15.2 | D26: 12 | E26: C45MCCAQ06XA3 | F26: =INDEX('Ductless cross'!$E$8:$E$296,MATCH('DUCTLESS Single-Zone'!E26,'Ductless cross'!$B$8:$B$296,0)) -> #N/A | G26: C37MAHAQ06AA3 | H26: =INDEX('Ductless cross'!$E$8:$E$296,MATCH('DUCTLESS Single-Zone'!G26,'Ductless cross'!$B$8:$B$296,0)) -> #N/A | I26: 1/4" x 3/8" | J26: 82.02' | K26: .16 Oz/Ft | L26: 49.21' | M26: 12A / 15A | N26: 15A | O26: 6400 | P26: 8100 | Q26: 11200 | R26: 6483
A27: 9,000 / 10,900 | B27: 24 | C27: 14.7 | D27: 12.2 | E27: C45MCCAQ12XA3 | F27: =INDEX('Ductless cross'!$E$8:$E$296,MATCH('DUCTLESS Single-Zone'!E27,'Ductless cross'!$B$8:$B$296,0)) -> #N/A | G27: C37MAHAQ09AA3 | H27: =INDEX('Ductless cross'!$E$8:$E$296,MATCH('DUCTLESS Single-Zone'!G27,'Ductless cross'!$B$8:$B$296,0)) -> #N/A | I27: 1/4" x 3/8" | J27: 82.02' | K27: .16 Oz/Ft | L27: 49.21' | M27: 15A / 15A | N27: 15A | O27: 8600 | P27: 10600 | Q27: 11200 | R27: 6483
A28: 12,000 / 12,500 | B28: 23 | C28: 13 | D28: 10.2 | E28: C45MCCAQ12XA3 | F28: =INDEX('Ductless cross'!$E$8:$E$296,MATCH('DUCTLESS Single-Zone'!E28,'Ductless cross'!$B$8:$B$296,0)) -> #N/A | G28: C37MAHAQ12AA3 | H28: =INDEX('Ductless cross'!$E$8:$E$296,MATCH('DUCTLESS Single-Zone'!G28,'Ductless cross'!$B$8:$B$296,0)) -> #N/A | I28: 1/4" x 3/8" | J28: 82.02' | K28: .16 Oz/Ft | L28: 49.21' | M28: 15A / 15A | N28: 15A | O28: 8600 | P28: 11500 | Q28: 11900 | R28: 6558
A29: 16,700 / 20,000 | B29: 20.7 | C29: 12.5 | D29: 12.2 | E29: C45MCCAQ18XA3 | F29: =INDEX('Ductless cross'!$E$8:$E$296,MATCH('DUCTLESS Single-Zone'!E29,'Ductless cross'!$B$8:$B$296,0)) -> #N/A | G29: C37MAHAQ18AA3 | H29: =INDEX('Ductless cross'!$E$8:$E$296,MATCH('DUCTLESS Single-Zone'!G29,'Ductless cross'!$B$8:$B$296,0)) -> #N/A | I29: 1/4" x 1/2" | J29: 98.42' | K29: .16 Oz/Ft | L29: 65.62' | M29: 19A / 20A | N29: 20A | O29: 14500 | P29: 17500 | Q29: 14500 | R29: 10289
A30: One-Way Cassette units include grill | F30: IDU Capacity select via dip switch and must match ODU size
A31: Preferred™ Series Low Static Slim-Ducted 1:1 Heat Pump Systems
A32: 6,500/8,000 | B32: 21.5 | C32: 14.5 | D32: 13.8 | E32: C45MBDAQ06XA3 | F32: =INDEX('Ductless cross'!$E$8:$E$296,MATCH('DUCTLESS Single-Zone'!E32,'Ductless cross'!$B$8:$B$296,0)) -> #N/A | G32: C37MAHAQ06AA3 | H32: =INDEX('Ductless cross'!$E$8:$E$296,MATCH('DUCTLESS Single-Zone'!G32,'Ductless cross'!$B$8:$B$296,0)) -> #N/A | I32: 1/4" x 3/8" | J32: 82.02' | K32: .16 Oz/Ft | L32: 49.21' | M32: 12A / 15A | N32: 15A | O32: 6302 | P32: 7800 | Q32: 10448 | R32: 7387
A33: 9,000/10,000 | B33: 21.5 | C33: 13.5 | D33: 12.5 | E33: C45MBDAQ12XA3 | F33: =INDEX('Ductless cross'!$E$8:$E$296,MATCH('DUCTLESS Single-Zone'!E33,'Ductless cross'!$B$8:$B$296,0)) -> #N/A | G33: C37MAHAQ09AA3 | H33: =INDEX('Ductless cross'!$E$8:$E$296,MATCH('DUCTLESS Single-Zone'!G33,'Ductless cross'!$B$8:$B$296,0)) -> #N/A | I33: 1/4" x 3/8" | J33: 82.02' | K33: .16 Oz/Ft | L33: 49.21' | M33: 15A / 15A | N33: 15A | O33: 9704 | P33: 11200 | Q33: 11147 | R33: 6056
A34: 12,000/12,500 | B34: 20 | C34: 12 | D34: 10.2 | E34: C45MBDAQ12XA3 | F34: =INDEX('Ductless cross'!$E$8:$E$296,MATCH('DUCTLESS Single-Zone'!E34,'Ductless cross'!$B$8:$B$296,0)) -> #N/A | G34: C37MAHAQ12AA3 | H34: =INDEX('Ductless cross'!$E$8:$E$296,MATCH('DUCTLESS Single-Zone'!G34,'Ductless cross'!$B$8:$B$296,0)) -> #N/A | I34: 1/4" x 3/8" | J34: 82.02' | K34: .16 Oz/Ft | L34: 49.21' | M34: 15A / 15A | N34: 15A | O34: 10256 | P34: 11800 | Q34: 11430 | R34: 6220
A35: 17,000/19,000 | B35: 18 | C35: 12 | D35: 10.8 | E35: C45MBDAQ18XA3 | F35: =INDEX('Ductless cross'!$E$8:$E$296,MATCH('DUCTLESS Single-Zone'!E35,'Ductless cross'!$B$8:$B$296,0)) -> #N/A | G35: C37MAHAQ18AA3 | H35: =INDEX('Ductless cross'!$E$8:$E$296,MATCH('DUCTLESS Single-Zone'!G35,'Ductless cross'!$B$8:$B$296,0)) -> #N/A | I35: 1/4" x 1/2" | J35: 98.42' | K35: .16 Oz/Ft | L35: 65.62' | M35: 19A / 20A | N35: 20A | O35: 15917 | P35: 18000 | Q35: 14525 | R35: 10543
A36: Preferred™ Series High Static Slim-Ducted 1:1 Heat Pump Systems
A37: 9,000/9,900 | B37: 20.6 | C37: 14 | D37: 13.8 | E37: C45MBDAQ12XH3 | F37: =INDEX('Ductless cross'!$E$8:$E$296,MATCH('DUCTLESS Single-Zone'!E37,'Ductless cross'!$B$8:$B$296,0)) -> #N/A | G37: C37MAHAQ09AA3 | H37: =INDEX('Ductless cross'!$E$8:$E$296,MATCH('DUCTLESS Single-Zone'!G37,'Ductless cross'!$B$8:$B$296,0)) -> #N/A | I37: 1/4" x 3/8" | J37: 82.02' | K37: .16 Oz/Ft | L37: 49.21' | M37: 15A / 15A | N37: 15A | O37: 8448 | P37: 11900 | Q37: 11048 | R37: 6060
A38: 12,000/12,000 | B38: 20.2 | C38: 12 | D38: 10.6 | E38: C45MBDAQ12XH3 | F38: =INDEX('Ductless cross'!$E$8:$E$296,MATCH('DUCTLESS Single-Zone'!E38,'Ductless cross'!$B$8:$B$296,0)) -> #N/A | G38: C37MAHAQ12AA3 | H38: =INDEX('Ductless cross'!$E$8:$E$296,MATCH('DUCTLESS Single-Zone'!G38,'Ductless cross'!$B$8:$B$296,0)) -> #N/A | I38: 1/4" x 3/8" | J38: 82.02' | K38: .16 Oz/Ft | L38: 49.21' | M38: 15A / 15A | N38: 15A | O38: 10171 | P38: 12000 | Q38: 11089 | R38: 6537
A39: 24,000/26,000 | B39: 19.2 | C39: 12 | D39: 11.7 | E39: C45MBDAQ24XH3 | F39: =INDEX('Ductless cross'!$E$8:$E$296,MATCH('DUCTLESS Single-Zone'!E39,'Ductless cross'!$B$8:$B$296,0)) -> #N/A | G39: C37MAHAQ24AA3 | H39: =INDEX('Ductless cross'!$E$8:$E$296,MATCH('DUCTLESS Single-Zone'!G39,'Ductless cross'!$B$8:$B$296,0)) -> #N/A | I39: 3/8" x 5/8" | J39: 164.04' | K39: .32 Oz/Ft | L39: 82.02' | M39: 24.9A / 25A | N39: 25A | O39: 19339 | P39: 24000 | Q39: 20858 | R39: 13979
A40: Preferred™ Series Console 1:1 Heat Pump Systems
...

Sheet DUCTLESS Multi-zone
C1: R454B Multi-Zone Quick Reference Guide | R1: Ductless Systems
A2: Outdoor Unit With | B2: Price | C2: Max Zones | D2: Max Heating Capacity Btu's | G2: Max Cooling BTU's AT 5F (-15C) | I2: Port Combinations | L2: Max Line Set | M2: Max Total | N2: Pre- | P2: MCA | Q2: MOCP | R2: Recommended Fuse Size
A3: Factory Installed | L3: Length | M3: Line Set | N3: Charge | O3: Max Lift
A4: Base Pan Heater | D4: @ 5° F | E4: @-13F | F4: @ -22° F | G4: @ 95°F | H4: @109F [43C] | I4: Liquid | K4: Suction | L4: Per Zone | M4: Length | N4: Length
A5: This Sheet is not intended to replace the Installation Instructions. It is a reference guide only. Always read through the Installation Instructions.
A6: Evolution™ Series Multi-Zone Heat Pump Systems
A7: C37MGHAQ18CA3 | B7: =INDEX('Ductless cross'!$E$8:$E$296,MATCH(A7,'Ductless cross'!$B$8:$B$296,0)) -> #N/A | C7: 3 | D7: 19000 | E7: 13600 | F7: 11000 | G7: 19000 | H7: 24000 | I7: 3 @ 1/4" | J7: 3 @ 3/8" | L7: 98.4' | M7: 196.9' | N7: 73.8' | O7: 49' | P7: 17.5 | Q7: 20 | R7: 20
A8: C37MGHAQ24DA3 | B8: =INDEX('Ductless cross'!$E$8:$E$296,MATCH(A8,'Ductless cross'!$B$8:$B$296,0)) -> #N/A | C8: 4 | D8: 25000 | E8: 17000 | F8: 14000 | G8: 24000 | H8: 32000 | I8: 4 @ 1/4" | J8: 3 @ 3/8" + 1 @ 1/2" | L8: 114.8' | M8: 262.5' | N8: 98.4' | O8: 49' | P8: 30 | Q8: 35 | R8: 35
A9: C37MGHAQ30EA3 | B9: =INDEX('Ductless cross'!$E$8:$E$296,MATCH(A9,'Ductless cross'!$B$8:$B$296,0)) -> #N/A | C9: 5 | D9: 36000 | E9: 28000 | F9: 22400 | G9: 30000 | H9: 39000 | I9: 5 @ 1/4" | J9: 3 @ 3/8" + 2 @ 1/2" | L9: 114.8' | M9: 262.5' | N9: 123' | O9: 49' | P9: 37 | Q9: 40 | R9: 40
A10: C37MGHAQ36EA3 | B10: =INDEX('Ductless cross'!$E$8:$E$296,MATCH(A10,'Ductless cross'!$B$8:$B$296,0)) -> #N/A | C10: 5 | D10: 36000 | E10: 28000 | F10: 22400 | G10: 36000 | H10: 39000 | I10: 5 @ 1/4" | J10: 3 @ 3/8" + 2 @ 1/2" | L10: 114.8' | M10: 262.5' | N10: 123' | O10: 65' | P10: 37 | Q10: 40 | R10: 40
A11: C37MGHAQ48FA3 | B11: =INDEX('Ductless cross'!$E$8:$E$296,MATCH(A11,'Ductless cross'!$B$8:$B$296,0)) -> #N/A | C11: 6 | D11: 47000 | E11: 30000 | F11: 25000 | G11: 47000 | H11: 45000 | I11: 6 @ 1/4" | J11: 4 @ 3/8" + 2 @ 1/2" | L11: 114.8' | M11: 262.5' | N11: 147.6' | O11: 65' | P11: 37 | Q11: 40 | R11: 40
A12: C37MGHAQ55FA3 | B12: =INDEX('Ductless cross'!$E$8:$E$296,MATCH(A12,'Ductless cross'!$B$8:$B$296,0)) -> #N/A | C12: 6 | D12: 47000 | E12: 32000 | F12: 26400 | G12: 51000 | H12: 46000 | I12: 6 @ 1/4" | J12: 4 @ 3/8" + 2 @ 1/2" | L12: 114.8' | M12: 262.5' | N12: 147.6' | O12: 65' | P12: 39.5 | Q12: 40 | R12: 40
A13: Preferred™ Series High Heat Multi-Zone Heat Pump Systems
A14: C37MGRAQ18CA3 | B14: =INDEX('Ductless cross'!$E$8:$E$296,MATCH(A14,'Ductless cross'!$B$8:$B$296,0)) -> #N/A | C14: 3 | D14: 13500 | E14: 8200 | G14: 18000 | H14: 18800 | I14: 3 @ 1/4" | J14: 3 @ 3/8" | L14: 98.4' | M14: 196.9' | N14: 73.8' | O14: 49.21' | P14: 16 | Q14: 20 | R14: 20
A15: C37MGRAQ24DA3 | B15: =INDEX('Ductless cross'!$E$8:$E$296,MATCH(A15,'Ductless cross'!$B$8:$B$296,0)) -> #N/A | C15: 4 | D15: 18000 | E15: 12000 | G15: 24000 | H15: 27400 | I15: 4 @ 1/4" | J15: 3 @ 3/8" + 1 @ 1/2" | L15: 114.8' | M15: 262.5' | N15: 98.4' | O15: 49.21' | P15: 23 | Q15: 25 | R15: 25
A16: C37MGRAQ30EA3 | B16: =INDEX('Ductless cross'!$E$8:$E$296,MATCH(A16,'Ductless cross'!$B$8:$B$296,0)) -> #N/A | C16: 5 | D16: 26000 | E16: 17500 | G16: 30000 | H16: 30600 | I16: 5 @ 1/4" | J16: 3 @ 3/8" + 2 @ 1/2" | L16: 114.8' | M16: 262.5' | N16: 123' | O16: 49.21' | P16: 30.5 | Q16: 35 | R16: 35
A17: C37MGRAQ36EA3 | B17: =INDEX('Ductless cross'!$E$8:$E$296,MATCH(A17,'Ductless cross'!$B$8:$B$296,0)) -> #N/A | C17: 5 | D17: 26000 | E17: 17500 | G17: 36000 | H17: 30600 | I17: 5 @ 1/4" | J17: 3 @ 3/8" + 2 @ 1/2" | L17: 114.8' | M17: 262.5' | N17: 123' | O17: 49.21' | P17: 30.5 | Q17: 35 | R17: 35
A18: C37MGRAQ48FA3 | B18: =INDEX('Ductless cross'!$E$8:$E$296,MATCH(A18,'Ductless cross'!$B$8:$B$296,0)) -> #N/A | C18: 6 | D18: 36000 | E18: 27000 | G18: 47000 | H18: 42000 | I18: 6 @ 1/4" | J18: 4 @ 3/8" + 2 @ 1/2" | L18: 114.8' | M18: 262.5' | N18: 147.6' | O18: 49.21' | P18: 34 | Q18: 40 | R18: 40
A19: C37MGRAQ55FA3 | B19: =INDEX('Ductless cross'!$E$8:$E$296,MATCH(A19,'Ductless cross'!$B$8:$B$296,0)) -> #N/A | C19: 6 | D19: 39000 | E19: 27800 | G19: 60000 | H19: 46000 | I19: 6 @ 1/4" | J19: 4 @ 3/8" + 2 @ 1/2" | L19: 114.8' | M19: 262.5' | N19: 147.6' | O19: 49.21' | P19: 36 | Q19: 40 | R19: 40
A20: Indoor Unit Types, Models, and Approved Btu/hr Combinations
