Workbook

Sheet Unitary & Crossover
G1: DAY & NIGHT MAY 2025
A2: AC Condensers | D2: Heat Pump Condensers | G2: Crossover Heat Pumps
A3: ION V/S 21 SEER Communicating | D3: ION V/S 23 SEER Communicating | G3: Quiet Comfort Crossover Heat Pump - High Heat
A4: IC5A1V24AKAWA | B4: =VLOOKUP(A4,'Paste Bid Here'!A:F,6,FALSE) -> #N/A | D4: IC5H3V24AKAAA | E4: =VLOOKUP(D4,'Paste Bid Here'!A:F,6,FALSE) -> #N/A | G4: ID5CUHAH24AAK | H4: =VLOOKUP(G4,'Paste Bid Here'!A:F,6,FALSE) -> #N/A
A5: IC5A1V36AKAWA | B5: =VLOOKUP(A5,'Paste Bid Here'!A:F,6,FALSE) -> #N/A | D5: IC5H3V36AKAAA | E5: =VLOOKUP(D5,'Paste Bid Here'!A:F,6,FALSE) -> #N/A | G5: ID5CUHAH30AAK | H5: =VLOOKUP(G5,'Paste Bid Here'!A:F,6,FALSE) -> #N/A
A6: IC5A1V48AKAWA | B6: =VLOOKUP(A6,'Paste Bid Here'!A:F,6,FALSE) -> #N/A | D6: IC5H3V48AKAAA | E6: =VLOOKUP(D6,'Paste Bid Here'!A:F,6,FALSE) -> #N/A | G6: ID5CUHAH36AAK | H6: =VLOOKUP(G6,'Paste Bid Here'!A:F,6,FALSE) -> #N/A
A7: IC5A1V60AKAWA | B7: =VLOOKUP(A7,'Paste Bid Here'!A:F,6,FALSE) -> #N/A | D7: IC5H3V60AKAAA | E7: =VLOOKUP(D7,'Paste Bid Here'!A:F,6,FALSE) -> #N/A | G7: ID5CUHAH48AAK | H7: =VLOOKUP(G7,'Paste Bid Here'!A:F,6,FALSE) -> #N/A
A8: ION Two-Stage 18 SEER Communicating | D8: ION V/S 20 SEER Communicating | G8: ID5CUHAH60AAK | H8: =VLOOKUP(G8,'Paste Bid Here'!A:F,6,FALSE) -> #N/A
A9: IC5A8T24AKAWA | B9: =VLOOKUP(A9,'Paste Bid Here'!A:F,6,FALSE) -> #N/A | D9: IC5H0V24AKAAA | E9: =VLOOKUP(D9,'Paste Bid Here'!A:F,6,FALSE) -> #N/A | G9: Quiet Comfort Crossover Air Handler (115/208/230V)
A10: IC5A8T36AKAWA | B10: =VLOOKUP(A10,'Paste Bid Here'!A:F,6,FALSE) -> #N/A | D10: IC5H0V36AKAAA | E10: =VLOOKUP(D10,'Paste Bid Here'!A:F,6,FALSE) -> #N/A | G10: ID5FUHAH24XAK | H10: =VLOOKUP(G10,'Paste Bid Here'!A:F,6,FALSE) -> #N/A
A11: IC5A8T48AKAWA | B11: =VLOOKUP(A11,'Paste Bid Here'!A:F,6,FALSE) -> #N/A | D11: IC5H0V48AKAAA | E11: =VLOOKUP(D11,'Paste Bid Here'!A:F,6,FALSE) -> #N/A | G11: ID5FUHAH36XAK | H11: =VLOOKUP(G11,'Paste Bid Here'!A:F,6,FALSE) -> #N/A
A12: IC5A8T60AKAWA | B12: =VLOOKUP(A12,'Paste Bid Here'!A:F,6,FALSE) -> #N/A | D12: IC5H0V60AKAAA | E12: =VLOOKUP(D12,'Paste Bid Here'!A:F,6,FALSE) -> #N/A | G12: ID5FUHAH60XAK | H12: =VLOOKUP(G12,'Paste Bid Here'!A:F,6,FALSE) -> #N/A
A13: ION Single Stage 16 SEER Communicating | D13: ION Two Stage 18 SEER Communicating | G13: Performance Crossover Heat Pump - Standard Heat
A14: IC5A6S24AKAWA | B14: =VLOOKUP(A14,'Paste Bid Here'!A:F,6,FALSE) -> #N/A | D14: IC5H8T24AKAAA | E14: =VLOOKUP(D14,'Paste Bid Here'!A:F,6,FALSE) -> #N/A | G14: ID5CURAH24AAK | H14: =VLOOKUP(G14,'Paste Bid Here'!A:F,6,FALSE) -> #N/A
A15: IC5A6S30AKAWA | B15: =VLOOKUP(A15,'Paste Bid Here'!A:F,6,FALSE) -> #N/A | D15: IC5H8T36AKAAA | E15: =VLOOKUP(D15,'Paste Bid Here'!A:F,6,FALSE) -> #N/A | G15: ID5CURAH30AAK | H15: =VLOOKUP(G15,'Paste Bid Here'!A:F,6,FALSE) -> #N/A
A16: IC5A6S36AKAWA | B16: =VLOOKUP(A16,'Paste Bid Here'!A:F,6,FALSE) -> #N/A | D16: IC5H8T48AKAAA | E16: =VLOOKUP(D16,'Paste Bid Here'!A:F,6,FALSE) -> #N/A | G16: ID5CURAH36AAK | H16: =VLOOKUP(G16,'Paste Bid Here'!A:F,6,FALSE) -> #N/A
A17: IC5A6S42AKAWA | B17: =VLOOKUP(A17,'Paste Bid Here'!A:F,6,FALSE) -> #N/A | D17: IC5H8T60AKAAA | E17: =VLOOKUP(D17,'Paste Bid Here'!A:F,6,FALSE) -> #N/A | G17: ID5CURAH48AAK | H17: =VLOOKUP(G17,'Paste Bid Here'!A:F,6,FALSE) -> #N/A
A18: IC5A6S48AKAWA | B18: =VLOOKUP(A18,'Paste Bid Here'!A:F,6,FALSE) -> #N/A | D18: ION Single Stage 15 SEER Communicating | G18: ID5CURAH60AAK | H18: =VLOOKUP(G18,'Paste Bid Here'!A:F,6,FALSE) -> #N/A
A19: IC5A6S60AKAWA | B19: =VLOOKUP(A19,'Paste Bid Here'!A:F,6,FALSE) -> #N/A | D19: IC5H6S24AKAAA | E19: =VLOOKUP(D19,'Paste Bid Here'!A:F,6,FALSE) -> #N/A | G19: Performance Crossover Air Handler - Standard Heat
A20: Performance Series Two Stage 18 SEER | D20: IC5H6S30AKAAA | E20: =VLOOKUP(D20,'Paste Bid Here'!A:F,6,FALSE) -> #N/A | G20: ID5FUAAH24XAK | H20: =VLOOKUP(G20,'Paste Bid Here'!A:F,6,FALSE) -> #N/A
A21: IN5A8T24AKAWA | B21: =VLOOKUP(A21,'Paste Bid Here'!A:F,6,FALSE) -> #N/A | D21: IC5H6S36AKAAA | E21: =VLOOKUP(D21,'Paste Bid Here'!A:F,6,FALSE) -> #N/A | G21: ID5FUAAH30XAK | H21: =VLOOKUP(G21,'Paste Bid Here'!A:F,6,FALSE) -> #N/A
A22: IN5A8T36AKAWA | B22: =VLOOKUP(A22,'Paste Bid Here'!A:F,6,FALSE) -> #N/A | D22: IC5H6S42AKAAA | E22: =VLOOKUP(D22,'Paste Bid Here'!A:F,6,FALSE) -> #N/A | G22: ID5FUAAH36XAK | H22: =VLOOKUP(G22,'Paste Bid Here'!A:F,6,FALSE) -> #N/A
A23: IN5A8T48AKAWA | B23: =VLOOKUP(A23,'Paste Bid Here'!A:F,6,FALSE) -> #N/A | D23: IC5H6S48AKAAA | E23: =VLOOKUP(D23,'Paste Bid Here'!A:F,6,FALSE) -> #N/A | G23: ID5FUAAH48XAK | H23: =VLOOKUP(G23,'Paste Bid Here'!A:F,6,FALSE) -> #N/A
A24: IN5A8T60AKAWA | B24: =VLOOKUP(A24,'Paste Bid Here'!A:F,6,FALSE) -> #N/A | D24: IC5H6S60AKAAA | E24: =VLOOKUP(D24,'Paste Bid Here'!A:F,6,FALSE) -> #N/A | G24: ID5FUAAH60XAK | H24: =VLOOKUP(G24,'Paste Bid Here'!A:F,6,FALSE) -> #N/A
A25: Performance Series Single Stage 15 SEER | D25: Performance Two Stage 17 SEER
A26: IN5A5S18AKAWA | B26: =VLOOKUP(A26,'Paste Bid Here'!A:F,6,FALSE) -> #N/A | D26: IN5H8T24AKAAA | E26: =VLOOKUP(D26,'Paste Bid Here'!A:F,6,FALSE) -> #N/A | G26: Electric Heat Kit - Used w/ D5FUAAH
A27: IN5A5S24AKAWA | B27: =VLOOKUP(A27,'Paste Bid Here'!A:F,6,FALSE) -> #N/A | D27: IN5H8T36AKAAA | E27: =VLOOKUP(D27,'Paste Bid Here'!A:F,6,FALSE) -> #N/A | G27: IEHKMC05KN | H27: =VLOOKUP(G27,'Paste Bid Here'!A:F,6,FALSE) -> #N/A
A28: IN5A5S30AKAWA | B28: =VLOOKUP(A28,'Paste Bid Here'!A:F,6,FALSE) -> #N/A | D28: IN5H8T48AKAAA | E28: =VLOOKUP(D28,'Paste Bid Here'!A:F,6,FALSE) -> #N/A | G28: IEHKMC08KN | H28: =VLOOKUP(G28,'Paste Bid Here'!A:F,6,FALSE) -> #N/A
A29: IN5A5S36AKAWA | B29: =VLOOKUP(A29,'Paste Bid Here'!A:F,6,FALSE) -> #N/A | D29: IN5H8T60AKAAA | E29: =VLOOKUP(D29,'Paste Bid Here'!A:F,6,FALSE) -> #N/A | G29: IEHKMC10KN | H29: =VLOOKUP(G29,'Paste Bid Here'!A:F,6,FALSE) -> #N/A
A30: IN5A5S42AKAWA | B30: =VLOOKUP(A30,'Paste Bid Here'!A:F,6,FALSE) -> #N/A | D30: Performance Single Stage 15 SEER | G30: IEHKMC15KN | H30: =VLOOKUP(G30,'Paste Bid Here'!A:F,6,FALSE) -> #N/A
A31: IN5A5S48AKAWA | B31: =VLOOKUP(A31,'Paste Bid Here'!A:F,6,FALSE) -> #N/A | D31: IN5H5S18AKAAA | E31: =VLOOKUP(D31,'Paste Bid Here'!A:F,6,FALSE) -> #N/A | G31: IEHKMC20KN | H31: =VLOOKUP(G31,'Paste Bid Here'!A:F,6,FALSE) -> #N/A
A32: IN5A5S60AKAWA | B32: =VLOOKUP(A32,'Paste Bid Here'!A:F,6,FALSE) -> #N/A | D32: IN5H5S24AKAAA | E32: =VLOOKUP(D32,'Paste Bid Here'!A:F,6,FALSE) -> #N/A | G32: IEHKMC25KN | H32: =VLOOKUP(G32,'Paste Bid Here'!A:F,6,FALSE) -> #N/A
A33: Performance Series Single Stage 14 SEER | D33: IN5H5S30AKAAA | E33: =VLOOKUP(D33,'Paste Bid Here'!A:F,6,FALSE) -> #N/A | G33: Electric Heat Kit - Used w/ D5FUHAH
A34: IN5A4S18AKANA | B34: =VLOOKUP(A34,'Paste Bid Here'!A:F,6,FALSE) -> #N/A | D34: IN5H5S36AKAAA | E34: =VLOOKUP(D34,'Paste Bid Here'!A:F,6,FALSE) -> #N/A | G34: CEHKMD05KN | H34: NEW
A35: IN5A4S24AKANA | B35: =VLOOKUP(A35,'Paste Bid Here'!A:F,6,FALSE) -> #N/A | D35: IN5H5S42AKAAA | E35: =VLOOKUP(D35,'Paste Bid Here'!A:F,6,FALSE) -> #N/A | G35: CEHKMD08KN | H35: NEW
A36: IN5A4S30AKANA | B36: =VLOOKUP(A36,'Paste Bid Here'!A:F,6,FALSE) -> #N/A | D36: IN5H5S48AKAAA | E36: =VLOOKUP(D36,'Paste Bid Here'!A:F,6,FALSE) -> #N/A | G36: CEHKMD10KN | H36: NEW
A37: IN5A4S36AKANA | B37: =VLOOKUP(A37,'Paste Bid Here'!A:F,6,FALSE) -> #N/A | D37: IN5H5S60AKAAA | E37: =VLOOKUP(D37,'Paste Bid Here'!A:F,6,FALSE) -> #N/A | G37: CEHKMD15KN | H37: NEW
A38: IN5A4S42AKANA | B38: =VLOOKUP(A38,'Paste Bid Here'!A:F,6,FALSE) -> #N/A | G38: CEHKMD20KN | H38: NEW
A39: IN5A4S48AKANA | B39: =VLOOKUP(A39,'Paste Bid Here'!A:F,6,FALSE) -> #N/A
A40: IN5A4S60AKANA | B40: =VLOOKUP(A40,'Paste Bid Here'!A:F,6,FALSE) -> #N/A | G40: ION Wall Control
...

Sheet Single Zone DLS
A1: Single Zone Quick Reference Guide - R-454B Ductless Systems
A2: AHRI Rated Btu's Cooling @ 95F [35C] Heating @ 47F [6.3C] | B2: SEER2 | C2: EER2 | D2: HSPF2 | E2: Indoor Unit With Wireless Remote | F2: SELL $ | G2: Outdoor Unit With Base Pan Heater | H2: SELL $ | I2: Line Set Liquid x Suction | J2: Max. Line Length | K2: Additional Charge ≥ 25ft | L2: Max. Lift | M2: MCA/MOCP | N2: Recommended Fuse Size | O2: Maximum Heating BTU's at -4F [-20C] | P2: Maximum Heating BTU's at 5F [-15C] | Q2: Maximum Cooling BTU's at 110F [43C] | R2: Maximum Cooling BTU's at 122F [50C]
O3: At 70F [21.1C] Indoor DB | Q3: At 80F [26.7C] Indoor DB
A4: Deluxe Series High Wall 1:1 Heat Pump Systems
A5: 6,000/9,000 | B5: 33.1 | C5: 16.5 | D5: 29 | E5: ID5FPHAH06XAK | F5: =VLOOKUP(E5,'Paste Bid Here'!A:F,6,FALSE) -> #N/A | G5: ID5CPRAH06AAK | H5: =VLOOKUP(G5,'Paste Bid Here'!A:F,6,FALSE) -> #N/A | I5: 1/4" x 3/8" | J5: 82.02' | K5: .16 Oz/Ft | L5: 49.21' | M5: 16A / 20A | N5: 20A | O5: 10130 | P5: 13965 | Q5: 15085 | R5: 7892
A6: 9,000/12,000 | B6: 31.5 | C6: 16 | D6: 21 | E6: ID5FPHAH09XAK | F6: =VLOOKUP(E6,'Paste Bid Here'!A:F,6,FALSE) -> #N/A | G6: ID5CPRAH09AAK | H6: =VLOOKUP(G6,'Paste Bid Here'!A:F,6,FALSE) -> #N/A | I6: 1/4" x 3/8" | J6: 82.02' | K6: .16 Oz/Ft | L6: 49.21' | M6: 16A / 20A | N6: 20A | O6: 10130 | P6: 13965 | Q6: 15085 | R6: 7892
A7: 12,000/12,000 | B7: 28 | C7: 13.5 | D7: 13.5 | E7: ID5FPHAH12XAK | F7: =VLOOKUP(E7,'Paste Bid Here'!A:F,6,FALSE) -> #N/A | G7: ID5CPRAH12AAK | H7: =VLOOKUP(G7,'Paste Bid Here'!A:F,6,FALSE) -> #N/A | I7: 1/4" x 3/8" | J7: 82.02' | K7: .16 Oz/Ft | L7: 49.21' | M7: 16A / 20A | N7: 20A | O7: 10130 | P7: 13965 | Q7: 15085 | R7: 7892
A8: 18,000/20,000 | B8: 24.5 | C8: 14 | D8: 15.2 | E8: ID5FPHAH18XAK | F8: =VLOOKUP(E8,'Paste Bid Here'!A:F,6,FALSE) -> #N/A | G8: ID5CPRAH18AAK | H8: =VLOOKUP(G8,'Paste Bid Here'!A:F,6,FALSE) -> #N/A | I8: 3/8" x 5/8" | J8: 164.04' | K8: .32 Oz/Ft | L8: 82.02' | M8: 24.9A / 25A | N8: 25A | O8: 20482 | P8: 24809 | Q8: 23263 | R8: 13286
A9: QuietComfort Series High Wall 1:1 Heat Pump Systems
A10: 6,000/7,000 | B10: 25.7 | C10: 18 | D10: 14.8 | E10: ID5FSHAH06XAK | F10: =VLOOKUP(E10,'Paste Bid Here'!A:F,6,FALSE) -> #N/A | G10: ID5CSHAH06AAK | H10: =VLOOKUP(G10,'Paste Bid Here'!A:F,6,FALSE) -> #N/A | I10: 1/4" x 3/8" | J10: 82.02' | K10: .16 Oz/Ft | L10: 49.21' | M10: 12A / 15A | N10: 15A | O10: 5125 | P10: 7700 | Q10: 10717 | R10: 7571
A11: 9,000/12,000 | B11: 27.5 | C11: 15.5 | D11: 12.5 | E11: ID5FSHAH09XAK | F11: =VLOOKUP(E11,'Paste Bid Here'!A:F,6,FALSE) -> #N/A | G11: ID5CSHAH09AAK | H11: =VLOOKUP(G11,'Paste Bid Here'!A:F,6,FALSE) -> #N/A | I11: 1/4" x 3/8" | J11: 82.02' | K11: .16 Oz/Ft | L11: 49.21' | M11: 15A / 15A | N11: 15A | O11: 8080 | P11: 11500 | Q11: 11215 | R11: 7447
A12: 12,000/12,000 | B12: 25.5 | C12: 13.5 | D12: 10.5 | E12: ID5FSHAH12XAK | F12: =VLOOKUP(E12,'Paste Bid Here'!A:F,6,FALSE) -> #N/A | G12: ID5CSHAH12AAK | H12: =VLOOKUP(G12,'Paste Bid Here'!A:F,6,FALSE) -> #N/A | I12: 1/4" x 3/8" | J12: 82.02' | K12: .16 Oz/Ft | L12: 49.21' | M12: 15A / 15A | N12: 15A | O12: 9260 | P12: 11500 | Q12: 12194 | R12: 6490
A13: 18,000/18,000 | B13: 21.5 | C13: 12.5 | D13: 11 | E13: ID5FSHAH18XAK | F13: =VLOOKUP(E13,'Paste Bid Here'!A:F,6,FALSE) -> #N/A | G13: ID5CSHAH18AAK | H13: =VLOOKUP(G13,'Paste Bid Here'!A:F,6,FALSE) -> #N/A | I13: 1/4" x 1/2" | J13: 98.42' | K13: .16 Oz/Ft | L13: 65.62' | M13: 19A / 20A | N13: 20A | O13: 15050 | P13: 18000 | Q13: 14794 | R13: 10590
A14: 24,000/29,000 | B14: 21.2 | C14: 13 | D14: 13.5 | E14: ID5FSHAH24XAK | F14: =VLOOKUP(E14,'Paste Bid Here'!A:F,6,FALSE) -> #N/A | G14: ID5CSHAH24AAK | H14: =VLOOKUP(G14,'Paste Bid Here'!A:F,6,FALSE) -> #N/A | I14: 3/8" x 5/8" | J14: 164.04' | K14: .32 Oz/Ft | L14: 82.02' | M14: 24.9A / 25A | N14: 25A | O14: 20482 | P14: 24200 | Q14: 23263 | R14: 13286
A15: 33,000/36,000 | B15: 19.6 | C15: 12 | D15: 10.5 | E15: ID5FSHAH33XAK | F15: =VLOOKUP(E15,'Paste Bid Here'!A:F,6,FALSE) -> #N/A | G15: ID5CSHAH33AAK | H15: =VLOOKUP(G15,'Paste Bid Here'!A:F,6,FALSE) -> #N/A | I15: 3/8" x 3/4" | J15: 164.04' | K15: .32 Oz/Ft | L15: 82.02' | M15: 34A / 35A | N15: 35A | O15: 29178 | P15: 35000 | Q15: 32895 | R15: 21554
A16: 12,000/12,000 | B16: 23.5 | C16: 13 | D16: 9.5 | E16: ID5FSHAH12XAJ | F16: =VLOOKUP(E16,'Paste Bid Here'!A:F,6,FALSE) -> #N/A | G16: ID5CSRAH12AAJ | H16: =VLOOKUP(G16,'Paste Bid Here'!A:F,6,FALSE) -> #N/A | I16: 1/4" x 3/8" | J16: 82.02' | K16: .16 Oz/Ft | L16: 49.21' | M16: 18A / 20A | N16: 20A | O16: 4374 | P16: 7700 | Q16: 11229 | R16: 6401
A17: 9,000/10,000 | B17: 26 | C17: 14.9 | D17: 12.5 | E17: ID5FSHAH09XAK | F17: =VLOOKUP(E17,'Paste Bid Here'!A:F,6,FALSE) -> #N/A | G17: ID5CSRAH09AAK | H17: =VLOOKUP(G17,'Paste Bid Here'!A:F,6,FALSE) -> #N/A | I17: 1/4" x 3/8" | J17: 82.02' | K17: .16 Oz/Ft | L17: 49.21' | M17: 12A / 15A | N17: 15A | O17: 7578 | P17: 8000 | Q17: 11188 | R17: 8230
A18: 12,000/12,000 | B18: 25.5 | C18: 13.1 | D18: 10.7 | E18: ID5FSHAH12XAK | F18: =VLOOKUP(E18,'Paste Bid Here'!A:F,6,FALSE) -> #N/A | G18: ID5CSRAH12AAK | H18: =VLOOKUP(G18,'Paste Bid Here'!A:F,6,FALSE) -> #N/A | I18: 1/4" x 3/8" | J18: 82.02' | K18: .16 Oz/Ft | L18: 49.21' | M18: 12A / 15A | N18: 15A | O18: 7175 | P18: 8400 | Q18: 11096 | R18: 7438
A19: 18,000/18,000 | B19: 23.5 | C19: 12.8 | D19: 10.8 | E19: ID5FSHAH18XAK | F19: =VLOOKUP(E19,'Paste Bid Here'!A:F,6,FALSE) -> #N/A | G19: ID5CSRAH18AAK | H19: =VLOOKUP(G19,'Paste Bid Here'!A:F,6,FALSE) -> #N/A | I19: 1/4" x 1/2" | J19: 98.42' | K19: .16 Oz/Ft | L19: 65.62' | M19: 18A / 20A | N19: 20A | O19: 10925 | P19: 12800 | Q19: 14747 | R19: 5496
A20: 24,000/25,000 | B20: 23.1 | C20: 14 | D20: 11.7 | E20: ID5FSHAH24XAK | F20: =VLOOKUP(E20,'Paste Bid Here'!A:F,6,FALSE) -> #N/A | G20: ID5CSRAH24AAK | H20: =VLOOKUP(G20,'Paste Bid Here'!A:F,6,FALSE) -> #N/A | I20: 3/8" x 5/8" | J20: 164.04' | K20: .32 Oz/Ft | L20: 82.02' | M20: 24A / 25A | N20: 25A | O20: 13829 | P20: 19600 | Q20: 23103 | R20: 18744
A21: 30,000/30,000 | B21: 20.5 | C21: 12 | D21: 9.5 | E21: ID5FSHAH30XAK | F21: =VLOOKUP(E21,'Paste Bid Here'!A:F,6,FALSE) -> #N/A | G21: ID5CSRAH30AAK | H21: =VLOOKUP(G21,'Paste Bid Here'!A:F,6,FALSE) -> #N/A | I21: 3/8" x 3/4" | J21: 164.04' | K21: .32 Oz/Ft | L21: 82.02' | M21: 28A / 30A | N21: 30A | O21: 21495 | P21: 20000 | Q21: 26498 | R21: 9359
A22: 36,000/36,000 | B22: 19 | C22: 8.7 | D22: 8.5 | E22: ID5FSHAH36XAK | F22: =VLOOKUP(E22,'Paste Bid Here'!A:F,6,FALSE) -> #N/A | G22: ID5CSRAH36AAK | H22: =VLOOKUP(G22,'Paste Bid Here'!A:F,6,FALSE) -> #N/A | I22: 3/8" x 3/4" | J22: 213.25' | K22: .32 Oz/Ft | L22: 98.43' | M22: 33A / 35A | N22: 35A | O22: 22961 | P22: 22000 | Q22: 26995 | R22: 12885
A23: QuietComfort Series 4-Way Cassette 1:1 Heat Pump Systems
A24: 9,000/10,000 | B24: 22.7 | C24: 14 | D24: 12.2 | E24: ID5FSCAH12XAK | F24: =VLOOKUP(E24,'Paste Bid Here'!A:F,6,FALSE) -> #N/A | G24: ID5CSHAH09AAK | H24: =VLOOKUP(G24,'Paste Bid Here'!A:F,6,FALSE) -> #N/A | I24: 1/4" x 3/8" | J24: 82.02' | K24: .16 Oz/Ft | L24: 49.21' | M24: 15A / 15A | N24: 15A | O24: 7400 | P24: 11000 | Q24: 11100 | R24: 6483
A25: 12,000/12,000 | B25: 23.7 | C25: 12.7 | D25: 11.6 | E25: ID5FSCAH12XAK | F25: =VLOOKUP(E25,'Paste Bid Here'!A:F,6,FALSE) -> #N/A | G25: ID5CSHAH12AAK | H25: =VLOOKUP(G25,'Paste Bid Here'!A:F,6,FALSE) -> #N/A | I25: 1/4" x 3/8" | J25: 82.02' | K25: .16 Oz/Ft | L25: 49.21' | M25: 15A / 15A | N25: 15A | O25: 7500 | P25: 11500 | Q25: 11700 | R25: 6558
A26: 16,000/19,000 | B26: 20 | C26: 12.5 | D26: 12.4 | E26: ID5FSCAH18XAK | F26: =VLOOKUP(E26,'Paste Bid Here'!A:F,6,FALSE) -> #N/A | G26: ID5CSHAH18AAK | H26: =VLOOKUP(G26,'Paste Bid Here'!A:F,6,FALSE) -> #N/A | I26: 1/4" x 1/2" | J26: 98.42' | K26: .16 Oz/Ft | L26: 65.62' | M26: 19A / 20A | N26: 20A | O26: 14000 | P26: 17000 | Q26: 14000 | R26: 9879
A27: 23,500/25,000 | B27: 20.8 | C27: 12 | D27: 11.6 | E27: ID5FSCAH24XAK | F27: =VLOOKUP(E27,'Paste Bid Here'!A:F,6,FALSE) -> #N/A | G27: ID5CSHAH24AAK | H27: =VLOOKUP(G27,'Paste Bid Here'!A:F,6,FALSE) -> #N/A | I27: 3/8" x 5/8" | J27: 164.04' | K27: .32 Oz/Ft | L27: 82.02' | M27: 24.9A / 25A | N27: 25A | O27: 17300 | P27: 23800 | Q27: 21000 | R27: 13293
A28: 36,600/37,000 | B28: 21.3 | C28: 12 | D28: 10.6 | E28: ID5FLCAH36XAK | F28: =VLOOKUP(E28,'Paste Bid Here'!A:F,6,FALSE) -> #N/A | G28: ID5CLHAH36AAK | H28: =VLOOKUP(G28,'Paste Bid Here'!A:F,6,FALSE) -> #N/A | I28: 3/8" x 3/4" | J28: 246' | K28: .32 Oz/Ft | L28: 98.4' | M28: 38A / 40A | N28: 40A | O28: 30100 | P28: 37000 | Q28: 34400 | R28: 16842
A29: 48,000 / 53,000 | B29: 18.2 | C29: 10 | D29: 11 | E29: ID5FLCAH48XAK | F29: =VLOOKUP(E29,'Paste Bid Here'!A:F,6,FALSE) -> #N/A | G29: ID5CLHAH48AAK | H29: =VLOOKUP(G29,'Paste Bid Here'!A:F,6,FALSE) -> #N/A | I29: 3/8" x 3/4" | J29: 246' | K29: .32 Oz/Ft | L29: 98.4' | M29: 44A / 45A | N29: 45A | O29: 38200 | P29: 47500 | Q29: 38700 | R29: 14068
A30: 9,000/10,000 | B30: 21.7 | C30: 14.3 | D30: 11.3 | E30: ID5FSCAH12XAK | F30: =VLOOKUP(E30,'Paste Bid Here'!A:F,6,FALSE) -> #N/A | G30: ID5CSRAH09AAK | H30: =VLOOKUP(G30,'Paste Bid Here'!A:F,6,FALSE) -> #N/A | I30: 1/4" x 3/8" | J30: 82.02' | K30: .16 Oz/Ft | L30: 49.21' | M30: 12A / 15A | N30: 15A | O30: 6100 | P30: 8300 | Q30: 11700 | R30: 7165
A31: 12,000/12,000 | B31: 21.2 | C31: 12.5 | D31: 10.4 | E31: ID5FSCAH12XAK | F31: =VLOOKUP(E31,'Paste Bid Here'!A:F,6,FALSE) -> #N/A | G31: ID5CSRAH12AAK | H31: =VLOOKUP(G31,'Paste Bid Here'!A:F,6,FALSE) -> #N/A | I31: 1/4" x 3/8" | J31: 82.02' | K31: .16 Oz/Ft | L31: 49.21' | M31: 12A / 15A | N31: 15A | O31: 6700 | P31: 8400 | Q31: 11700 | R31: 6735
A32: 16,800/18,000 | B32: 20.8 | C32: 12.5 | D32: 11.4 | E32: ID5FSCAH18XAK | F32: =VLOOKUP(E32,'Paste Bid Here'!A:F,6,FALSE) -> #N/A | G32: ID5CSRAH18AAK | H32: =VLOOKUP(G32,'Paste Bid Here'!A:F,6,FALSE) -> #N/A | I32: 1/4" x 1/2" | J32: 98.42' | K32: .16 Oz/Ft | L32: 65.62' | M32: 18A / 20A | N32: 20A | O32: 10600 | P32: 12800 | Q32: 13400 | R32: 4709
A33: 24,000/25,000 | B33: 22.1 | C33: 12 | D33: 10.5 | E33: ID5FSCAH24XAK | F33: =VLOOKUP(E33,'Paste Bid Here'!A:F,6,FALSE) -> #N/A | G33: ID5CSRAH24AAK | H33: =VLOOKUP(G33,'Paste Bid Here'!A:F,6,FALSE) -> #N/A | I33: 3/8" x 5/8" | J33: 164.04' | K33: .32 Oz/Ft | L33: 82.02' | M33: 24A / 25A | N33: 25A | O33: 12800 | P33: 18500 | Q33: 21000 | R33: 14388
A34: 36,000/38,000 | B34: 20 | C34: 9.7 | D34: 10.4 | E34: ID5FLCAH36XAK | F34: =VLOOKUP(E34,'Paste Bid Here'!A:F,6,FALSE) -> #N/A | G34: ID5CLRAH36AAK | H34: =VLOOKUP(G34,'Paste Bid Here'!A:F,6,FALSE) -> #N/A | I34: 3/8" x 3/4" | J34: 246' | K34: .32 Oz/Ft | L34: 98.4' | M34: 33A / 35A | N34: 35A | O34: 20800 | P34: 26600 | Q34: 28200 | R34: 16644
A35: 48,000/50,000 | B35: 19.1 | C35: 9.5 | D35: 9.9 | E35: ID5FLCAH48XAK | F35: =VLOOKUP(E35,'Paste Bid Here'!A:F,6,FALSE) -> #N/A | G35: ID5CLRAH48AAK | H35: =VLOOKUP(G35,'Paste Bid Here'!A:F,6,FALSE) -> #N/A | I35: 3/8" x 3/4" | J35: 246' | K35: .32 Oz/Ft | L35: 98.4' | M35: 39A / 40A | N35: 40A | O35: 32100 | P35: 40500 | Q35: 40400 | R35: 21475
A36: 9k, 12k, 18k 4-way Cassette Grille | E36: IKSALG0103AAA | F36: =VLOOKUP(E36,'Paste Bid Here'!A:F,6,FALSE) -> #N/A
A37: 24k, 36k, 48k 4-way Cassette Grille | E37: IKSALG0203AAA | F37: =VLOOKUP(E37,'Paste Bid Here'!A:F,6,FALSE) -> #N/A
A38: Ceiling Cassette Grille for 9K, 12K & 18K BTU KSALG0103AAA (unbranded) ~ Ceiling Cassette Grille for 24K, 36K & 48K KSALG0203AAA (unbranded) [Required on all sizes and Sold Separately]
A39: QuietComfort Series 1-Way Cassette 1:1 Heat Pump Systems
A40: 6,500/7,400 | B40: 22 | C40: 15.2 | D40: 12 | E40: ID5FSOAH06XAK | F40: =VLOOKUP(E40,'Paste Bid Here'!A:F,6,FALSE) -> #N/A | G40: ID5CSHAH06AAK | H40: =VLOOKUP(G40,'Paste Bid Here'!A:F,6,FALSE) -> #N/A | I40: 1/4" x 3/8" | J40: 82.02' | K40: .16 Oz/Ft | L40: 49.21' | M40: 12A / 15A | N40: 15A | O40: 6400 | P40: 8100 | Q40: 11200 | R40: 6483
...

Sheet Ducted Solutions
A1: Ducted Solutions Quick Reference Guide | O1: Ductless Systems
A2: AHRI Rated Btu's Cooling @ 95F [35C] Heating @ 47F [6.3C] | B2: SEER2 | C2: EER2 | D2: HSPF2 | E2: Indoor Unit With Factory Installed 24V Interface | F2: SELL $ | G2: Outdoor Unit With Base Pan Heater | H2: SELL $ | I2: Line Set Liquid x Suction | J2: Max. Line Length | K2: Additional Charge ≥ 25ft | L2: Max. Lift | M2: MCA/MOCP | N2: Recommended Fuse Size | O2: Maximum Heating BTU's at -5F [-20F] | P2: Maximum Heating BTU's at 5F [-15C] | Q2: Maximum Cooling BTU's at 113F [45C] | R2: Maximum Cooling BTU's at 122F [50C]
O3: At 69F [20.5C] Indoor DB | Q3: At 75.2F [24C] Indoor DB
A4: This sheet is not intended to replace the installation instructions. It is a reference guide only. Always read through the installation instructions.
A5: QuietComfort Series AHU 1:1 Heat Pump Systems w/ Factory Installed 24V Interface
A6: 18,000/19,500 | B6: 18.2 | C6: 12 | D6: 10.1 | E6: ID5FSAAH18XBK | F6: =VLOOKUP(E6,'Paste Bid Here'!A:F,6,FALSE) -> #N/A | G6: ID5CSHAH18AAK | H6: =VLOOKUP(G6,'Paste Bid Here'!A:F,6,FALSE) -> #N/A | I6: 1/4" x 1/2" | J6: 98.42' | K6: .16 Oz/Ft | L6: 65.62' | M6: 19A / 20A | N6: 20A | O6: 15484 | P6: 18688 | Q6: 17391 | R6: 12157
A7: 23,000/26,000 | B7: 18.8 | C7: 12 | D7: 10 | E7: ID5FSAAH24XBK | F7: =VLOOKUP(E7,'Paste Bid Here'!A:F,6,FALSE) -> #N/A | G7: ID5CSHAH24AAK | H7: =VLOOKUP(G7,'Paste Bid Here'!A:F,6,FALSE) -> #N/A | I7: 3/8" x 5/8" | J7: 164.04' | K7: .32 Oz/Ft | L7: 82.02' | M7: 24.9A / 25A | N7: 25A | O7: 19483 | P7: 24689 | Q7: 25819 | R7: 16531
A8: 33,000/35,000 | B8: 16.7 | C8: 11.7 | D8: 10 | E8: ID5FSAAH30XBK | F8: =VLOOKUP(E8,'Paste Bid Here'!A:F,6,FALSE) -> #N/A | G8: ID5CSHAH33AAK | H8: =VLOOKUP(G8,'Paste Bid Here'!A:F,6,FALSE) -> #N/A | I8: 3/8" x 3/4" | J8: 164.04' | K8: .32 Oz/Ft | L8: 82.02' | M8: 38A / 40A | N8: 40A | O8: 29944 | P8: 35826 | Q8: 34216 | R8: 15385
A9: 36,000/38,000 | B9: 17.3 | C9: 11.7 | D9: 9.5 | E9: ID5FLAAH36XAK | F9: =VLOOKUP(E9,'Paste Bid Here'!A:F,6,FALSE) -> #N/A | G9: ID5CLHCH36AAK | H9: =VLOOKUP(G9,'Paste Bid Here'!A:F,6,FALSE) -> #N/A | I9: 3/8" x 3/4" | J9: 246' | K9: .32 Oz/Ft | L9: 98.4' | M9: 44A / 45A | N9: 45A | O9: 32267 | P9: 39385 | Q9: 33526 | R9: 14764
A10: 48,000/50,000 | B10: 17 | C10: 10.1 | D10: 10.2 | E10: ID5FLAAH48XAK | F10: =VLOOKUP(E10,'Paste Bid Here'!A:F,6,FALSE) -> #N/A | G10: ID5CLHCH48AAK | H10: =VLOOKUP(G10,'Paste Bid Here'!A:F,6,FALSE) -> #N/A | I10: 3/8" x 3/4" | J10: 246' | K10: .32 Oz/Ft | L10: 98.4' | M10: 12A / 15A | N10: 15A | O10: 32097 | P10: 41899 | Q10: 42510 | R10: 27958
A11: 54,000/59,000 | B11: 15.4 | C11: 10 | D11: 9.2 | E11: ID5FLAAH60XAK | F11: =VLOOKUP(E11,'Paste Bid Here'!A:F,6,FALSE) -> #N/A | G11: ID5CLHCH58AAK | H11: =VLOOKUP(G11,'Paste Bid Here'!A:F,6,FALSE) -> #N/A | I11: 3/8" x 3/4" | J11: 246' | K11: .32 Oz/ft | L11: 98.4' | M11: 44A / 45A | N11: 45A | O11: 41493 | P11: 54678 | Q11: 37722 | R11: 10562
A12: 18,000/18,000 | B12: 18.5 | C12: 12.2 | D12: 9.8 | E12: ID5FSAAH18XBK | F12: =VLOOKUP(E12,'Paste Bid Here'!A:F,6,FALSE) -> #N/A | G12: ID5CSRAH18AAK | H12: =VLOOKUP(G12,'Paste Bid Here'!A:F,6,FALSE) -> #N/A | I12: 1/4" x 1/2" | J12: 98.42' | K12: .16 Oz/ft | L12: 65.62' | M12: 18A / 20A | N12: 20A | O12: 10929 | P12: 13689 | Q12: 15398 | R12: 9595
A13: 24,000/25,000 | B13: 19.8 | C13: 11.7 | D13: 9 | E13: ID5FSAAH24XBK | F13: =VLOOKUP(E13,'Paste Bid Here'!A:F,6,FALSE) -> #N/A | G13: ID5CSRAH24AAK | H13: =VLOOKUP(G13,'Paste Bid Here'!A:F,6,FALSE) -> #N/A | I13: 3/8" x 5/8" | J13: 164.04' | K13: .32 Oz/ft | L13: 82.02' | M13: 24A / 25A | N13: 25A | O13: 15364 | P13: 18920 | Q13: 23239 | R13: 15108
A14: 30,000/30,000 | B14: 17 | C14: 11 | D14: 8.8 | E14: ID5FSAAH30XBK | F14: =VLOOKUP(E14,'Paste Bid Here'!A:F,6,FALSE) -> #N/A | G14: ID5CSRAH30AAK | H14: =VLOOKUP(G14,'Paste Bid Here'!A:F,6,FALSE) -> #N/A | I14: 3/8" x 3/4" | J14: 164.04' | K14: .32 Oz/ft | L14: 82.02' | M14: 28A / 30A | N14: 30A | O14: 12966 | P14: 20820 | Q14: 27432 | R14: 9475
A15: 36,000/37,000 | B15: 16 | C15: 8.6 | D15: 7.7 | E15: ID5FSAAH36XBK | F15: =VLOOKUP(E15,'Paste Bid Here'!A:F,6,FALSE) -> #N/A | G15: ID5CSRAH36AAK | H15: =VLOOKUP(G15,'Paste Bid Here'!A:F,6,FALSE) -> #N/A | I15: 3/8" x 3/4" | J15: 213.25' | K15: .32 Oz/ft | L15: 98.43' | M15: 33A / 35A | N15: 35A | O15: 18896 | P15: 23536 | Q15: 27757 | R15: 10062
A16: 36,000/38,000 | B16: 15.9 | C16: 9 | D16: 9.3 | E16: ID5FLAAH36XAK | F16: =VLOOKUP(E16,'Paste Bid Here'!A:F,6,FALSE) -> #N/A | G16: ID5CLRCH36AAK | H16: =VLOOKUP(G16,'Paste Bid Here'!A:F,6,FALSE) -> #N/A | I16: 3/8" x 3/4" | J16: 246' | K16: .32 Oz/ft | L16: 98.4' | M16: 33A / 35A | N16: 35A | O16: 21062 | P16: 24802 | Q16: 28115 | R16: 15282
A17: 48,000/50,000 | B17: 17.8 | C17: 10 | D17: 10 | E17: ID5FLAAH48XAK | F17: =VLOOKUP(E17,'Paste Bid Here'!A:F,6,FALSE) -> #N/A | G17: ID5CLRCH48AAK | H17: =VLOOKUP(G17,'Paste Bid Here'!A:F,6,FALSE) -> #N/A | I17: 3/8" x 3/4" | J17: 246' | K17: .32 Oz/ft | L17: 98.4' | M17: 39A / 40A | N17: 40A | O17: 32653 | P17: 34918 | Q17: 43227 | R17: 21724
A18: 55,000/59,000 | B18: 16 | C18: 9.5 | D18: 9.2 | E18: ID5FLAAH60XAK | F18: =VLOOKUP(E18,'Paste Bid Here'!A:F,6,FALSE) -> #N/A | G18: ID5CLRCH58AAK | H18: =VLOOKUP(G18,'Paste Bid Here'!A:F,6,FALSE) -> #N/A | I18: 3/8" x 3/4" | J18: 246' | K18: .32 Oz/ft | L18: 98.4' | M18: 42A / 45A | N18: 45A | O18: 29985 | P18: 35954 | Q18: 42081 | R18: 19276
A19: QuietComfort AHU 1:1 QuietComfort Heat Pump Systems (Crossover Solutions)
A20: 18,000/18,000 | B20: 19 | C20: 12.5 | D20: 10.2 | E20: ID5FUHAH24XAK | F20: =VLOOKUP(E20,'Paste Bid Here'!A:F,6,FALSE) -> #N/A | G20: ID5CUHAH18AAK | H20: =VLOOKUP(G20,'Paste Bid Here'!A:F,6,FALSE) -> #N/A | I20: 3/8" x 3/4" | J20: 98.42' | K20: .70 Oz/ft | L20: 65.62' | M20: 16A / 20A | N20: 20A | O20: 16514 | P20: 19261 | Q20: 17916 | R20: 14214
A21: 24,000/24,000 | B21: 18.7 | C21: 12 | D21: 10 | E21: ID5FUHAH24XAK | F21: =VLOOKUP(E21,'Paste Bid Here'!A:F,6,FALSE) -> #N/A | G21: ID5CUHAH24AAK | H21: =VLOOKUP(G21,'Paste Bid Here'!A:F,6,FALSE) -> #N/A | I21: 3/8" x 3/4" | J21: 164.04' | K21: .70 Oz/ft | L21: 82.02' | M21: 19A / 20A | N21: 20A | O21: 17927 | P21: 21458 | Q21: 23751 | R21: 17725
A22: 30,000/33,000 | B22: 17.2 | C22: 12.1 | D22: 10.8 | E22: ID5FUHAH36XAK | F22: =VLOOKUP(E22,'Paste Bid Here'!A:F,6,FALSE) -> #N/A | G22: ID5CUHAH30AAK | H22: =VLOOKUP(G22,'Paste Bid Here'!A:F,6,FALSE) -> #N/A | I22: 3/8" x 3/4" | J22: 164.04' | K22: .70 Oz/ft | L22: 82.02' | M22: 29.5A / 30A | N22: 30A | O22: 27252 | P22: 33236 | Q22: 32779 | R22: 20649
A23: 36,000/37,000 | B23: 18 | C23: 12 | D23: 10 | E23: ID5FUHAH36XAK | F23: =VLOOKUP(E23,'Paste Bid Here'!A:F,6,FALSE) -> #N/A | G23: ID5CUHAH36AAK | H23: =VLOOKUP(G23,'Paste Bid Here'!A:F,6,FALSE) -> #N/A | I23: 3/8" x 3/4" | J23: 246' | K23: .70 Oz/ft | L23: 98.43' | M23: 29A / 30A | N23: 30A | O23: 37170 | P23: 38436 | Q23: 38525 | R23: 24495
A24: 48,000/48,000 | B24: 17.5 | C24: 12 | D24: 9.5 | E24: ID5FUHAH60XAK | F24: =VLOOKUP(E24,'Paste Bid Here'!A:F,6,FALSE) -> #N/A | G24: ID5CUHAH48AAK | H24: =VLOOKUP(G24,'Paste Bid Here'!A:F,6,FALSE) -> #N/A | I24: 3/8" x 3/4" | J24: 246' | K24: .70 Oz/ft | L24: 98.43' | M24: 38A / 40A | N24: 40A | O24: 43387 | P24: 48328 | Q24: 45560 | R24: 32789
A25: 54,000/55,000 | B25: 17.5 | C25: 12 | D25: 9.5 | E25: ID5FUHAH60XAK | F25: =VLOOKUP(E25,'Paste Bid Here'!A:F,6,FALSE) -> #N/A | G25: ID5CUHAH60AAK | H25: =VLOOKUP(G25,'Paste Bid Here'!A:F,6,FALSE) -> #N/A | I25: 3/8" x 3/4" | J25: 246' | K25: .70 Oz/ft | L25: 98.43' | M25: 40A / 40A | N25: 40A | O25: 49989 | P25: 56830 | Q25: 53125 | R25: 33738
A26: Performance AHU 1:1 QuietComfort Heat Pump Systems (Crossover Solutions)
A27: 18,000/19,000 | B27: 19 | C27: 12.5 | D27: 9.8 | E27: ID5FUAAH18XAK | F27: =VLOOKUP(E27,'Paste Bid Here'!A:F,6,FALSE) -> #N/A | G27: ID5CUHAH18AAK | H27: =VLOOKUP(G27,'Paste Bid Here'!A:F,6,FALSE) -> #N/A | I27: 3/8" x 3/4" | J27: 98.42' | K27: .70 Oz/ft | L27: 65.62' | M27: 16A / 20A | N27: 20A | O27: 16780 | P27: 19813 | Q27: 18855 | R27: 15316
A28: 23,000/24,000 | B28: 18.4 | C28: 11.7 | D28: 10 | E28: ID5FUAAH24XAK | F28: =VLOOKUP(E28,'Paste Bid Here'!A:F,6,FALSE) -> #N/A | G28: ID5CUHAH24AAK | H28: =VLOOKUP(G28,'Paste Bid Here'!A:F,6,FALSE) -> #N/A | I28: 3/8" x 3/4" | J28: 164.04' | K28: .70 Oz/ft | L28: 82.02' | M28: 19A / 20A | N28: 20A | O28: 17309 | P28: 22891 | Q28: 25051 | R28: 16371
A29: 30,000/34,000 | B29: 16.9 | C29: 11.7 | D29: 10 | E29: ID5FUAAH30XAK | F29: =VLOOKUP(E29,'Paste Bid Here'!A:F,6,FALSE) -> #N/A | G29: ID5CUHAH30AAK | H29: =VLOOKUP(G29,'Paste Bid Here'!A:F,6,FALSE) -> #N/A | I29: 3/8" x 3/4" | J29: 164.04' | K29: .70 Oz/ft | L29: 82.02' | M29: 29.5A / 30A | N29: 30A | O29: 28190 | P29: 33287 | Q29: 32404 | R29: 21287
A30: 36,000/37,000 | B30: 17.4 | C30: 11.7 | D30: 10.3 | E30: ID5FUAAH36XAK | F30: =VLOOKUP(E30,'Paste Bid Here'!A:F,6,FALSE) -> #N/A | G30: ID5CUHAH36AAK | H30: =VLOOKUP(G30,'Paste Bid Here'!A:F,6,FALSE) -> #N/A | I30: 3/8" x 3/4" | J30: 246' | K30: .70 Oz/ft | L30: 98.43' | M30: 29A / 30A | N30: 30A | O30: 35662 | P30: 41538 | Q30: 36996 | R30: 24959
A31: 48,000/50,000 | B31: 16.5 | C31: 10.5 | D31: 9.5 | E31: ID5FUAAH48XAK | F31: =VLOOKUP(E31,'Paste Bid Here'!A:F,6,FALSE) -> #N/A | G31: ID5CUHAH48AAK | H31: =VLOOKUP(G31,'Paste Bid Here'!A:F,6,FALSE) -> #N/A | I31: 3/8" x 3/4" | J31: 246' | K31: .70 Oz/ft | L31: 98.43' | M31: 38A / 40A | N31: 40A | O31: 40674 | P31: 46850 | Q31: 42234 | R31: 30465
A32: 54,000/56,000 | B32: 16 | C32: 10 | D32: 9 | E32: ID5FUAAH60XAK | F32: =VLOOKUP(E32,'Paste Bid Here'!A:F,6,FALSE) -> #N/A | G32: ID5CUHAH60AAK | H32: =VLOOKUP(G32,'Paste Bid Here'!A:F,6,FALSE) -> #N/A | I32: 3/8" x 3/4" | J32: 246' | K32: .70 Oz/ft | L32: 98.43' | M32: 40A / 40A | N32: 40A | O32: 46714 | P32: 54228 | Q32: 50848 | R32: 34671
A33: 18k/24k IDU Capacity select via dip switch and must match ODU size
A34: Performance AHU 1:1 Performance Heat Pump Systems (Crossover Solutions)
A35: 18,000/18,000 | B35: 18.8 | C35: 11 | D35: 9.2 | E35: ID5FUAAH18XAK | F35: =VLOOKUP(E35,'Paste Bid Here'!A:F,6,FALSE) -> #N/A | G35: ID5CURAH18AAK | H35: =VLOOKUP(G35,'Paste Bid Here'!A:F,6,FALSE) -> #N/A | I35: 3/8" x 3/4" | J35: 98.42' | K35: .70 Oz/ft | L35: 65.62' | M35: 16A / 20A | N35: 20A | O35: 9175 | P35: 11379 | Q35: 15815 | R35: 9543
A36: 24,000/26,000 | B36: 18.2 | C36: 11 | D36: 9.7 | E36: ID5FUAAH24XAK | F36: =VLOOKUP(E36,'Paste Bid Here'!A:F,6,FALSE) -> #N/A | G36: ID5CURAH24AAK | H36: =VLOOKUP(G36,'Paste Bid Here'!A:F,6,FALSE) -> #N/A | I36: 3/8" x 3/4" | J36: 164.04' | K36: .70 Oz/ft | L36: 82.02' | M36: 19A / 20A | N36: 20A | O36: 16963 | P36: 22433 | Q36: 24550 | R36: 16043
A37: 30,000/31,000 | B37: 17 | C37: 10.8 | D37: 8.5 | E37: ID5FUAAH30XAK | F37: =VLOOKUP(E37,'Paste Bid Here'!A:F,6,FALSE) -> #N/A | G37: ID5CURAH30AAK | H37: =VLOOKUP(G37,'Paste Bid Here'!A:F,6,FALSE) -> #N/A | I37: 3/8" x 3/4" | J37: 164.04' | K37: .70 Oz/ft | L37: 82.02' | M37: 22.5A / 25A | N37: 25A | O37: 15521 | P37: 19356 | Q37: 29603 | R37: 14498
A38: 36,000/36,000 | B38: 16.2 | C38: 10 | D38: 8.7 | E38: ID5FUAAH36XAK | F38: =VLOOKUP(E38,'Paste Bid Here'!A:F,6,FALSE) -> #N/A | G38: ID5CURAH36AAK | H38: =VLOOKUP(G38,'Paste Bid Here'!A:F,6,FALSE) -> #N/A | I38: 3/8" x 3/4" | J38: 246' | K38: .70 Oz/ft | L38: 98.42' | M38: 24A / 30A | N38: 30A | O38: 22765 | P38: 26515 | Q38: 32032 | R38: 18926
A39: 48,000/48,000 | B39: 16 | C39: 10 | D39: 8.5 | E39: ID5FUAAH48XAK | F39: =VLOOKUP(E39,'Paste Bid Here'!A:F,6,FALSE) -> #N/A | G39: ID5CURAH48AAK | H39: =VLOOKUP(G39,'Paste Bid Here'!A:F,6,FALSE) -> #N/A | I39: 3/8" x 3/4" | J39: 246' | K39: .70 Oz/ft | L39: 98.42' | M39: 36A / 40A | N39: 40A | O39: 35908 | P39: 43152 | Q39: 42022 | R39: 30316
A40: 54,000/54,000 | B40: 15.2 | C40: 8.7 | D40: 8.4 | E40: ID5FUAAH60XAK | F40: =VLOOKUP(E40,'Paste Bid Here'!A:F,6,FALSE) -> #N/A | G40: ID5CURAH60AAK | H40: =VLOOKUP(G40,'Paste Bid Here'!A:F,6,FALSE) -> #N/A | I40: 3/8" x 3/4" | J40: 246' | K40: .70 Oz/ft | L40: 98.42' | M40: 39A / 40A | N40: 40A | O40: 35597 | P40: 41473 | Q40: 41858 | R40: 32571
...

Sheet Multi-Zone DLS
A1: Multizone Quick Reference Guide - R-454B Ductless Systems
A2: Outdoor Unit With Base Pan Heater | B2: SELL $ | C2: Max Zones | D2: Max Heating Capacity BTU's | G2: Maximum Cooling BTU's at 5F [-15C] | I2: Port Combinations | K2: Max Line Set Length Per Zone | L2: Max Total Line Set Length | M2: Pre-Charge Length | N2: Max. Lift | O2: MCA | P2: MOCP | Q2: Recommended Fuse Size
D3: @5F [-15C] | E3: @-13F [-25C] | F3: @-22F [-30C] | G3: @95F [35C] | H3: @109F [43C] | I3: Liquid | J3: Suction
A4: This sheet is not intended to replace the installation instructions. It is a reference guide only. Always read through the installation instructions.
A5: Deluxe System Multi-Zone Heat Pump
A6: ID5CMHAH18CAK | B6: =VLOOKUP(A6,'Paste Bid Here'!A:F,6,FALSE) -> #N/A | C6: 3 | D6: 19000 | E6: 13600 | F6: 11000 | G6: 19000 | H6: 24000 | I6: 3 @ 1/4" | J6: 3 @ 3/8" | K6: 98.4' | L6: 196.9' | M6: 73.8' | N6: 49.21' | O6: 17.5 | P6: 20 | Q6: 20
A7: ID5CMHAH24DAK | B7: =VLOOKUP(A7,'Paste Bid Here'!A:F,6,FALSE) -> #N/A | C7: 4 | D7: 25000 | E7: 17000 | F7: 14000 | G7: 24000 | H7: 32000 | I7: 4 @ 1/4" | J7: 3 @ 3/8" + 1 @ 1/2" | K7: 114.8' | L7: 262.5' | M7: 98.4' | N7: 49.21' | O7: 30 | P7: 35 | Q7: 35
A8: ID5CMHAH30EAK | B8: =VLOOKUP(A8,'Paste Bid Here'!A:F,6,FALSE) -> #N/A | C8: 5 | D8: 36000 | E8: 28000 | F8: 22400 | G8: 30000 | H8: 39000 | I8: 5 @ 1/4" | J8: 3 @ 3/8" + 2 @ 1/2" | K8: 114.8' | L8: 262.5' | M8: 123' | N8: 49.21' | O8: 37 | P8: 40 | Q8: 40
A9: ID5CMHAH36EAK | B9: =VLOOKUP(A9,'Paste Bid Here'!A:F,6,FALSE) -> #N/A | C9: 5 | D9: 36000 | E9: 28000 | F9: 22400 | G9: 36000 | H9: 39000 | I9: 5 @ 1/4" | J9: 3 @ 3/8" + 2 @ 1/2" | K9: 114.8' | L9: 262.5' | M9: 123' | N9: 49.21' | O9: 37 | P9: 40 | Q9: 40
A10: ID5CMHAH48FAK | B10: =VLOOKUP(A10,'Paste Bid Here'!A:F,6,FALSE) -> #N/A | C10: 6 | D10: 47000 | E10: 30000 | F10: 25000 | G10: 47000 | H10: 45000 | I10: 6 @ 1/4" | J10: 4 @ 3/8" + 2 @ 1/2" | K10: 114.8' | L10: 262.5' | M10: 147.6' | N10: 49.21' | O10: 37 | P10: 40 | Q10: 40
A11: ID5CMHAH55FAK | B11: =VLOOKUP(A11,'Paste Bid Here'!A:F,6,FALSE) -> #N/A | C11: 6 | D11: 47000 | E11: 32000 | F11: 26400 | G11: 51000 | H11: 46000 | I11: 6 @ 1/4" | J11: 4 @ 3/8" + 2 @ 1/2" | K11: 114.8' | L11: 262.5' | M11: 147.6' | N11: 49.21' | O11: 39.5 | P11: 40 | Q11: 40
A12: QuietComfort Series Multi-Zone Heat Pump Systems
A13: ID5CMRAH18CAK | B13: =VLOOKUP(A13,'Paste Bid Here'!A:F,6,FALSE) -> #N/A | C13: 3 | D13: 13500 | E13: 8200 | G13: 18000 | H13: 18800 | I13: 3 @ 1/4" | J13: 3 @ 3/8" | K13: 98.4' | L13: 196.9' | M13: 73.8' | N13: 49.21' | O13: 16 | P13: 20 | Q13: 20
A14: ID5CMRAH24DAK | B14: =VLOOKUP(A14,'Paste Bid Here'!A:F,6,FALSE) -> #N/A | C14: 4 | D14: 18000 | E14: 12000 | G14: 24000 | H14: 27400 | I14: 4 @ 1/4" | J14: 3 @ 3/8" + 1 @ 1/2" | K14: 114.8' | L14: 262.5' | M14: 98.4' | N14: 49.21' | O14: 23 | P14: 25 | Q14: 25
A15: ID5CMRAH30EAK | B15: =VLOOKUP(A15,'Paste Bid Here'!A:F,6,FALSE) -> #N/A | C15: 5 | D15: 26000 | E15: 17500 | G15: 30000 | H15: 30600 | I15: 5 @ 1/4" | J15: 3 @ 3/8" + 2 @ 1/2" | K15: 114.8' | L15: 262.5' | M15: 123' | N15: 49.21' | O15: 30.5 | P15: 35 | Q15: 35
A16: ID5CMRAH36EAK | B16: =VLOOKUP(A16,'Paste Bid Here'!A:F,6,FALSE) -> #N/A | C16: 5 | D16: 26000 | E16: 17500 | G16: 36000 | H16: 30600 | I16: 5 @ 1/4" | J16: 3 @ 3/8" + 2 @ 1/2" | K16: 114.8' | L16: 262.5' | M16: 123' | N16: 49.21' | O16: 30.5 | P16: 35 | Q16: 35
A17: ID5CMRAH48FAK | B17: =VLOOKUP(A17,'Paste Bid Here'!A:F,6,FALSE) -> #N/A | C17: 6 | D17: 36000 | E17: 27000 | G17: 47000 | H17: 42000 | I17: 6 @ 1/4" | J17: 4 @ 3/8" + 2 @ 1/2" | K17: 114.8' | L17: 262.5' | M17: 147.6' | N17: 49.21' | O17: 34 | P17: 40 | Q17: 40
A18: ID5CMRAH55FAK | B18: =VLOOKUP(A18,'Paste Bid Here'!A:F,6,FALSE) -> #N/A | C18: 6 | D18: 39000 | E18: 27800 | G18: 60000 | H18: 46000 | I18: 6 @ 1/4" | J18: 4 @ 3/8" + 2 @ 1/2" | K18: 114.8' | L18: 262.5' | M18: 147.6' | N18: 49.21' | O18: 36 | P18: 40 | Q18: 40
A19: Indoor Unit Types, Models, and Approved Btu/hr Combinations
A45: Installation Notes
A46: Port adaptors included with the outdoor units and no branch boxes required.
A47: 10' minimum line length require per zone.
A48: Minimum 2 zones must be connected.
A49: Up to 2 AHUs can be used for the following combinations only: 18+18, 18+24, 18+30, 18+36, 24+24, 24+30, 24+36. In the case that 2 AHU units are selected, no other units may be connected to the outdoor unit, regardless of remaining ports or capacity availability.
A50: When a 30k or 36k AHU is utilized with a Multi-Zone ODU, 500 grams (17.6 Oz) of additional refrigerant should be added to the system.
A51: One-Way Cassette sizing is determined by capacity rotary swith on IDU.
A52: Wi-Fi Kits and Wire Remote Controllers compatible with single or multi-zone as per IDU compatibility.

Sheet Multi-Zone Combination Chart
A1: Multizone Quick Reference Guide - R-454B Ductless Systems
A2: Combinations valid for D5CM(H/R)A units.
B3: Two Zones | D3: Three Zones | G3: Four Zones | L3: Five Zones | Q3: Six Zones
A5: D5CMRAH18CAK | B5: 6+6 | C5: 6+18 | D5: 6+6+6
B6: 6+9 | C6: 9+9 | D6: 6+6+9
B7: 6+12 | C7: 9+12 | D7: 6+9+9
B8: 12+12
A9: D5CMHAH18CAK D5CMRAH24DAK | B9: 6+6 | C9: 9+12 | D9: 6+6+6 | E9: 6+9+18 | F9: 12+12+12 | G9: 6+6+6+6 | H9: 9+9+9+9
B10: 6+9 | C10: 9+18 | D10: 6+6+9 | E10: 6+12+12 | G10: 6+6+6+9
B11: 6+12 | C11: 9+24 | D11: 6+6+12 | E11: 6+12+18 | G11: 6+6+6+12
B12: 6+18 | C12: 12+12 | D12: 6+6+18 | E12: 9+9+9 | G12: 6+6+9+9
B13: 6+24 | C13: 12+18 | D13: 6+6+24 | E13: 9+9+12 | G13: 6+6+9+12
B14: 9+9 | C14: 12+24 | D14: 6+9+9 | E14: 9+9+18 | G14: 6+9+9+9
B15: 18+18 | D15: 6+9+12 | E15: 9+12+12 | G15: 6+9+9+12
A16: 37MGRAQ24DA3 | B16: 6+6 | C16: 9+12 | D16: 6+6+6 | E16: 6+9+18 | F16: 12+12+12 | G16: 6+6+6+6 | H16: 9+9+9+9
B17: 6+9 | C17: 9+18 | D17: 6+6+9 | E17: 6+12+12 | G17: 6+6+6+9
B18: 6+12 | C18: 9+24 | D18: 6+6+12 | E18: 6+12+18 | G18: 6+6+6+12
B19: 6+18 | C19: 12+12 | D19: 6+6+18 | E19: 9+9+9 | G19: 6+6+9+9
B20: 6+24 | C20: 12+18 | D20: 6+6+24 | E20: 9+9+12 | G20: 6+6+9+12
B21: 9+9 | C21: 12+24 | D21: 6+9+9 | E21: 9+9+18 | G21: 6+9+9+9
B22: 18+18 | D22: 6+9+12 | E22: 9+12+12 | G22: 6+9+9+12
A23: D5CMHAH24DAK | B23: 6+18 | C23: 9+24 | D23: 6+6+6 | E23: 6+12+12 | F23: 9+12+12 | G23: 6+6+6+6 | H23: 6+6+12+12 | I23: 6+9+12+18 | J23: 12+12+12+12
B24: 6+24 | C24: 12+12 | D24: 6+6+9 | E24: 6+12+18 | F24: 9+12+18 | G24: 6+6+6+9 | H24: 6+6+12+18 | I24: 6+12+12+12
B25: 9+9 | C25: 12+18 | D25: 6+6+12 | E25: 6+12+24 | F25: 9+12+24 | G25: 6+6+6+12 | H25: 6+6+12+24 | I25: 6+12+12+18
B26: 9+12 | C26: 12+24 | D26: 6+6+18 | E26: 6+18+18 | F26: 9+18+18 | G26: 6+6+6+18 | H26: 6+6+18+18 | I26: 9+9+9+9
B27: 9+18 | C27: 18+18 | D27: 6+6+24 | E27: 6+18+24 | F27: 12+12+12 | G27: 6+6+6+24 | H27: 6+9+9+9 | I27: 9+9+9+12
D28: 6+9+9 | E28: 9+9+9 | F28: 12+12+18 | G28: 6+6+9+9 | H28: 6+9+9+12 | I28: 9+9+9+18
D29: 6+9+12 | E29: 9+9+12 | F29: 12+12+24 | G29: 6+6+9+12 | H29: 6+9+9+18 | I29: 9+9+12+12
D30: 6+9+18 | E30: 9+9+18 | F30: 12+18+18 | G30: 6+6+9+18 | H30: 6+9+9+24 | I30: 9+9+12+18
D31: 6+9+24 | E31: 9+9+24 | G31: 6+6+9+24 | H31: 6+9+12+12 | I31: 9+12+12+12
A32: D5CMRAH30EAK D5CMRAH36EAK | B32: 6+18 | C32: 9+24 | D32: 6+6+6 | E32: 6+12+12 | F32: 9+12+18 | G32: 6+6+6+6 | H32: 6+6+12+12 | I32: 6+9+12+18 | J32: 12+12+12+12 | L32: 6+6+6+6+6 | M32: 6+6+9+9+18
B33: 6+24 | C33: 12+12 | D33: 6+6+9 | E33: 6+12+18 | F33: 9+12+24 | G33: 6+6+6+9 | H33: 6+6+12+18 | I33: 6+12+12+12 | L33: 6+6+6+6+9 | M33: 6+9+9+9+9
B34: 9+9 | C34: 12+18 | D34: 6+6+12 | E34: 6+12+24 | F34: 9+18+18 | G34: 6+6+6+12 | H34: 6+6+12+24 | I34: 6+12+12+18 | L34: 6+6+6+6+12 | M34: 6+9+9+9+12
B35: 9+12 | C35: 12+24 | D35: 6+6+18 | E35: 6+18+18 | F35: 12+12+12 | G35: 6+6+6+18 | H35: 6+6+18+18 | I35: 9+9+9+9 | L35: 6+6+6+6+18 | M35: 6+9+9+9+18
B36: 9+18 | C36: 18+18 | D36: 6+6+24 | E36: 9+9+9 | F36: 12+12+18 | G36: 6+6+6+24 | H36: 6+9+9+9 | I36: 9+9+9+12 | L36: 6+6+6+9+9 | M36: 9+9+9+9+9
D37: 6+9+9 | E37: 9+9+12 | F37: 12+12+24 | G37: 6+6+9+9 | H37: 6+9+9+12 | I37: 9+9+9+18 | L37: 6+6+6+9+12 | M37: 9+9+9+9+12
D38: 6+9+12 | E38: 9+9+18 | F38: 12+18+18 | G38: 6+6+9+12 | H38: 6+9+9+18 | I38: 9+9+12+12 | L38: 6+6+6+9+18
D39: 6+9+18 | E39: 9+9+24 | G39: 6+6+9+18 | H39: 6+9+9+24 | I39: 9+9+12+18 | L39: 6+6+9+9+9
D40: 6+9+24 | E40: 9+12+12 | G40: 6+6+9+24 | H40: 6+9+12+12 | I40: 9+12+12+12 | L40: 6+6+9+9+12
A41: D5CMHAH30EAK D5CMHAH36EAK | B41: 6+24 | C41: 12+18 | D41: 6+6+12 | E41: 6+12+18 | F41: 9+12+18 | G41: 6+6+6+6 | H41: 6+6+12+24 | I41: 6+9+18+24 | J41: 9+9+12+12 | K41: 12+12+12+18 | L41: 6+6+6+6+6 | M41: 6+6+9+9+18
...

Sheet DIM ELEC
A1: A/C CONDENSERS
A2: Item | B2: DIMENSIONS LxWxH (SEE SPECS FOR EXACT DIMENSIONS) | C2: PAD SIZE | D2: MCA | E2: MAX FUSE | F2: LINESET
A3: IC5A1V24AKAWA | B3: 24X24X35 | C3: DIVUC24243CA | D3: 19.4 | E3: 25 | F3: 3/8 X 3/4
A4: IC5A1V36AKAWA | B4: 32X32X35 | C4: DIVUC32323CA | D4: 22.9 | E4: 25 | F4: 3/8 X 3/4
A5: IC5A1V48AKAWA | B5: 32X32X43 | C5: DIVUC32323CA | D5: 30.6 | E5: 40 | F5: 3/8 X 7/8
A6: IC5A1V60AKAWA | B6: 35X35X44 | C6: DIVUC36363CA | D6: 36.9 | E6: 50 | F6: 3/8 X 7/8
A8: IC5A8T24AKAWA | B8: 32X32X35 | C8: DIVUC32323CA | D8: 15.5 | E8: 20 | F8: 3/8 X 3/4
A9: IC5A8T36AKAWA | B9: 35X35X37 | C9: DIVUC36363CA | D9: 20.9 | E9: 35 | F9: 3/8 X 7/8
A10: IC5A8T48AKAWA | B10: 35X35X37 | C10: DIVUC36363CA | D10: 25.5 | E10: 40 | F10: 3/8 X 7/8
A11: IC5A8T60AKAWA | B11: 35X35X41 | C11: DIVUC36363CA | D11: 30.5 | E11: 50 | F11: 3/8 X 7/8
A13: IC5A6S24AKAWA | B13: 32X32X36 | C13: DIVUC32323CA | D13: 13.6 | E13: 20 | F13: 3/8 X 3/4
A14: IC5A6S30AKAWA | B14: 32X32X39 | C14: DIVUC32323CA | D14: 16.5 | E14: 25 | F14: 3/8 X 3/4
A15: IC5A6S36AKAWA | B15: 32X32X33 | C15: DIVUC32323CA | D15: 17.6 | E15: 30 | F15: 3/8 X 7/8
A16: IC5A6S42AKAWA | B16: 32X32X39 | C16: DIVUC32323CA | D16: 22.7 | E16: 40 | F16: 3/8 X 7/8
... A39: IN5A4S60AKANA | B39: 32X32X32 | C39: DIVUC32323CA | D39: 31.1 | E39: 50 | F39: 3/8 X 7/8
A40: 90+% GAS FURNACES | D40: 80% GAS FURNACES
A41: Item | B41: DIMENSIONS LxWxH (SEE SPECS FOR EXACT DIMENSIONS) | D41: Item | E41: DIMENSIONS LxWxH (SEE SPECS FOR EXACT DIMENSIONS)
A42: IG97CMN0601714B | B42: 29.5X17.5X35 | D42: IG80CTL0451712B | E42: 29X17.5X33.25
A43: IG97CMN0602120B | B43: 29.5X21X35 | D43: IG80CTL0701412B | E43: 29X14.5X33.25
A44: IG97CMN0801714B | B44: 29.5X17.5X35 | D44: IG80CTL0701716B | E44: 29X17.5X33.25
A45: IG97CMN0802120B | B45: 29.5X21X35 | D45: IG80CTL0702120B | E45: 29X21X33.5
A46: IG97CMN1002122B | B46: 29.5X21X35 | D46: IG80CTL0901716B | E46: 29X17.5X33.25
A47: IG97CMN1202422B | B47: 29.5X24.5X35 | D47: IG80CTL0902120B | E47: 29X21X33.5
D48: IG80CTL1102120B | E48: 29X21X33.5
A49: IG96CTN0601714B | B49: 29.5X17.5X35 | D49: IG80CTL1352422B | E49: 29X21X33.5
A50: IG96CTN0801714B | B50: 29.5X17.5X35
A51: IG96CTN0802120B | B51: 29.5X21X35 | D51: IN80MSN0451412A | E51: 29X14.5X33.25
A52: IG96CTN1002122B | B52: 29.5X21X35 | D52: IN80MSN0701412A | E52: 29X14.5X33.25
A53: IG96CTN1202422B | B53: 29.5X24.5X35 | D53: IN80MSN0701712A | E53: 29X17.5X33.25
D54: IN80MSN0701716A | E54: 29X17.5X33.25
A55: IG96VTN0401410B | B55: 29.5X14.5X35 | D55: IN80MSN0702116A | E55: 29X21X33.5
A56: IG96VTN0401712B | B56: 29.5X17.5X35 | D56: IN80MSN0901714A | E56: 29X17.5X33.25
A57: IG96VTN0601412B | B57: 29.5X14.5X35 | D57: IN80MSN0902116A | E57: 29X21X33.5
A58: IG96VTN0601716B | B58: 29.5X17.5X35 | D58: IN80MSN0902120A | E58: 29X21X33.5
A59: IG96VTN0801716B | B59: 29.5X17.5X35 | D59: IN80MSN0902420A | E59: 29X24.4X33.5
A60: IG96VTN0802120B | B60: 29.5X21X35 | D60: IN80MSN1102120A | E60: 29X21X33.5
A61: IG96VTN1002120B | B61: 29.5X21X35 | D61: IN80MSN1102420A | E61: 29X24.4X33.5
A62: IG96VTN1002122B | B62: 29.5X21X35 | D62: IN80MSN1352420A | E62: 29X21X33.5
A63: IG96VTN1202422B | B63: 29.5X24.5X35 | D63: IN80MSN1552420A | E63: 29X24.4X33.5
A65: IN96MSN0401410A | B65: 29.5X14.5X35
...

Sheet Paste Bid Here
A1: R454B | B1: B372944
