Workbook

Sheet GAS FURNACES
B1: GAS FURNACES
E2: 46048
B4: Part Number | C4: Ferguson PN | D4: Price | E4: PRODUCT CATEGORY
A5: INFINITY 98% FURNACE WITH GREENSPEED INTELLIGENCE | B5: 59MN7C060C17--14 | C5: C59MN7C060C1714 | D5: =VLOOKUP(C5,'Paste bid here'!A:F,4,FALSE) -> #N/A | E5: BEST
B6: 59MN7C060C21--20 | C6: C59MN7C060C2120 | D6: =VLOOKUP(C6,'Paste bid here'!A:F,4,FALSE) -> #N/A
B7: 59MN7C080C17--14 | C7: C59MN7C080C1714 | D7: =VLOOKUP(C7,'Paste bid here'!A:F,4,FALSE) -> #N/A
B8: 59MN7C080C21--20 | C8: C59MN7C080C2120 | D8: =VLOOKUP(C8,'Paste bid here'!A:F,4,FALSE) -> #N/A
B9: 59MN7C100C21--22 | C9: C59MN7C100C2122 | D9: =VLOOKUP(C9,'Paste bid here'!A:F,4,FALSE) -> #N/A
B10: 59MN7C120C24--22 | C10: C59MN7C120C2422 | D10: =VLOOKUP(C10,'Paste bid here'!A:F,4,FALSE) -> #N/A
A11: INFINITY 97% 2-STAGE VARIABLE SPEED FURNACE | B11: 59TN7A060C1716 | C11: C59TN7A060C1716 | D11: =VLOOKUP(C11,'Paste bid here'!A:F,4,FALSE) -> #N/A
B12: 59TN7A080C1716 | C12: C59TN7A080C1716 | D12: =VLOOKUP(C12,'Paste bid here'!A:F,4,FALSE) -> #N/A
B13: 59TN7A080C2120 | C13: C59TN7A080C2120 | D13: =VLOOKUP(C13,'Paste bid here'!A:F,4,FALSE) -> #N/A
B14: 59TN7A100C2122 | C14: C59TN7A100C2122 | D14: =VLOOKUP(C14,'Paste bid here'!A:F,4,FALSE) -> #N/A
B15: 59TN7A120C2422 | C15: C59TN7A120C2422 | D15: =VLOOKUP(C15,'Paste bid here'!A:F,4,FALSE) -> #N/A
A16: INFINITY 96% 2-STAGE VARIABLE SPEED FURNACE (SELL THESE FIRST) | B16: 59TN6C040C14--10 | C16: C59TN6C040C1410 | D16: =VLOOKUP(C16,'Paste bid here'!A:F,4,FALSE) -> #N/A
B17: 59TN6C060C17--14 | C17: C59TN6C060C1714 | D17: =VLOOKUP(C17,'Paste bid here'!A:F,4,FALSE) -> #N/A
B18: 59TN6C080C17--14 | C18: C59TN6C080C1714 | D18: =VLOOKUP(C18,'Paste bid here'!A:F,4,FALSE) -> #N/A
B19: 59TN6C080C21--20 | C19: C59TN6C080C2120 | D19: =VLOOKUP(C19,'Paste bid here'!A:F,4,FALSE) -> #N/A
B20: 59TN6C100C21--22 | C20: C59TN6C100C2122 | D20: =VLOOKUP(C20,'Paste bid here'!A:F,4,FALSE) -> #N/A
B21: 59TN6C120C24--22 | C21: C59TN6C120C2422 | D21: =VLOOKUP(C21,'Paste bid here'!A:F,4,FALSE) -> #N/A
A22: PERFORMANCE 97% 2-STAGE VARIABLE SPEED FURNACE | B22: 59TP7A060V1716 | C22: C59TP7A060V1716 | D22: =VLOOKUP(C22,'Paste bid here'!A:F,4,FALSE) -> #N/A | E22: BETTER
B23: 59TP7A080V1716 | C23: C59TP7A080V1716 | D23: =VLOOKUP(C23,'Paste bid here'!A:F,4,FALSE) -> #N/A
B24: 59TP7A080V2120 | C24: C59TP7A080V2120 | D24: =VLOOKUP(C24,'Paste bid here'!A:F,4,FALSE) -> #N/A
B25: 59TP7A100V2120 | C25: C59TP7A100V2120 | D25: =VLOOKUP(C25,'Paste bid here'!A:F,4,FALSE) -> #N/A
B26: 59TP7A100V2122 | C26: C59TP7A100V2122 | D26: =VLOOKUP(C26,'Paste bid here'!A:F,4,FALSE) -> #N/A
B27: 59TP7A120V2422 | C27: C59TP7A120V2422 | D27: =VLOOKUP(C27,'Paste bid here'!A:F,4,FALSE) -> #N/A
A28: PERFORMANCE 96% 2-STAGE VARIABLE SPEED FURNACE (SELL THESE FIRST) | B28: 59TP6C040V14--10 | C28: C59TP6C040V1410 | D28: =VLOOKUP(C28,'Paste bid here'!A:F,4,FALSE) -> #N/A
B29: 59TP6C040V17--12 | C29: C59TP6C040V1712 | D29: =VLOOKUP(C29,'Paste bid here'!A:F,4,FALSE) -> #N/A
B30: 59TP6C060V14--12 | C30: C59TP6C060V1412 | D30: =VLOOKUP(C30,'Paste bid here'!A:F,4,FALSE) -> #N/A
B31: 59TP6C060V17--16 | C31: C59TP6C060V1716 | D31: =VLOOKUP(C31,'Paste bid here'!A:F,4,FALSE) -> #N/A
B32: 59TP6C080V17--16 | C32: C59TP6C080V1716 | D32: =VLOOKUP(C32,'Paste bid here'!A:F,4,FALSE) -> #N/A
B33: 59TP6C080V21--20 | C33: C59TP6C080V2120 | D33: =VLOOKUP(C33,'Paste bid here'!A:F,4,FALSE) -> #N/A
B34: 59TP6C100V21--20 | C34: C59TP6C100V2120 | D34: =VLOOKUP(C34,'Paste bid here'!A:F,4,FALSE) -> #N/A
B35: 59TP6C100V21--22 | C35: C59TP6C100V2122 | D35: =VLOOKUP(C35,'Paste bid here'!A:F,4,FALSE) -> #N/A
B36: 59TP6C120V24--22 | C36: C59TP6C120V2422 | D36: =VLOOKUP(C36,'Paste bid here'!A:F,4,FALSE) -> #N/A
A37: COMFORT 96% 1-STAGE FURNACE | B37: 59SC6A026M14--10 | C37: C59SC6A026M1410 | D37: =VLOOKUP(C37,'Paste bid here'!A:F,4,FALSE) -> #N/A | E37: GOOD
B38: 59SC6A040M14--10 | C38: C59SC6A040M1410 | D38: =VLOOKUP(C38,'Paste bid here'!A:F,4,FALSE) -> #N/A
B39: 59SC6A040M17--12 | C39: C59SC6A040M1712 | D39: =VLOOKUP(C39,'Paste bid here'!A:F,4,FALSE) -> #N/A
B40: 59SC6A060M14--12 | C40: C59SC6A060M1412 | D40: =VLOOKUP(C40,'Paste bid here'!A:F,4,FALSE) -> #N/A
B41: 59SC6A060M17--16 | C41: C59SC6A060M1716 | D41: =VLOOKUP(C41,'Paste bid here'!A:F,4,FALSE) -> #N/A
...

Sheet FAN COILS & HEAT STRIPS
B1: FAN COILS & HEAT STRIPS
E2: ='GAS FURNACES'!E2 -> 46048
B4: Part Number | C4: Ferguson PN | D4: Price | E4: PRODUCT CATEGORY
A5: R454B INFINITY SERIES COMMUNICATING FAN COIL | B5: FE5BNXB24L00 | C5: CFE5BNXB24L00 | D5: =VLOOKUP(C7,'Paste bid here'!A:F,4,FALSE) -> #N/A | E5: BEST
B6: FE5BNXC36L00 | C6: CFE5BNXC36L00 | D6: =VLOOKUP(C9,'Paste bid here'!A:F,4,FALSE) -> #N/A | E6: *Use Slope Coil Downflow Kit
B7: FE5BNBC36L00 | C7: CFE5BNBC36L00 | D7: =VLOOKUP(C10,'Paste bid here'!A:F,4,FALSE) -> #N/A | E7: *FE5BNB MODELS ARE MODULAR 2-PIECE CABINET DESIGN
B8: FE5BNXC48L00 | C8: CFE5BNXC48L00 | D8: =VLOOKUP(C5,'Paste bid here'!A:F,4,FALSE) -> #N/A | E8: *FE5BNX MODELS ARE 1-PIECE CABINET DESIGN
B9: FE5BNBC48L00 | C9: CFE5BNBC48L00 | D9: =VLOOKUP(C6,'Paste bid here'!A:F,4,FALSE) -> #N/A
B10: FE5BNBD60L00 | C10: CFE5BNBD60L00 | D10: =VLOOKUP(C8,'Paste bid here'!A:F,4,FALSE) -> #N/A
A11: R454B PERFORMANCE SERIES VARIABLE SPEED FAN COIL | B11: FT5ANXB24L00 | C11: CFT5ANXB24L00 | D11: =VLOOKUP(C11,'Paste bid here'!A:F,4,FALSE) -> #N/A | E11: BETTER
B12: FT5ANBC36L00 | C12: CFT5ANBC36L00 | D12: =VLOOKUP(C12,'Paste bid here'!A:F,4,FALSE) -> #N/A | E12: *Use Slope Coil Downflow Kit
B13: FT5ANBC48L00 | C13: CFT5ANBC48L00 | D13: =VLOOKUP(C13,'Paste bid here'!A:F,4,FALSE) -> #N/A | E13: *FT5ANB MODELS ARE MODULAR 2-PIECE CABINET DESIGN
B14: FT5ANBD60L00 | C14: CFT5ANBD60L00 | D14: =VLOOKUP(C14,'Paste bid here'!A:F,4,FALSE) -> #N/A | E14: *FT5ANX MODELS ARE 1-PIECE CABINET DESIGN
A15: R454B COMFORT SERIES FAN COIL | B15: FJ5ANXA18L00 | C15: CFJ5ANXA18L00 | D15: =VLOOKUP(C15,'Paste bid here'!A:F,4,FALSE) -> #N/A | E15: GOOD
B16: FJ5ANXB24L00 | C16: CFJ5ANXB24L00 | D16: =VLOOKUP(C16,'Paste bid here'!A:F,4,FALSE) -> #N/A | E16: *Use Slope Coil Downflow Kit
B17: FJ5ANXB30L00 | C17: CFJ5ANXB30L00 | D17: =VLOOKUP(C17,'Paste bid here'!A:F,4,FALSE) -> #N/A
B18: FJ5ANXB36L00 | C18: CFJ5ANXB36L00 | D18: =VLOOKUP(C18,'Paste bid here'!A:F,4,FALSE) -> #N/A
B19: FJ5ANXC42L00 | C19: CFJ5ANXC42L00 | D19: =VLOOKUP(C19,'Paste bid here'!A:F,4,FALSE) -> #N/A
B20: FJ5ANXC48L00 | C20: CFJ5ANXC48L00 | D20: =VLOOKUP(C20,'Paste bid here'!A:F,4,FALSE) -> #N/A
B21: FJ5ANXD60L00 | C21: CFJ5ANXD60L00 | D21: =VLOOKUP(C21,'Paste bid here'!A:F,4,FALSE) -> #N/A
A22: Unitary Strip Heat for FJ, FT, FE4B & FE5B Fan Coils | B22: FF-2401C05 | C22: TFF2401C05 | D22: =VLOOKUP(C22,'Paste bid here'!A:F,4,FALSE) -> #N/A | E22: 5kW sizes 24-60
B23: FF-2501C08 | C23: TFF2501C08 | D23: =VLOOKUP(C23,'Paste bid here'!A:F,4,FALSE) -> #N/A | E23: 8kW sizes 24-60
B24: FF-2601C10 | C24: TFF2601C10 | D24: =VLOOKUP(C24,'Paste bid here'!A:F,4,FALSE) -> #N/A | E24: 10kW sizes 24-60
B25: FF-3101C15 | C25: TFF3101C15 | D25: =VLOOKUP(C25,'Paste bid here'!A:F,4,FALSE) -> #N/A | E25: 15kW sizes 24-60
B26: FF-3301C20 | C26: TFF3301C20 | D26: =VLOOKUP(C26,'Paste bid here'!A:F,4,FALSE) -> #N/A | E26: 20kW sizes 30-60
B27: FF-8401C05 | C27: TFF8401C05 | D27: =VLOOKUP(C27,'Paste bid here'!A:F,4,FALSE) -> #N/A | E27: 5kW size 18 ONLY
B28: FF-8501C08 | C28: TFF8501C08 | D28: =VLOOKUP(C28,'Paste bid here'!A:F,4,FALSE) -> #N/A | E28: 8kW size 18 ONLY
B29: FF-8601C10 | C29: TFF8601C10 | D29: =VLOOKUP(C29,'Paste bid here'!A:F,4,FALSE) -> #N/A | E29: 10kW size 18 ONLY
A30: Downflow Kits - Unitary Fan Coils | B30: KFADC0201SLP | C30: CKFADC0201SLP | D30: =VLOOKUP(C30,'Paste bid here'!A:F,4,FALSE) -> #N/A | E30: Downflow Kit - Slope Coil, FJ5 18-24, FE5/FT5 36
B31: KFADC0401ACL | C31: CKFADC0401ACL | D31: =VLOOKUP(C31,'Paste bid here'!A:F,4,FALSE) -> #N/A | E31: Downflow Kit - A Coil, FJ5 30-60, FE5/FT5 24,48,60
A32: CROSSOVER FAN COILS & HEAT STRIP KITS
A33: R454B CROSSOVER FAN COIL FOR USE W/ 37MUHA | B33: 45MUHAQ24XX3 | C33: C45MUHAQ24XX3 | D33: =VLOOKUP(C33,'Paste bid here'!A:F,4,FALSE) -> #N/A | E33: *Use EHKMD model heat strips
B34: 45MUHAQ36XX3 | C34: C45MUHAQ36XX3 | D34: =VLOOKUP(C34,'Paste bid here'!A:F,4,FALSE) -> #N/A | E34: *MODULAR 2 PIECE CABINET DESIGN
B35: 45MUHAQ60XX3 | C35: C45MUHAQ60XX3 | D35: =VLOOKUP(C35,'Paste bid here'!A:F,4,FALSE) -> #N/A | E35: *4" MEDIA FILTER RACK INCLUDED
E36: *5 TON FAN COIL IS 21" WIDTH
A37: R454B CROSSOVER FAN COIL FOR USE W/ 37MURA/37MUHA | B37: 45MUAAQ18XX3 | C37: C45MUAAQ18XX3 | D37: =VLOOKUP(C37,'Paste bid here'!A:F,4,FALSE) -> #N/A | E37: *SINGLE PIECE CABINET DESIGN
B38: 45MUAAQ24XX3 | C38: C45MUAAQ24XX3 | D38: =VLOOKUP(C38,'Paste bid here'!A:F,4,FALSE) -> #N/A | E38: *Use EHKMC model heat strips
B39: 45MUAAQ30XX3 | C39: C45MUAAQ30XX3 | D39: =VLOOKUP(C39,'Paste bid here'!A:F,4,FALSE) -> #N/A
B40: 45MUAAQ36XX3 | C40: C45MUAAQ36XX3 | D40: =VLOOKUP(C40,'Paste bid here'!A:F,4,FALSE) -> #N/A
B41: 45MUAAQ48XX3 | C41: C45MUAAQ48XX3 | D41: =VLOOKUP(C41,'Paste bid here'!A:F,4,FALSE) -> #N/A
...

Sheet EVAP COILS
B1: EVAP COILS
E2: ='GAS FURNACES'!E2 -> 46048
B4: Part Number | C4: Ferguson PN | D4: Price
A5: R454B UPFLOW / DOWNFLOW CASED V COIL | B5: CVAVA1814XMA | C5: CCVAVA1814XMA | D5: =VLOOKUP(C5,'Paste bid here'!A:F,4,FALSE) -> #N/A
B6: CVAVA1917XMA | C6: CCVAVA1917XMA | D6: =VLOOKUP(C6,'Paste bid here'!A:F,4,FALSE) -> #N/A
B7: CVAVA2414XMA | C7: CCVAVA2414XMA | D7: =VLOOKUP(C7,'Paste bid here'!A:F,4,FALSE) -> #N/A
B8: CVAVA2417XMA | C8: CCVAVA2417XMA | D8: =VLOOKUP(C8,'Paste bid here'!A:F,4,FALSE) -> #N/A
B9: CVAVA2514XMA | C9: CCVAVA2514XMA | D9: =VLOOKUP(C9,'Paste bid here'!A:F,4,FALSE) -> #N/A
B10: CVAVA2517XMA | C10: CCVAVA2517XMA | D10: =VLOOKUP(C10,'Paste bid here'!A:F,4,FALSE) -> #N/A
B11: CVAVA3014XMA | C11: CCVAVA3014XMA | D11: =VLOOKUP(C11,'Paste bid here'!A:F,4,FALSE) -> #N/A
B12: CVAVA3017XMA | C12: CCVAVA3017XMA | D12: =VLOOKUP(C12,'Paste bid here'!A:F,4,FALSE) -> #N/A
B13: CVAVA3117XMA | C13: CCVAVA3117XMA | D13: =VLOOKUP(C13,'Paste bid here'!A:F,4,FALSE) -> #N/A
B14: CVAVA3617XMA | C14: CCVAVA3617XMA | D14: =VLOOKUP(C14,'Paste bid here'!A:F,4,FALSE) -> #N/A
B15: CVAVA3621XMA | C15: CCVAVA3621XMA | D15: =VLOOKUP(C15,'Paste bid here'!A:F,4,FALSE) -> #N/A
B16: CVAVA3721XMA | C16: CCVAVA3721XMA | D16: =VLOOKUP(C16,'Paste bid here'!A:F,4,FALSE) -> #N/A
B17: CVAVA3817XMA | C17: CCVAVA3817XMA | D17: =VLOOKUP(C17,'Paste bid here'!A:F,4,FALSE) -> #N/A
... B27: CVAVA6124XMA | C27: CCVAVA6124XMA | D27: =VLOOKUP(C27,'Paste bid here'!A:F,4,FALSE) -> #N/A
A28: R454B MULTIPOISE CASED V COIL | B28: CVAMA2414XMA | C28: CCVAMA2414XMA | D28: =VLOOKUP(C28,'Paste bid here'!A:F,4,FALSE) -> #N/A
B29: CVAMA2417XMA | C29: CCVAMA2417XMA | D29: =VLOOKUP(C29,'Paste bid here'!A:F,4,FALSE) -> #N/A
B30: CVAMA2517XMA | C30: CCVAMA2517XMA | D30: =VLOOKUP(C30,'Paste bid here'!A:F,4,FALSE) -> #N/A
B31: CVAMA3017XMA | C31: CCVAMA3017XMA | D31: =VLOOKUP(C31,'Paste bid here'!A:F,4,FALSE) -> #N/A
B32: CVAMA3117XMA | C32: CCVAMA3117XMA | D32: =VLOOKUP(C32,'Paste bid here'!A:F,4,FALSE) -> #N/A
B33: CVAMA3217XMA | C33: CCVAMA3217XMA | D33: =VLOOKUP(C33,'Paste bid here'!A:F,4,FALSE) -> #N/A
B34: CVAMA3617XMA | C34: CCVAMA3617XMA | D34: =VLOOKUP(C34,'Paste bid here'!A:F,4,FALSE) -> #N/A
B35: CVAMA4221XMA | C35: CCVAMA4221XMA | D35: =VLOOKUP(C35,'Paste bid here'!A:F,4,FALSE) -> #N/A
B36: CVAMA4321XMA | C36: CCVAMA4321XMA | D36: =VLOOKUP(C36,'Paste bid here'!A:F,4,FALSE) -> #N/A
B37: CVAMA4421XMA | C37: CCVAMA4421XMA | D37: =VLOOKUP(C37,'Paste bid here'!A:F,4,FALSE) -> #N/A
B38: CVAMA4821XMA | C38: CCVAMA4821XMA | D38: =VLOOKUP(C38,'Paste bid here'!A:F,4,FALSE) -> #N/A
B39: CVAMA4921XMA | C39: CCVAMA4921XMA | D39: =VLOOKUP(C39,'Paste bid here'!A:F,4,FALSE) -> #N/A
B40: CVAMA6021XMA | C40: CCVAMA6021XMA | D40: =VLOOKUP(C40,'Paste bid here'!A:F,4,FALSE) -> #N/A
... B42: CVAMA6124XMA | C42: CCVAMA6124XMA | D42: =VLOOKUP(C42,'Paste bid here'!A:F,4,FALSE) -> #N/A
A43: R454B MULTIPOISE CASED A COIL | B43: CAAMP1917AMA | C43: CCAAMP1917AMA | D43: =VLOOKUP(C43,'Paste bid here'!A:F,4,FALSE) -> #N/A
B44: CAAMP2414AMA | C44: CCAAMP2414AMA | D44: =VLOOKUP(C44,'Paste bid here'!A:F,4,FALSE) -> #N/A
B45: CAAMP2417AMA | C45: CCAAMP2417AMA | D45: =VLOOKUP(C45,'Paste bid here'!A:F,4,FALSE) -> #N/A
B46: CAAMP2517AMA | C46: CCAAMP2517AMA | D46: =VLOOKUP(C46,'Paste bid here'!A:F,4,FALSE) -> #N/A
B47: CAAMP3014AMA | C47: CCAAMP3014AMA | D47: =VLOOKUP(C47,'Paste bid here'!A:F,4,FALSE) -> #N/A
B48: CAAMP3017AMA | C48: CCAAMP3017AMA | D48: =VLOOKUP(C48,'Paste bid here'!A:F,4,FALSE) -> #N/A
B49: CAAMP3617AMA | C49: CCAAMP3617AMA | D49: =VLOOKUP(C49,'Paste bid here'!A:F,4,FALSE) -> #N/A
B50: CAAMP3717AMA | C50: CCAAMP3717AMA | D50: =VLOOKUP(C50,'Paste bid here'!A:F,4,FALSE) -> #N/A
B51: CAAMP3721AMA | C51: CCAAMP3721AMA | D51: =VLOOKUP(C51,'Paste bid here'!A:F,4,FALSE) -> #N/A
...

Sheet AIR CONDITIONERS
B1: AIR CONDITIONERS
E2: ='GAS FURNACES'!E2 -> 46048
B4: Part Number | C4: Ferguson PN | D4: Price | E4: PRODUCT CATEGORY
A5: R454B INFINITY SERIES 21 SEER2 VARIABLE SPEED AC | B5: 26VNA124W003 | C5: C26VNA124W003 | D5: =VLOOKUP(C5,'Paste bid here'!A:F,4,FALSE) -> #N/A | E5: BEST
B6: 26VNA136W003 | C6: C26VNA136W003 | D6: =VLOOKUP(C6,'Paste bid here'!A:F,4,FALSE) -> #N/A
B7: 26VNA148W003 | C7: C26VNA148W003 | D7: =VLOOKUP(C7,'Paste bid here'!A:F,4,FALSE) -> #N/A
B8: 26VNA160W003 | C8: C26VNA160W003 | D8: =VLOOKUP(C8,'Paste bid here'!A:F,4,FALSE) -> #N/A
A9: R454B PERFORMANCE 18 SEER2 2-STAGE AC | B9: 26TPA824W003 | C9: C26TPA824W003 | D9: =VLOOKUP(C9,'Paste bid here'!A:F,4,FALSE) -> #N/A | E9: BETTER
B10: 26TPA836W003 | C10: C26TPA836W003 | D10: =VLOOKUP(C10,'Paste bid here'!A:F,4,FALSE) -> #N/A
B11: 26TPA848W003 | C11: C26TPA848W003 | D11: =VLOOKUP(C11,'Paste bid here'!A:F,4,FALSE) -> #N/A
B12: 26TPA860W003 | C12: C26TPA860W003 | D12: =VLOOKUP(C12,'Paste bid here'!A:F,4,FALSE) -> #N/A
A13: R454B PERFORMANCE 16 SEER2 1-STAGE AC | B13: 26SPA618W003 | C13: C26SPA618W003 | D13: =VLOOKUP(C13,'Paste bid here'!A:F,4,FALSE) -> #N/A
B14: 26SPA624W003 | C14: C26SPA624W003 | D14: =VLOOKUP(C14,'Paste bid here'!A:F,4,FALSE) -> #N/A
B15: 26SPA630W003 | C15: C26SPA630W003 | D15: =VLOOKUP(C15,'Paste bid here'!A:F,4,FALSE) -> #N/A
B16: 26SPA636W003 | C16: C26SPA636W003 | D16: =VLOOKUP(C16,'Paste bid here'!A:F,4,FALSE) -> #N/A
B17: 26SPA642W003 | C17: C26SPA642W003 | D17: =VLOOKUP(C17,'Paste bid here'!A:F,4,FALSE) -> #N/A
B18: 26SPA648W003 | C18: C26SPA648W003 | D18: =VLOOKUP(C18,'Paste bid here'!A:F,4,FALSE) -> #N/A
B19: 26SPA660W003 | C19: C26SPA660W003 | D19: =VLOOKUP(C19,'Paste bid here'!A:F,4,FALSE) -> #N/A
A20: R454B COMFORT SERIES 14 SEER2 1-STAGE AC | B20: 26SCA418N003 | C20: C26SCA418N003 | D20: =VLOOKUP(C20,'Paste bid here'!A:F,4,FALSE) -> #N/A | E20: GOOD
B21: 26SCA424N003 | C21: C26SCA424N003 | D21: =VLOOKUP(C21,'Paste bid here'!A:F,4,FALSE) -> #N/A
B22: 26SCA430N003 | C22: C26SCA430N003 | D22: =VLOOKUP(C22,'Paste bid here'!A:F,4,FALSE) -> #N/A
B23: 26SCA436N003 | C23: C26SCA436N003 | D23: =VLOOKUP(C23,'Paste bid here'!A:F,4,FALSE) -> #N/A
B24: 26SCA442N003 | C24: C26SCA442N003 | D24: =VLOOKUP(C24,'Paste bid here'!A:F,4,FALSE) -> #N/A
B25: 26SCA448N003 | C25: C26SCA448N003 | D25: =VLOOKUP(C25,'Paste bid here'!A:F,4,FALSE) -> #N/A
B26: 26SCA460N003 | C26: C26SCA460N003 | D26: =VLOOKUP(C26,'Paste bid here'!A:F,4,FALSE) -> #N/A

Sheet HEAT PUMPS
B1: HEAT PUMPS
E2: ='GAS FURNACES'!E2 -> 46048
B4: Part Number | C4: Ferguson PN | D4: Price | E4: PRODUCT CATEGORY
A5: R454B INFINITY SERIES 23 SEER2 / GREENSPEED INVERTER HEAT PUMP | B5: 27VNA324A003 | C5: C27VNA324A003 | D5: =VLOOKUP(C5,'Paste bid here'!A:F,4,FALSE) -> #N/A | E5: BEST
B6: 27VNA336A003 | C6: C27VNA336A003 | D6: =VLOOKUP(C6,'Paste bid here'!A:F,4,FALSE) -> #N/A
B7: 27VNA348A003 | C7: C27VNA348A003 | D7: =VLOOKUP(C7,'Paste bid here'!A:F,4,FALSE) -> #N/A
B8: 27VNA360A003 | C8: C27VNA360A003 | D8: =VLOOKUP(C8,'Paste bid here'!A:F,4,FALSE) -> #N/A
A9: R454B INFINITY SERIES 20 SEEER2 /GREENSPEED INVERTER HEAT PUMP | B9: 27VNA024A003 | C9: C27VNA024A003 | D9: =VLOOKUP(C9,'Paste bid here'!A:F,4,FALSE) -> #N/A
B10: 27VNA036A003 | C10: C27VNA036A003 | D10: =VLOOKUP(C10,'Paste bid here'!A:F,4,FALSE) -> #N/A
B11: 27VNA048A003 | C11: C27VNA048A003 | D11: =VLOOKUP(C11,'Paste bid here'!A:F,4,FALSE) -> #N/A
B12: 27VNA060A003 | C12: C27VNA060A003 | D12: =VLOOKUP(C12,'Paste bid here'!A:F,4,FALSE) -> #N/A
A13: CROSSOVER HEAT PUMP R454B HIGH HEAT PERFORMANCE SERIES 18 SEER2 INVERTER | B13: 37MUHAQ18AA3 | C13: C37MUHAQ18AA3 | D13: =VLOOKUP(C13,'Paste bid here'!A:F,4,FALSE) -> #N/A | E13: BETTER
B14: 37MUHAQ24AA3 | C14: C37MUHAQ24AA3 | D14: =VLOOKUP(C14,'Paste bid here'!A:F,4,FALSE) -> #N/A
B15: 37MUHAQ30AA3 | C15: C37MUHAQ30AA3 | D15: =VLOOKUP(C15,'Paste bid here'!A:F,4,FALSE) -> #N/A
B16: 37MUHAQ36AA3 | C16: C37MUHAQ36AA3 | D16: =VLOOKUP(C16,'Paste bid here'!A:F,4,FALSE) -> #N/A
B17: 37MUHAQ48AA3 | C17: C37MUHAQ48AA3 | D17: =VLOOKUP(C17,'Paste bid here'!A:F,4,FALSE) -> #N/A
B18: 37MUHAQ60AA3 | C18: C37MUHAQ60AA3 | D18: =VLOOKUP(C18,'Paste bid here'!A:F,4,FALSE) -> #N/A
A19: R454B INTELISENSE PERFORMANCE SERIES 18 SEER2 / 2-STAGE HEAT PUMP | B19: 27TPA824A003 | C19: C27TPA824A003 | D19: =VLOOKUP(C19,'Paste bid here'!A:F,4,FALSE) -> #N/A
B20: 27TPA836A003 | C20: C27TPA836A003 | D20: =VLOOKUP(C20,'Paste bid here'!A:F,4,FALSE) -> #N/A
B21: 27TPA848A003 | C21: C27TPA848A003 | D21: =VLOOKUP(C21,'Paste bid here'!A:F,4,FALSE) -> #N/A
B22: 27TPA860A003 | C22: C27TPA860A003 | D22: =VLOOKUP(C22,'Paste bid here'!A:F,4,FALSE) -> #N/A
A23: R454B INTELISENSE PERFORMANCE SERIES 16 SEER2 / 1-STAGE HEAT PUMP | B23: 27SPA618A003 | C23: C27SPA618A003 | D23: =VLOOKUP(C23,'Paste bid here'!A:F,4,FALSE) -> #N/A
B24: 27SPA624A003 | C24: C27SPA624A003 | D24: =VLOOKUP(C24,'Paste bid here'!A:F,4,FALSE) -> #N/A
B25: 27SPA630A003 | C25: C27SPA630A003 | D25: =VLOOKUP(C25,'Paste bid here'!A:F,4,FALSE) -> #N/A
B26: 27SPA636A003 | C26: C27SPA636A003 | D26: =VLOOKUP(C26,'Paste bid here'!A:F,4,FALSE) -> #N/A
B27: 27SPA642A003 | C27: C27SPA642A003 | D27: =VLOOKUP(C27,'Paste bid here'!A:F,4,FALSE) -> #N/A
B28: 27SPA648A003 | C28: C27SPA648A003 | D28: =VLOOKUP(C28,'Paste bid here'!A:F,4,FALSE) -> #N/A
B29: 27SPA660A003 | C29: C27SPA660A003 | D29: =VLOOKUP(C29,'Paste bid here'!A:F,4,FALSE) -> #N/A
A30: CROSSOVER HEAT PUMP R454B REGULAR HEAT COMFORT SERIES 18 SEER2 INVERTER | B30: 37MURAQ18AA3 | C30: C37MURAQ18AA3 | D30: =VLOOKUP(C30,'Paste bid here'!A:F,4,FALSE) -> #N/A | E30: GOOD
B31: 37MURAQ24AA3 | C31: C37MURAQ24AA3 | D31: =VLOOKUP(C31,'Paste bid here'!A:F,4,FALSE) -> #N/A
B32: 37MURAQ30AA3 | C32: C37MURAQ30AA3 | D32: =VLOOKUP(C32,'Paste bid here'!A:F,4,FALSE) -> #N/A
B33: 37MURAQ36AA3 | C33: C37MURAQ36AA3 | D33: =VLOOKUP(C33,'Paste bid here'!A:F,4,FALSE) -> #N/A
B34: 37MURAQ48AA3 | C34: C37MURAQ48AA3 | D34: =VLOOKUP(C34,'Paste bid here'!A:F,4,FALSE) -> #N/A
B35: 37MURAQ60AA3 | C35: C37MURAQ60AA3 | D35: =VLOOKUP(C35,'Paste bid here'!A:F,4,FALSE) -> #N/A
A36: R454B COMFORT SERIES 16 SEER2 / 1-STAGE HEAT PUMP | B36: 27SCA518A003 | C36: C27SCA518A003 | D36: =VLOOKUP(C36,'Paste bid here'!A:F,4,FALSE) -> #N/A
B37: 27SCA524A003 | C37: C27SCA524A003 | D37: =VLOOKUP(C37,'Paste bid here'!A:F,4,FALSE) -> #N/A
B38: 27SCA530A003 | C38: C27SCA530A003 | D38: =VLOOKUP(C38,'Paste bid here'!A:F,4,FALSE) -> #N/A
B39: 27SCA536A003 | C39: C27SCA536A003 | D39: =VLOOKUP(C39,'Paste bid here'!A:F,4,FALSE) -> #N/A
B40: 27SCA542A003 | C40: C27SCA542A003 | D40: =VLOOKUP(C40,'Paste bid here'!A:F,4,FALSE) -> #N/A
B41: 27SCA548A003 | C41: C27SCA548A003 | D41: =VLOOKUP(C41,'Paste bid here'!A:F,4,FALSE) -> #N/A
...

Sheet ACCESSORIES
B1: ACCESSORIES
E2: ='GAS FURNACES'!E2 -> 46048
B4: Part Number | C4: Ferguson PN | D4: Price | E4: Product Description
A5: Infinity System Controls | B5: SYSTXCCITC01-B | C5: CSYSTXCCITC01C | D5: =VLOOKUP(C5,'Paste bid here'!A:F,4,FALSE) -> #N/A | E5: Infinity Touch Control Smart Wifi - Communicating- Black
B6: SYSTXCCWIC01-B | C6: CSYSTXCCWIC01C | D6: =VLOOKUP(C6,'Paste bid here'!A:F,4,FALSE) -> #N/A | E6: Infinity Touch Control Smart Wifi - Communicating- White
B7: TSTATCCEWF01 | C7: CTSTATCCEWF01 | D7: =VLOOKUP(C7,'Paste bid here'!A:F,4,FALSE) -> #N/A | E7: Carrier Smart Wifi Non-Communicating Thermostat
B8: SYSTXCC4ZC01 | C8: CSYSTXCC4ZC01 | D8: =VLOOKUP(C8,'Paste bid here'!A:F,4,FALSE) -> #N/A | E8: Infinity Damper Control Module - 4-Zones
B9: SYSTXCCNIM01 | C9: CSYSTXCCNIM01 | D9: =VLOOKUP(C9,'Paste bid here'!A:F,4,FALSE) -> #N/A | E9: Infinity NIM module - For use w/non-communicating HP's
B10: SYSTXZNSMS01 | C10: CSYSTXZNSMS01 | D10: =VLOOKUP(C10,'Paste bid here'!A:F,4,FALSE) -> #N/A | E10: Infinity Smart Sensor - Additional Zone Stats
A11: ECOBEE STATS | B11: EB-STATE7P-01 | C11: REBSTATE7P01 | D11: =VLOOKUP(C11,'Paste bid here'!A:F,4,FALSE) -> #N/A | E11: Ecobee 7 Lite Pro - Replaced Ecobee 3 Lite
B12: EB-STATE7ICR-01 | C12: CEBSTATE7ICR01 | D12: =VLOOKUP(C12,'Paste bid here'!A:F,4,FALSE) -> #N/A | E12: NEW Ecobee 7 Lite Pro - Carrier Branded - Intellisense
B13: EB-STATE7PB01 | C13: EEBSTATE7PB01 | D13: =VLOOKUP(C13,'Paste bid here'!A:F,4,FALSE) -> #N/A | E13: Ecobee 7 Lite Pro - Builder Model
B14: EB-STATE3LTICR-01 | C14: CEBSTATE3LTICR01 | D14: =VLOOKUP(C14,'Paste bid here'!A:F,4,FALSE) -> #N/A | E14: Ecobee 3 Lite Pro - Carrier Branded - Intellisense (limited stock)
B15: EB-STATE6P-01 | C15: REBSTATE6P01 | D15: =VLOOKUP(C15,'Paste bid here'!A:F,4,FALSE) -> #N/A | E15: Ecboee Premium Control w/ Smart Sensor
B16: EB-STATE6ICR-01 | C16: CEBSTATE6ICR01 | D16: =VLOOKUP(C16,'Paste bid here'!A:F,4,FALSE) -> #N/A | E16: Ecobee Premium Carrier Branded - Intellisense
B17: EB-STATE6LP-01 | C17: EEBSTATE6LP01 | D17: =VLOOKUP(C17,'Paste bid here'!A:F,4,FALSE) -> #N/A | E17: Ecobee Enhanced Control
B18: EB-STATE6PB01 | C18: EEBSTATE6PB01 | D18: =VLOOKUP(C18,'Paste bid here'!A:F,4,FALSE) -> #N/A | E18: Ecobee Premium - Builder Model
B19: EB-RSHM2PK-01 | C19: REBRSHM2PK01 | D19: =VLOOKUP(C19,'Paste bid here'!A:F,4,FALSE) -> #N/A | E19: Ecobee Wireless Smart Sensors
A20: CARRIER EDGE 2-WIRE STATS | B20: 33CS2PP2S03 | C20: C33CS2PP2S03 | D20: =VLOOKUP(C20,'Paste bid here'!A:F,4,FALSE) -> #N/A | E20: EDGE PRO 2H/2C PROG. STAT
B21: 33CS2PPRH03 | C21: C33CS2PPRH03 | D21: =VLOOKUP(C21,'Paste bid here'!A:F,4,FALSE) -> #N/A | E21: EDGE PRO PROG. STAT WITH HUMIDITY CONTROL
A22: RGF AIR PURIFICATION | B22: REMELEDAS | C22: RREMELEDAS | D22: =VLOOKUP(C22,'Paste bid here'!A:F,4,FALSE) -> #N/A | E22: RGF LED AIR PURIFIER
B23: REMEH | C23: RREMEH | D23: =VLOOKUP(C23,'Paste bid here'!A:F,4,FALSE) -> #N/A | E23: RGF UV AIR PURIFIER
B24: ZEROH4ACT | C24: RZEROH4ACT | D24: =VLOOKUP(C24,'Paste bid here'!A:F,4,FALSE) -> #N/A | E24: RGF ZERO OZONE AIR PURIFIER
B25: SPLITHVACPHI230 | C25: ARFSPLITHVACPHI230 | D25: =VLOOKUP(C25,'Paste bid here'!A:F,4,FALSE) -> #N/A | E25: RGF MINI SPLIT AIR PURIFIER
B26: CLEARSKYMS | C26: ARFCLEARSKYMS | D26: =VLOOKUP(C26,'Paste bid here'!A:F,4,FALSE) -> #N/A | E26: RGF MINI SPLIT AIR PURIFIER-BUDGET OPTION
B27: RPHIPKG524V | C27: RPHIPKG524V | D27: =VLOOKUP(C27,'Paste bid here'!A:F,4,FALSE) -> #N/A | E27: RGF DUCT MOUNTED 5" COMM AIR PURIFICATION SYSTEM
B28: RPHIPKG924V | C28: RPHIPKG924V | D28: =VLOOKUP(C28,'Paste bid here'!A:F,4,FALSE) -> #N/A | E28: RGF DUCT MOUNTED 9" COMM AIR PURIFICATION SYSTEM
B29: CLEARSKYDM | C29: RCLEARSKYDM | D29: =VLOOKUP(C29,'Paste bid here'!A:F,4,FALSE) -> #N/A | E29: RGF DUCT MOUNTED AIR PURIFIER-BUDGET OPTION
A30: AERUS AIR SCRUBBERS | B30: 9960051 | C30: A9960051 | D30: =VLOOKUP(C30,'Paste bid here'!A:F,4,FALSE) -> #N/A | E30: AIR SCRUBBER PURIFIER - OZONE
B31: 9960052 | C31: A9960052 | D31: =VLOOKUP(C31,'Paste bid here'!A:F,4,FALSE) -> #N/A | E31: AIR SCRUBBER PURIFIER - NO OZONE
B32: 00811 | C32: A00811 | D32: =VLOOKUP(C32,'Paste bid here'!A:F,4,FALSE) -> #N/A | E32: LAUNDRY PRO 3.0
B33: 00693 | C33: A00693 | D33: =VLOOKUP(C33,'Paste bid here'!A:F,4,FALSE) -> #N/A | E33: PLUG IN WALL OUTLET PURIFIER - 250 SQ FT
B34: 00746 | C34: A00746 | D34: =VLOOKUP(C34,'Paste bid here'!A:F,4,FALSE) -> #N/A | E34: PURE & CLEAN - STAND ALONE PURIFIER - 2000 SQ FT
A35: Infinity Air Purifiers | B35: DGAPAXX1620 | C35: CDGAPAXX1620 | D35: =VLOOKUP(C35,'Paste bid here'!A:F,4,FALSE) -> #N/A | E35: Infinity Air Purifier 16x20
B36: DGAPAXX1625 | C36: CDGAPAXX1625 | D36: =VLOOKUP(C36,'Paste bid here'!A:F,4,FALSE) -> #N/A | E36: Infinity Air Purifier 16x25
B37: DGAPAXX2020 | C37: CDGAPAXX2020 | D37: =VLOOKUP(C37,'Paste bid here'!A:F,4,FALSE) -> #N/A | E37: Infinity Air Purifier 20x20
B38: DGAPAXX2025 | C38: CDGAPAXX2025 | D38: =VLOOKUP(C38,'Paste bid here'!A:F,4,FALSE) -> #N/A | E38: Infinity Air Purifier 20x25
B39: DGAPAXX2420 | C39: CDGAPAXX2420 | D39: =VLOOKUP(C39,'Paste bid here'!A:F,4,FALSE) -> #N/A | E39: Infinity Air Purifier 24x20
A40: ELECTRONIC AIR CLEANERS | B40: F300E1001 | C40: HF300E1001 | D40: =VLOOKUP(C40,'Paste bid here'!A:F,4,FALSE) -> #N/A | E40: (16X20, 1200 CFM
A41: RGF AIR PURIFICATION | B41: F300E1019 | C41: HF300E1019 | D41: =VLOOKUP(C41,'Paste bid here'!A:F,4,FALSE) -> #N/A | E41: (16X25, 1400 CFM)
...

Sheet MOBILE HOME APPROVED
B1: MOBILE HOME APPROVED
E2: ='GAS FURNACES'!E2 -> 46048
B4: Part Number | C4: Ferguson PN | D4: Price
A5: GAS FURNACES
A6: COMFORT 96% 1-STAGE FURNACE | B6: 59SC6A026M14--10 | C6: C59SC6A026M1410 | D6: =VLOOKUP(C6,'Paste bid here'!A:F,4,FALSE) -> #N/A
B7: 59SC6A040M14--10 | C7: C59SC6A040M1410 | D7: =VLOOKUP(C7,'Paste bid here'!A:F,4,FALSE) -> #N/A
B8: 59SC6A040M17--12 | C8: C59SC6A040M1712 | D8: =VLOOKUP(C8,'Paste bid here'!A:F,4,FALSE) -> #N/A
B9: 59SC6A060M14--12 | C9: C59SC6A060M1412 | D9: =VLOOKUP(C9,'Paste bid here'!A:F,4,FALSE) -> #N/A
B10: 59SC6A060M17--16 | C10: C59SC6A060M1716 | D10: =VLOOKUP(C10,'Paste bid here'!A:F,4,FALSE) -> #N/A
B11: 59SC6A080M17--16 | C11: C59SC6A080M1716 | D11: =VLOOKUP(C11,'Paste bid here'!A:F,4,FALSE) -> #N/A
B12: 59SC6A080M21--20 | C12: C59SC6A080M2120 | D12: =VLOOKUP(C12,'Paste bid here'!A:F,4,FALSE) -> #N/A
B13: 59SC6A100M21--20 | C13: C59SC6A100M2120 | D13: =VLOOKUP(C13,'Paste bid here'!A:F,4,FALSE) -> #N/A
B14: 59SC6A100M21--22 | C14: C59SC6A100M2122 | D14: =VLOOKUP(C14,'Paste bid here'!A:F,4,FALSE) -> #N/A
B15: 59SC6A120M24--22 | C15: C59SC6A120M2422 | D15: =VLOOKUP(C15,'Paste bid here'!A:F,4,FALSE) -> #N/A
B16: 59SC6A140M24--22 | C16: C59SC6A140M2422 | D16: =VLOOKUP(C16,'Paste bid here'!A:F,4,FALSE) -> #N/A
A17: 90% LP CONVERSION KIT | B17: AGAGC9NPS01D | C17: RAGAGC9NPS01E | D17: =VLOOKUP(C17,'Paste bid here'!A:F,4,FALSE) -> #N/A
A18: ELECTRIC FURNACES
A19: R454B PERFORMANCE SERIES VARIABLE SPEED FAN COIL | B19: FT5ANXB24L00 | C19: CFT5ANXB24L00 | D19: =VLOOKUP(C19,'Paste bid here'!A:F,4,FALSE) -> #N/A | E19: BETTER
B20: FT5ANBC36L00 | C20: CFT5ANBC36L00 | D20: =VLOOKUP(C20,'Paste bid here'!A:F,4,FALSE) -> #N/A
B21: FT5ANBC48L00 | C21: CFT5ANBC48L00 | D21: =VLOOKUP(C21,'Paste bid here'!A:F,4,FALSE) -> #N/A
B22: FT5ANBD60L00 | C22: CFT5ANBD60L00 | D22: =VLOOKUP(C22,'Paste bid here'!A:F,4,FALSE) -> #N/A
A23: R454B COMFORT SERIES FAN COIL | B23: FJ5ANXA18L00 | C23: CFJ5ANXA18L00 | D23: =VLOOKUP(C23,'Paste bid here'!A:F,4,FALSE) -> #N/A | E23: GOOD
B24: FJ5ANXB24L00 | C24: CFJ5ANXB24L00 | D24: =VLOOKUP(C24,'Paste bid here'!A:F,4,FALSE) -> #N/A
B25: FJ5ANXB30L00 | C25: CFJ5ANXB30L00 | D25: =VLOOKUP(C25,'Paste bid here'!A:F,4,FALSE) -> #N/A
B26: FJ5ANXB36L00 | C26: CFJ5ANXB36L00 | D26: =VLOOKUP(C26,'Paste bid here'!A:F,4,FALSE) -> #N/A
B27: FJ5ANXC42L00 | C27: CFJ5ANXC42L00 | D27: =VLOOKUP(C27,'Paste bid here'!A:F,4,FALSE) -> #N/A
B28: FJ5ANXC48L00 | C28: CFJ5ANXC48L00 | D28: =VLOOKUP(C28,'Paste bid here'!A:F,4,FALSE) -> #N/A
B29: FJ5ANXD60L00 | C29: CFJ5ANXD60L00 | D29: =VLOOKUP(C29,'Paste bid here'!A:F,4,FALSE) -> #N/A
A30: UNITARY STRIP HEAT FOR FJ & FT FAN COILS | B30: FF-2401C05 | C30: TFF2401C05 | D30: =VLOOKUP(C30,'Paste bid here'!A:F,4,FALSE) -> #N/A | E30: 5kW sizes 24-60
B31: FF-2501C08 | C31: TFF2501C08 | D31: =VLOOKUP(C31,'Paste bid here'!A:F,4,FALSE) -> #N/A | E31: 8kW sizes 24-60
B32: FF-2601C10 | C32: TFF2601C10 | D32: =VLOOKUP(C32,'Paste bid here'!A:F,4,FALSE) -> #N/A | E32: 10kW sizes 24-60
B33: FF-3101C15 | C33: TFF3101C15 | D33: =VLOOKUP(C33,'Paste bid here'!A:F,4,FALSE) -> #N/A | E33: 15kW sizes 24-60
B34: FF-3301C20 | C34: TFF3301C20 | D34: =VLOOKUP(C34,'Paste bid here'!A:F,4,FALSE) -> #N/A | E34: 20kW sizes 30-60
B35: FF-8401C05 | C35: TFF8401C05 | D35: =VLOOKUP(C35,'Paste bid here'!A:F,4,FALSE) -> #N/A | E35: 5kW size 18 ONLY
B36: FF-8501C08 | C36: TFF8501C08 | D36: =VLOOKUP(C36,'Paste bid here'!A:F,4,FALSE) -> #N/A | E36: 10kW size 18 ONLY
B37: FF-8601C10 | C37: TFF8601C10 | D37: =VLOOKUP(C37,'Paste bid here'!A:F,4,FALSE) -> #N/A | E37: 15kW size 18 ONLY
A38: Downflow Kits - Unitary Fan Coils | B38: KFADC0201SLP | C38: CKFADC0201SLP | D38: =VLOOKUP(C38,'Paste bid here'!A:F,4,FALSE) -> #N/A | E38: Downflow Kit - Slope Coil, FJ5 18-24, FE5/FT5 36
B39: KFADC0401ACL | C39: CKFADC0401ACL | D39: =VLOOKUP(C39,'Paste bid here'!A:F,4,FALSE) -> #N/A | E39: Downflow Kit - A Coil, FJ5 30-60, FE5/FT5 24,48,60
B40: MOBILE HOME APPROVED
A43: COILS
...

Sheet CROSSOVER SYSTEMS
C1: R454B Ducted Solutions Quick Reference Guide | R1: Ductless Systems
A2: AHRI Rated Btu's | E2: Indoor Unit w/ | K2: Additional | O2: Maximum | P2: Maximum | Q2: Maximum | R2: Maximum
A3: Cooling @ 95°F / | B3: SEER2 | C3: EER2 | D3: HSPF2 | E3: Factory Installed | F3: Indoor Unit | G3: Outdoor Unit With | H3: Outdoor Unit | I3: Line Set | J3: Max. Line | K3: Charge | L3: Max. Lift | M3: MCA / MOCP | N3: Recommended | O3: Heating BTU's at | P3: Heating BTU's at | Q3: Cooling BTU's at | R3: Cooling BTU's at
A4: Heating @ 47°F | E4: 24V Interface | F4: Price | G4: Base Pan Heater | H4: Price | I4: Liquid x Suction | J4: Length | K4: >25ft | N4: Fuse Size | O4: -5F [-20F] | P4: 5F [-15C] | Q4: 113⁰F | R4: 122⁰F
O5: At 69°F Indoor DB | Q5: At 75.2°F Indoor DB
A6: This Sheet is not intended to replace the Installation Instructions. It is a reference guide only. Always read through the Installation Instructions.
A7: Performance™ Series AHU 1:1 Heat Pump Systems w/ Factory Installed 24V Interface
A8: 18,000/19,500 | B8: 18.2 | C8: 12 | D8: 10.1 | E8: C45MBAAQ18XB3 | F8: =VLOOKUP(E8,'Paste bid here'!A:F,6,FALSE) -> #N/A | G8: C37MAHAQ18AA3 | H8: =VLOOKUP(G8,'Paste bid here'!A:F,6,FALSE) -> #N/A | I8: 1/4" x 1/2" | J8: 98.42' | K8: .16 Oz/Ft | L8: 65.62' | M8: 19A / 20A | N8: 20A | O8: 15484 | P8: 18688 | Q8: 17391 | R8: 12157
A9: 23,000/26,000 | B9: 18.8 | C9: 12 | D9: 10 | E9: C45MBAAQ24XB3 | F9: =VLOOKUP(E9,'Paste bid here'!A:F,6,FALSE) -> #N/A | G9: C37MAHAQ24AA3 | H9: =VLOOKUP(G9,'Paste bid here'!A:F,6,FALSE) -> #N/A | I9: 3/8" x 5/8" | J9: 164.04' | K9: .32 Oz/Ft | L9: 82.02' | M9: 24.9A / 25A | N9: 25A | O9: 19483 | P9: 24689 | Q9: 25819 | R9: 16531
A10: 33,000/35,000 | B10: 16.7 | C10: 11.7 | D10: 10 | E10: C45MBAAQ36XB3 | F10: =VLOOKUP(E10,'Paste bid here'!A:F,6,FALSE) -> #N/A | G10: C37MAHAQ33AA3 | H10: =VLOOKUP(G10,'Paste bid here'!A:F,6,FALSE) -> #N/A | I10: 3/8" x 3/4" | J10: 164.04' | K10: .32 Oz/Ft | L10: 82.02' | M10: 38A / 40A | N10: 40A | O10: 29944 | P10: 35826 | Q10: 34216 | R10: 15385
A11: Performance Series Horizontal Discharge AHU 1:1 Heat Pump Split Systems (Crossover Solutions)
A12: 18,000/18,000 | B12: 19 | C12: 12.5 | D12: 10.2 | E12: C45MUHAQ24XX3 | F12: =VLOOKUP(E12,'Paste bid here'!A:F,6,FALSE) -> #N/A | G12: C37MUHAQ18AA3 | H12: =VLOOKUP(G12,'Paste bid here'!A:F,6,FALSE) -> #N/A | I12: 3/8" x 3/4" | J12: 98.42' | K12: .70 Oz/ft | L12: 65.62' | M12: 16A / 20A | N12: 20A | O12: 16514 | P12: 19261 | Q12: 17916 | R12: 14214
A13: 24,000/24,000 | B13: 18.7 | C13: 12 | D13: 10 | E13: C45MUHAQ24XX3 | F13: =VLOOKUP(E13,'Paste bid here'!A:F,6,FALSE) -> #N/A | G13: C37MUHAQ24AA3 | H13: =VLOOKUP(G13,'Paste bid here'!A:F,6,FALSE) -> #N/A | I13: 3/8" x 3/4" | J13: 164.04' | K13: .70 Oz/ft | L13: 82.02' | M13: 19A / 20A | N13: 20A | O13: 17927 | P13: 21458 | Q13: 23751 | R13: 17725
A14: 30,000/33,000 | B14: 17.2 | C14: 12.1 | D14: 10.8 | E14: C45MUHAQ36XX3 | F14: =VLOOKUP(E14,'Paste bid here'!A:F,6,FALSE) -> #N/A | G14: C37MUHAQ30AA3 | H14: =VLOOKUP(G14,'Paste bid here'!A:F,6,FALSE) -> #N/A | I14: 3/8" x 3/4" | J14: 164.04' | K14: .70 Oz/ft | L14: 82.02' | M14: 29.5A / 30A | N14: 30A | O14: 27252 | P14: 33236 | Q14: 32779 | R14: 20649
A15: 36,000/37,000 | B15: 18 | C15: 12 | D15: 10 | E15: C45MUHAQ36XX3 | F15: =VLOOKUP(E15,'Paste bid here'!A:F,6,FALSE) -> #N/A | G15: C37MUHAQ36AA3 | H15: =VLOOKUP(G15,'Paste bid here'!A:F,6,FALSE) -> #N/A | I15: 3/8" x 3/4" | J15: 246' | K15: .70 Oz/ft | L15: 98.43' | M15: 29A / 30A | N15: 30A | O15: 37170 | P15: 38436 | Q15: 38525 | R15: 24495
A16: 48,000/48,000 | B16: 17.5 | C16: 12 | D16: 9.5 | E16: C45MUHAQ60XX3 | F16: =VLOOKUP(E16,'Paste bid here'!A:F,6,FALSE) -> #N/A | G16: C37MUHAQ48AA3 | H16: =VLOOKUP(G16,'Paste bid here'!A:F,6,FALSE) -> #N/A | I16: 3/8" x 3/4" | J16: 246' | K16: .70 Oz/ft | L16: 98.43' | M16: 38A / 40A | N16: 40A | O16: 43387 | P16: 48328 | Q16: 45560 | R16: 32789
A17: 54,000/55,000 | B17: 17.5 | C17: 12 | D17: 9.5 | E17: C45MUHAQ60XX3 | F17: =VLOOKUP(E17,'Paste bid here'!A:F,6,FALSE) -> #N/A | G17: C37MUHAQ60AA3 | H17: =VLOOKUP(G17,'Paste bid here'!A:F,6,FALSE) -> #N/A | I17: 3/8" x 3/4" | J17: 246' | K17: .70 Oz/ft | L17: 98.43' | M17: 40A / 40A | N17: 40A | O17: 49989 | P17: 56830 | Q17: 53125 | R17: 33738
A18: Performance Series Horizontal Discharge AHU 1:1 Heat Pump Split Systems (Crossover Solutions)
A19: note: 18k/24k IDU Capacity select via dip switch and must match ODU size
A20: 18,000/19,000 | B20: 19 | C20: 12.5 | D20: 9.8 | E20: C45MUAAQ18XX3 | F20: =VLOOKUP(E20,'Paste bid here'!A:F,6,FALSE) -> #N/A | G20: C37MUHAQ18AA3 | H20: =VLOOKUP(G20,'Paste bid here'!A:F,6,FALSE) -> #N/A | I20: 3/8" x 3/4" | J20: 98.42' | K20: .70 Oz/ft | L20: 65.62' | M20: 16A / 20A | N20: 20A | O20: 16780 | P20: 19813 | Q20: 18855 | R20: 15316
A21: 23,000/24,000 | B21: 18.4 | C21: 11.7 | D21: 10 | E21: C45MUAAQ24XX3 | F21: =VLOOKUP(E21,'Paste bid here'!A:F,6,FALSE) -> #N/A | G21: C37MUHAQ24AA3 | H21: =VLOOKUP(G21,'Paste bid here'!A:F,6,FALSE) -> #N/A | I21: 3/8" x 3/4" | J21: 164.04' | K21: .70 Oz/ft | L21: 82.02' | M21: 19A / 20A | N21: 20A | O21: 17309 | P21: 22891 | Q21: 25051 | R21: 16371
A22: 30,000/34,000 | B22: 16.9 | C22: 11.7 | D22: 10 | E22: C45MUAAQ30XX3 | F22: =VLOOKUP(E22,'Paste bid here'!A:F,6,FALSE) -> #N/A | G22: C37MUHAQ30AA3 | H22: =VLOOKUP(G22,'Paste bid here'!A:F,6,FALSE) -> #N/A | I22: 3/8" x 3/4" | J22: 164.04' | K22: .70 Oz/ft | L22: 82.02' | M22: 29.5A / 30A | N22: 30A | O22: 28190 | P22: 33287 | Q22: 32404 | R22: 21287
A23: 36,000/37,000 | B23: 17.4 | C23: 11.7 | D23: 10.3 | E23: C45MUAAQ36XX3 | F23: =VLOOKUP(E23,'Paste bid here'!A:F,6,FALSE) -> #N/A | G23: C37MUHAQ36AA3 | H23: =VLOOKUP(G23,'Paste bid here'!A:F,6,FALSE) -> #N/A | I23: 3/8" x 3/4" | J23: 246' | K23: .70 Oz/ft | L23: 98.43' | M23: 29A / 30A | N23: 30A | O23: 35662 | P23: 41538 | Q23: 36996 | R23: 24959
A24: 48,000/50,000 | B24: 16.5 | C24: 10.5 | D24: 9.5 | E24: C45MUAAQ48XX3 | F24: =VLOOKUP(E24,'Paste bid here'!A:F,6,FALSE) -> #N/A | G24: C37MUHAQ48AA3 | H24: =VLOOKUP(G24,'Paste bid here'!A:F,6,FALSE) -> #N/A | I24: 3/8" x 3/4" | J24: 246' | K24: .70 Oz/ft | L24: 98.43' | M24: 38A / 40A | N24: 40A | O24: 40674 | P24: 46850 | Q24: 42234 | R24: 30465
A25: 54,000/56,000 | B25: 16 | C25: 10 | D25: 9 | E25: C45MUAAQ60XX3 | F25: =VLOOKUP(E25,'Paste bid here'!A:F,6,FALSE) -> #N/A | G25: C37MUHAQ60AA3 | H25: =VLOOKUP(G25,'Paste bid here'!A:F,6,FALSE) -> #N/A | I25: 3/8" x 3/4" | J25: 246' | K25: .70 Oz/ft | L25: 98.43' | M25: 40A / 40A | N25: 40A | O25: 46714 | P25: 54228 | Q25: 50848 | R25: 34671
A26: Comfort Series Horizontal Discharge AHU 1:1 High Capacity Heat Pump Split Systems (Crossover Solutions)
A27: note: 18k/24k IDU Capacity select via dip switch and must match ODU size
A28: 18,000/18,000 | B28: 18.8 | C28: 11 | D28: 9.2 | E28: C45MUAAQ18XX3 | F28: =VLOOKUP(E28,'Paste bid here'!A:F,6,FALSE) -> #N/A | G28: C37MURAQ18AA3 | H28: =VLOOKUP(G28,'Paste bid here'!A:F,6,FALSE) -> #N/A | I28: 3/8" x 3/4" | J28: 98.42' | K28: .70 Oz/ft | L28: 65.62' | M28: 16A / 20A | N28: 20A | O28: 9175 | P28: 11379 | Q28: 15815 | R28: 9543
A29: 24,000/26,000 | B29: 18.2 | C29: 11 | D29: 9.7 | E29: C45MUAAQ24XX3 | F29: =VLOOKUP(E29,'Paste bid here'!A:F,6,FALSE) -> #N/A | G29: C37MURAQ24AA3 | H29: =VLOOKUP(G29,'Paste bid here'!A:F,6,FALSE) -> #N/A | I29: 3/8" x 3/4" | J29: 164.04' | K29: .70 Oz/ft | L29: 82.02' | M29: 19A / 20A | N29: 20A | O29: 16963 | P29: 22433 | Q29: 24550 | R29: 16043
A30: 30,000/31,000 | B30: 17 | C30: 10.8 | D30: 8.5 | E30: C45MUAAQ30XX3 | F30: =VLOOKUP(E30,'Paste bid here'!A:F,6,FALSE) -> #N/A | G30: C37MURAQ30AA3 | H30: =VLOOKUP(G30,'Paste bid here'!A:F,6,FALSE) -> #N/A | I30: 3/8" x 3/4" | J30: 164.04' | K30: .70 Oz/ft | L30: 82.02' | M30: 22.5A / 25A | N30: 25A | O30: 15521 | P30: 19356 | Q30: 29603 | R30: 14498
A31: 36,000/36,000 | B31: 16.2 | C31: 10 | D31: 8.7 | E31: C45MUAAQ36XX3 | F31: =VLOOKUP(E31,'Paste bid here'!A:F,6,FALSE) -> #N/A | G31: C37MURAQ36AA3 | H31: =VLOOKUP(G31,'Paste bid here'!A:F,6,FALSE) -> #N/A | I31: 3/8" x 3/4" | J31: 246' | K31: .70 Oz/ft | L31: 98.42' | M31: 24A / 30A | N31: 30A | O31: 22765 | P31: 26515 | Q31: 32032 | R31: 18926
A32: 48,000/48,000 | B32: 16 | C32: 10 | D32: 8.5 | E32: C45MUAAQ48XX3 | F32: =VLOOKUP(E32,'Paste bid here'!A:F,6,FALSE) -> #N/A | G32: C37MURAQ48AA3 | H32: =VLOOKUP(G32,'Paste bid here'!A:F,6,FALSE) -> #N/A | I32: 3/8" x 3/4" | J32: 246' | K32: .70 Oz/ft | L32: 98.42' | M32: 36A / 40A | N32: 40A | O32: 35908 | P32: 43152 | Q32: 42022 | R32: 30316
A33: 54,000/54,000 | B33: 15.2 | C33: 8.7 | D33: 8.4 | E33: C45MUAAQ60XX3 | F33: =VLOOKUP(E33,'Paste bid here'!A:F,6,FALSE) -> #N/A | G33: C37MURAQ60AA3 | H33: =VLOOKUP(G33,'Paste bid here'!A:F,6,FALSE) -> #N/A | I33: 3/8" x 3/4" | J33: 246' | K33: .70 Oz/ft | L33: 98.42' | M33: 39A / 40A | N33: 40A | O33: 35597 | P33: 41473 | Q33: 41858 | R33: 32571
A34: Accessory Options:
A35: Accessory Electric Heater Kits for 45MBAA & 45MUAA | G35: ACCESSORY ELECTRIC HEATER KITS FOR 45MUHA | L35: OPTIONAL - Accessory Air Purifiers & Media Filters
A36: Model Number | B36: Size | C36: Size Used With | F36: Price | G36: Model Number | H36: Size | I36: Size Used With | K36: Price | L36: Model Number | N36: Description | P36: Size Used With | R36: Price
A37: CEHKMC05KN | B37: 5 kW | C37: 18k, 24k, 30k, 36k | F37: =VLOOKUP(A37,'Paste bid here'!A:F,6,FALSE) -> #N/A | G37: CEHKMD05KN | H37: 5 kW | I37: 24k, 36k | J37: 24k, 36k | K37: =VLOOKUP(G37,'Paste bid here'!A:F,6,FALSE) -> #N/A | L37: CDGAPAXX1620 | N37: Infinity® Air Purifier Size 1620 | P37: 18k, 24k | R37: =VLOOKUP(L37,'Paste bid here'!A:F,6,FALSE) -> #N/A
A38: CEHKMC08KN | B38: 8 kW | C38: 18k, 24k, 30k, 36k, 48k | F38: =VLOOKUP(A38,'Paste bid here'!A:F,6,FALSE) -> #N/A | G38: CEHKMD08KN | H38: 8 kW | I38: 24k, 36k | J38: 24k, 36k | K38: =VLOOKUP(G38,'Paste bid here'!A:F,6,FALSE) -> #N/A | L38: CDGAPAXX2020 | N38: Infinity® Air Purifier Size 2020 | P38: 30k, 36k, 48k | R38: =VLOOKUP(L38,'Paste bid here'!A:F,6,FALSE) -> #N/A
A39: CEHKMC10KN | B39: 10 kW | C39: 18k, 23k, 30k, 36k, 48k, 60k | F39: =VLOOKUP(A39,'Paste bid here'!A:F,6,FALSE) -> #N/A | G39: CEHKMD10KN | H39: 10 kW | I39: 24k, 36k, 60k | J39: 24k, 36k, 60k | K39: =VLOOKUP(G39,'Paste bid here'!A:F,6,FALSE) -> #N/A | L39: CDGAPAXX2420 | N39: Infinity® Air Purifier Size 2420 | P39: 60k | R39: =VLOOKUP(L39,'Paste bid here'!A:F,6,FALSE) -> #N/A
A40: CEHKMC15KN | B40: 15kW | C40: 24k, 30k, 36k, 48k, 60k | F40: =VLOOKUP(A40,'Paste bid here'!A:F,6,FALSE) -> #N/A | G40: CEHKMD15KN | H40: 15kW | I40: 24k, 36k, 60k | J40: 24k, 36k, 60k | K40: =VLOOKUP(G40,'Paste bid here'!A:F,6,FALSE) -> #N/A | L40: HF100F1620 | M40: HF100F1620 | N40: RESIDEO 4" MEDIA CABINET | P40: 1200cfm | R40: =VLOOKUP(L40,'Paste bid here'!A:F,6,FALSE) -> #N/A
...

Sheet DUCTLESS Single-Zone
E1: R454B Single Zone Quick Reference Guide | R1: Ductless Systems
A2: AHRI Rated Btu's | E2: Indoor Unit With Wireless Remote | F2: Indoor Unit Price | G2: Outdoor Unit With Base Pan Heater | H2: Outdoor Unit Price | I2: Line Set Liquid x Suction | J2: Max. Line Length | K2: Additional | L2: Max. Lift | N2: Recommended Fuse Size | O2: Maximum | P2: Maximum | Q2: Maximum | R2: Maximum
A3: Cooling @ 95°F / | B3: SEER2 | C3: EER2 | D3: HSPF2 | K3: Charge | M3: MCA / MOCP | O3: Heating BTU's | P3: Heating BTU's | Q3: Cooling BTU's | R3: Cooling BTU's
A4: Heating @ 47°F | K4: >25ft | O4: at -4⁰F | P4: at 5⁰F | Q4: at 110⁰F | R4: at 122⁰F
A5: This Sheet is not intended to replace the Installation Instructions. It is a reference guide only. Always read through the Installation Instructions.
A6: Infinity™ Series High Wall 1:1 Heat Pump Systems
A7: 6,000/9,000 | B7: 35.1 | C7: 17.5 | D7: 30 | E7: C45MPHAQ06XA3 | F7: =VLOOKUP(E7,'Paste bid here'!A:F,6,FALSE) -> #N/A | G7: C37MPRAQ06AA3 | H7: =VLOOKUP(G7,'Paste bid here'!A:F,6,FALSE) -> #N/A | I7: 1/4" x 3/8" | J7: 82.02' | K7: .16 Oz/Ft | L7: 49.21' | M7: 16A / 20A | N7: 20A | O7: 10130 | P7: 13965 | Q7: 15085 | R7: 7892
A8: 9,000/12,000 | B8: 33.5 | C8: 17 | D8: 22 | E8: C45MPHAQ09XA3 | F8: =VLOOKUP(E8,'Paste bid here'!A:F,6,FALSE) -> #N/A | G8: C37MPRAQ09AA3 | H8: =VLOOKUP(G8,'Paste bid here'!A:F,6,FALSE) -> #N/A | I8: 1/4" x 3/8" | J8: 82.02' | K8: .16 Oz/Ft | L8: 49.21' | M8: 16A / 20A | N8: 20A | O8: 10130 | P8: 13965 | Q8: 15085 | R8: 7892
A9: 12,000/12,000 | B9: 29.5 | C9: 14.3 | D9: 14.5 | E9: C45MPHAQ12XA3 | F9: =VLOOKUP(E9,'Paste bid here'!A:F,6,FALSE) -> #N/A | G9: C37MPRAQ12AA3 | H9: =VLOOKUP(G9,'Paste bid here'!A:F,6,FALSE) -> #N/A | I9: 1/4" x 3/8" | J9: 82.02' | K9: .16 Oz/Ft | L9: 49.21' | M9: 16A / 20A | N9: 20A | O9: 10130 | P9: 13965 | Q9: 15085 | R9: 7892
A10: 18,000/20,000 | B10: 25.8 | C10: 15 | D10: 16.2 | E10: C45MPHAQ18XA3 | F10: =VLOOKUP(E10,'Paste bid here'!A:F,6,FALSE) -> #N/A | G10: C37MPRAQ18AA3 | H10: =VLOOKUP(G10,'Paste bid here'!A:F,6,FALSE) -> #N/A | I10: 3/8" x 5/8" | J10: 164.04' | K10: .32 Oz/Ft | L10: 82.02' | M10: 24.9A / 25A | N10: 25A | O10: 20482 | P10: 24809 | Q10: 23263 | R10: 13286
A11: Performance™ Series High Wall 1:1 Heat Pump Systems
A12: 6,000/7,000 | B12: 25.7 | C12: 18 | D12: 14.8 | E12: C45MAHAQ06XA3 | F12: =VLOOKUP(E12,'Paste bid here'!A:F,6,FALSE) -> #N/A | G12: C37MAHAQ06AA3 | H12: =VLOOKUP(G12,'Paste bid here'!A:F,6,FALSE) -> #N/A | I12: 1/4" x 3/8" | J12: 82.02' | K12: .16 Oz/Ft | L12: 49.21' | M12: 12A / 15A | N12: 15A | O12: 5125 | P12: 7700 | Q12: 10717 | R12: 7571
A13: 9,000/12,000 | B13: 27.5 | C13: 15.5 | D13: 12.5 | E13: C45MAHAQ09XA3 | F13: =VLOOKUP(E13,'Paste bid here'!A:F,6,FALSE) -> #N/A | G13: C37MAHAQ09AA3 | H13: =VLOOKUP(G13,'Paste bid here'!A:F,6,FALSE) -> #N/A | I13: 1/4" x 3/8" | J13: 82.02' | K13: .16 Oz/Ft | L13: 49.21' | M13: 15A / 15A | N13: 15A | O13: 8080 | P13: 11500 | Q13: 11215 | R13: 7447
A14: 12,000/12,000 | B14: 25.5 | C14: 13.5 | D14: 10.5 | E14: C45MAHAQ12XA3 | F14: =VLOOKUP(E14,'Paste bid here'!A:F,6,FALSE) -> #N/A | G14: C37MAHAQ12AA3 | H14: =VLOOKUP(G14,'Paste bid here'!A:F,6,FALSE) -> #N/A | I14: 1/4" x 3/8" | J14: 82.02' | K14: .16 Oz/Ft | L14: 49.21' | M14: 15A / 15A | N14: 15A | O14: 9260 | P14: 11500 | Q14: 12194 | R14: 6490
A15: 18,000/18,000 | B15: 21.5 | C15: 12.5 | D15: 11 | E15: C45MAHAQ18XA3 | F15: =VLOOKUP(E15,'Paste bid here'!A:F,6,FALSE) -> #N/A | G15: C37MAHAQ18AA3 | H15: =VLOOKUP(G15,'Paste bid here'!A:F,6,FALSE) -> #N/A | I15: 1/4" x 1/2" | J15: 98.42' | K15: .16 Oz/Ft | L15: 65.62' | M15: 19A / 20A | N15: 20A | O15: 15050 | P15: 18000 | Q15: 14794 | R15: 10590
A16: 24,000/29,000 | B16: 21.2 | C16: 13 | D16: 13.5 | E16: C45MAHAQ24XA3 | F16: =VLOOKUP(E16,'Paste bid here'!A:F,6,FALSE) -> #N/A | G16: C37MAHAQ24AA3 | H16: =VLOOKUP(G16,'Paste bid here'!A:F,6,FALSE) -> #N/A | I16: 3/8" x 5/8" | J16: 164.04' | K16: .32 Oz/Ft | L16: 82.02' | M16: 24.9A / 25A | N16: 25A | O16: 20482 | P16: 24200 | Q16: 23263 | R16: 13286
A17: 33,000/36,000 | B17: 19.6 | C17: 12 | D17: 10.5 | E17: C45MAHAQ33XA3 | F17: =VLOOKUP(E17,'Paste bid here'!A:F,6,FALSE) -> #N/A | G17: C37MAHAQ33AA3 | H17: =VLOOKUP(G17,'Paste bid here'!A:F,6,FALSE) -> #N/A | I17: 3/8" x 3/4" | J17: 164.04' | K17: .32 Oz/Ft | L17: 82.02' | M17: 34A / 35A | N17: 35A | O17: 29178 | P17: 35000 | Q17: 32895 | R17: 21554
A18: 12,000/12,000 | B18: 23.5 | C18: 13 | D18: 9.5 | E18: C45MAHAQ12XA1 | F18: =VLOOKUP(E18,'Paste bid here'!A:F,6,FALSE) -> #N/A | G18: C37MARAQ12AA1 | H18: =VLOOKUP(G18,'Paste bid here'!A:F,6,FALSE) -> #N/A | I18: 1/4" x 3/8" | J18: 82.02' | K18: .16 Oz/Ft | L18: 49.21' | M18: 18A / 20A | N18: 20A | O18: 4374 | P18: 7700 | Q18: 11229 | R18: 6401
A19: Performance™ Series 4-Way Ceiling Cassette 1:1 Heat Pump Systems
A20: 9,000/10,000 | B20: 22.7 | C20: 14 | D20: 12.2 | E20: C45MBCAQ12XA3 | F20: =VLOOKUP(E20,'Paste bid here'!A:F,6,FALSE) -> #N/A | G20: C37MAHAQ09AA3 | H20: =VLOOKUP(G20,'Paste bid here'!A:F,6,FALSE) -> #N/A | I20: 1/4" x 3/8" | J20: 82.02' | K20: .16 Oz/Ft | L20: 49.21' | M20: 15A / 15A | N20: 15A | O20: 7400 | P20: 11000 | Q20: 11100 | R20: 6483
A21: 12,000/12,000 | B21: 23.7 | C21: 12.7 | D21: 11.6 | E21: C45MBCAQ12XA3 | F21: =VLOOKUP(E21,'Paste bid here'!A:F,6,FALSE) -> #N/A | G21: C37MAHAQ12AA3 | H21: =VLOOKUP(G21,'Paste bid here'!A:F,6,FALSE) -> #N/A | I21: 1/4" x 3/8" | J21: 82.02' | K21: .16 Oz/Ft | L21: 49.21' | M21: 15A / 15A | N21: 15A | O21: 7500 | P21: 11500 | Q21: 11700 | R21: 6558
A22: 16,000/19,000 | B22: 20 | C22: 12.5 | D22: 12.4 | E22: C45MBCAQ18XA3 | F22: =VLOOKUP(E22,'Paste bid here'!A:F,6,FALSE) -> #N/A | G22: C37MAHAQ18AA3 | H22: =VLOOKUP(G22,'Paste bid here'!A:F,6,FALSE) -> #N/A | I22: 1/4" x 1/2" | J22: 98.42' | K22: .16 Oz/Ft | L22: 65.62' | M22: 19A / 20A | N22: 20A | O22: 14000 | P22: 17000 | Q22: 14000 | R22: 9879
A23: 23,500/25,000 | B23: 20.8 | C23: 12 | D23: 11.6 | E23: C45MBCAQ24XA3 | F23: =VLOOKUP(E23,'Paste bid here'!A:F,6,FALSE) -> #N/A | G23: C37MAHAQ24AA3 | H23: =VLOOKUP(G23,'Paste bid here'!A:F,6,FALSE) -> #N/A | I23: 3/8" x 5/8" | J23: 164.04' | K23: .32 Oz/Ft | L23: 82.02' | M23: 24.9A / 25A | N23: 25A | O23: 17300 | P23: 23800 | Q23: 21000 | R23: 13293
A24: Ceiling Cassette Grille for 9K, 12K & 18K BTU | F24: C45MBCQ01XXX3 | G24: =VLOOKUP(F24,'Paste bid here'!A:F,6,FALSE) -> #N/A | H24: Ceiling Cassette Grille for 24K, 36K & 48K BTU | M24: C45MBCQ02XXX4 | N24: =VLOOKUP(M24,'Paste bid here'!A:F,6,FALSE) -> #N/A | R24: [Required on all sizes and Sold Separately]
A25: Performance™ Series One-Way Ceiling Cassette 1:1 Heat Pump Systems
A26: 6,500 / 7,100 | B26: 22 | C26: 15.2 | D26: 12 | E26: C45MCCAQ06XA3 | F26: =VLOOKUP(E26,'Paste bid here'!A:F,6,FALSE) -> #N/A | G26: C37MAHAQ06AA3 | H26: =VLOOKUP(G26,'Paste bid here'!A:F,6,FALSE) -> #N/A | I26: 1/4" x 3/8" | J26: 82.02' | K26: .16 Oz/Ft | L26: 49.21' | M26: 12A / 15A | N26: 15A | O26: 6400 | P26: 8100 | Q26: 11200 | R26: 6483
A27: 9,000 / 10,900 | B27: 24 | C27: 14.7 | D27: 12.2 | E27: C45MCCAQ12XA3 | F27: =VLOOKUP(E27,'Paste bid here'!A:F,6,FALSE) -> #N/A | G27: C37MAHAQ09AA3 | H27: =VLOOKUP(G27,'Paste bid here'!A:F,6,FALSE) -> #N/A | I27: 1/4" x 3/8" | J27: 82.02' | K27: .16 Oz/Ft | L27: 49.21' | M27: 15A / 15A | N27: 15A | O27: 8600 | P27: 10600 | Q27: 11200 | R27: 6483
A28: 12,000 / 12,500 | B28: 23 | C28: 13 | D28: 10.2 | E28: C45MCCAQ12XA3 | F28: =VLOOKUP(E28,'Paste bid here'!A:F,6,FALSE) -> #N/A | G28: C37MAHAQ12AA3 | H28: =VLOOKUP(G28,'Paste bid here'!A:F,6,FALSE) -> #N/A | I28: 1/4" x 3/8" | J28: 82.02' | K28: .16 Oz/Ft | L28: 49.21' | M28: 15A / 15A | N28: 15A | O28: 8600 | P28: 11500 | Q28: 11900 | R28: 6558
A29: 16,700 / 20,000 | B29: 20.7 | C29: 12.5 | D29: 12.2 | E29: C45MCCAQ18XA3 | F29: =VLOOKUP(E29,'Paste bid here'!A:F,6,FALSE) -> #N/A | G29: C37MAHAQ18AA3 | H29: =VLOOKUP(G29,'Paste bid here'!A:F,6,FALSE) -> #N/A | I29: 1/4" x 1/2" | J29: 98.42' | K29: .16 Oz/Ft | L29: 65.62' | M29: 19A / 20A | N29: 20A | O29: 14500 | P29: 17500 | Q29: 14500 | R29: 10289
A30: One-Way Cassette units include grill | F30: IDU Capacity select via dip switch and must match ODU size
A31: Performance™ Series Low Static Slim-Ducted 1:1 Heat Pump Systems
A32: 6,500/8,000 | B32: 21.5 | C32: 14.5 | D32: 13.8 | E32: C45MBDAQ06XA3 | F32: =VLOOKUP(E32,'Paste bid here'!A:F,6,FALSE) -> #N/A | G32: C37MAHAQ06AA3 | H32: =VLOOKUP(G32,'Paste bid here'!A:F,6,FALSE) -> #N/A | I32: 1/4" x 3/8" | J32: 82.02' | K32: .16 Oz/Ft | L32: 49.21' | M32: 12A / 15A | N32: 15A | O32: 6302 | P32: 7800 | Q32: 10448 | R32: 7387
A33: 9,000/10,000 | B33: 21.5 | C33: 13.5 | D33: 12.5 | E33: C45MBDAQ12XA3 | F33: =VLOOKUP(E33,'Paste bid here'!A:F,6,FALSE) -> #N/A | G33: C37MAHAQ09AA3 | H33: =VLOOKUP(G33,'Paste bid here'!A:F,6,FALSE) -> #N/A | I33: 1/4" x 3/8" | J33: 82.02' | K33: .16 Oz/Ft | L33: 49.21' | M33: 15A / 15A | N33: 15A | O33: 9704 | P33: 11200 | Q33: 11147 | R33: 6056
A34: 12,000/12,500 | B34: 20 | C34: 12 | D34: 10.2 | E34: C45MBDAQ12XA3 | F34: =VLOOKUP(E34,'Paste bid here'!A:F,6,FALSE) -> #N/A | G34: C37MAHAQ12AA3 | H34: =VLOOKUP(G34,'Paste bid here'!A:F,6,FALSE) -> #N/A | I34: 1/4" x 3/8" | J34: 82.02' | K34: .16 Oz/Ft | L34: 49.21' | M34: 15A / 15A | N34: 15A | O34: 10256 | P34: 11800 | Q34: 11430 | R34: 6220
A35: 17,000/19,000 | B35: 18 | C35: 12 | D35: 10.8 | E35: C45MBDAQ18XA3 | F35: =VLOOKUP(E35,'Paste bid here'!A:F,6,FALSE) -> #N/A | G35: C37MAHAQ18AA3 | H35: =VLOOKUP(G35,'Paste bid here'!A:F,6,FALSE) -> #N/A | I35: 1/4" x 1/2" | J35: 98.42' | K35: .16 Oz/Ft | L35: 65.62' | M35: 19A / 20A | N35: 20A | O35: 15917 | P35: 18000 | Q35: 14525 | R35: 10543
A36: Performance™ Series High Static Slim-Ducted 1:1 Heat Pump Systems
A37: 9,000/9,900 | B37: 20.6 | C37: 14 | D37: 13.8 | E37: C45MBDAQ12XH3 | F37: =VLOOKUP(E37,'Paste bid here'!A:F,6,FALSE) -> #N/A | G37: C37MAHAQ09AA3 | H37: =VLOOKUP(G37,'Paste bid here'!A:F,6,FALSE) -> #N/A | I37: 1/4" x 3/8" | J37: 82.02' | K37: .16 Oz/Ft | L37: 49.21' | M37: 15A / 15A | N37: 15A | O37: 8448 | P37: 11900 | Q37: 11048 | R37: 6060
A38: 12,000/12,000 | B38: 20.2 | C38: 12 | D38: 10.6 | E38: C45MBDAQ12XH3 | F38: =VLOOKUP(E38,'Paste bid here'!A:F,6,FALSE) -> #N/A | G38: C37MAHAQ12AA3 | H38: =VLOOKUP(G38,'Paste bid here'!A:F,6,FALSE) -> #N/A | I38: 1/4" x 3/8" | J38: 82.02' | K38: .16 Oz/Ft | L38: 49.21' | M38: 15A / 15A | N38: 15A | O38: 10171 | P38: 12000 | Q38: 11089 | R38: 6537
A39: 24,000/26,000 | B39: 19.2 | C39: 12 | D39: 11.7 | E39: C45MBDAQ24XH3 | F39: =VLOOKUP(E39,'Paste bid here'!A:F,6,FALSE) -> #N/A | G39: C37MAHAQ24AA3 | H39: =VLOOKUP(G39,'Paste bid here'!A:F,6,FALSE) -> #N/A | I39: 3/8" x 5/8" | J39: 164.04' | K39: .32 Oz/Ft | L39: 82.02' | M39: 24.9A / 25A | N39: 25A | O39: 19339 | P39: 24000 | Q39: 20858 | R39: 13979
A40: Performance™ Series Floor Console 1:1 Heat Pump Systems
...

Sheet DUCTLESS Multi-Zone
B1: R454B Multi-Zone Quick Reference Guide | R1: Ductless Systems
A2: Outdoor Unit With | B2: Price | C2: Max Zones | D2: Max Heating Capacity Btu's | G2: Max Cooling Btu's at 5F | I2: Port Combinations | L2: Max | M2: Max Total | N2: Pre- | P2: MCA | Q2: MOCP | R2: Recommended Fuse Size
A3: Base Pan Heater | L3: Line Set | M3: Line Set | N3: Charge | O3: Max Lift
D4: @5F [-15C] | E4: @-13F [-25C] | F4: @-22F [-30C] | G4: @ 95°F | H4: @109F [43C] | I4: Liquid | J4: Suction | L4: Per Zone | M4: Length | N4: Length
A5: This Sheet is not intended to replace the Installation Instructions. It is a reference guide only. Always read through the Installation Instructions.
A6: Infinity™ Series High Heat Multi-Zone Heat Pump Systems
A7: C37MGHAQ18CA3 | B7: =VLOOKUP(A7,'Paste bid here'!A:F,6,FALSE) -> #N/A | C7: 3 | D7: 19000 | E7: 13600 | F7: 11000 | G7: 19000 | H7: 24000 | I7: 3 @ 1/4" | J7: 3 @ 3/8" | L7: 98.4' | M7: 196.9' | N7: 73.8' | O7: 49' | P7: 17.5 | Q7: 20 | R7: 20
A8: C37MGHAQ24DA3 | B8: =VLOOKUP(A8,'Paste bid here'!A:F,6,FALSE) -> #N/A | C8: 4 | D8: 25000 | E8: 17000 | F8: 14000 | G8: 24000 | H8: 32000 | I8: 4 @ 1/4" | J8: 3 @ 3/8" + 1 @ 1/2" | L8: 114.8' | M8: 262.5' | N8: 98.4' | O8: 49' | P8: 30 | Q8: 35 | R8: 35
A9: C37MGHAQ30EA3 | B9: =VLOOKUP(A9,'Paste bid here'!A:F,6,FALSE) -> #N/A | C9: 5 | D9: 36000 | E9: 28000 | F9: 22400 | G9: 30000 | H9: 39000 | I9: 5 @ 1/4" | J9: 3 @ 3/8" + 2 @ 1/2" | L9: 114.8' | M9: 262.5' | N9: 123' | O9: 49' | P9: 37 | Q9: 40 | R9: 40
A10: C37MGHAQ36EA3 | B10: =VLOOKUP(A10,'Paste bid here'!A:F,6,FALSE) -> #N/A | C10: 5 | D10: 36000 | E10: 28000 | F10: 22400 | G10: 36000 | H10: 39000 | I10: 5 @ 1/4" | J10: 3 @ 3/8" + 2 @ 1/2" | L10: 114.8' | M10: 262.5' | N10: 123' | O10: 65' | P10: 37 | Q10: 40 | R10: 40
A11: C37MGHAQ48FA3 | B11: =VLOOKUP(A11,'Paste bid here'!A:F,6,FALSE) -> #N/A | C11: 6 | D11: 47000 | E11: 30000 | F11: 25000 | G11: 47000 | H11: 45000 | I11: 6 @ 1/4" | J11: 4 @ 3/8" + 2 @ 1/2" | L11: 114.8' | M11: 262.5' | N11: 147.6' | O11: 65' | P11: 37 | Q11: 40 | R11: 40
A12: C37MGHAQ55FA3 | B12: =VLOOKUP(A12,'Paste bid here'!A:F,6,FALSE) -> #N/A | C12: 6 | D12: 47000 | E12: 32000 | F12: 26400 | G12: 51000 | H12: 46000 | I12: 6 @ 1/4" | J12: 4 @ 3/8" + 2 @ 1/2" | L12: 114.8' | M12: 262.5' | N12: 147.6' | O12: 65' | P12: 39.5 | Q12: 40 | R12: 40
A13: Performance™ Series Multi-Zone Heat Pump Systems
A14: C37MGRAQ18CA3 | B14: =VLOOKUP(A14,'Paste bid here'!A:F,6,FALSE) -> #N/A | C14: 3 | D14: 13500 | E14: 8200 | G14: 18000 | H14: 18800 | I14: 3 @ 1/4" | J14: 3 @ 3/8" | L14: 98.4' | M14: 196.9' | N14: 73.8' | O14: 49.21' | P14: 16 | Q14: 20 | R14: 20
A15: C37MGRAQ24DA3 | B15: =VLOOKUP(A15,'Paste bid here'!A:F,6,FALSE) -> #N/A | C15: 4 | D15: 18000 | E15: 12000 | G15: 24000 | H15: 27400 | I15: 4 @ 1/4" | J15: 3 @ 3/8" + 1 @ 1/2" | L15: 114.8' | M15: 262.5' | N15: 98.4' | O15: 49.21' | P15: 23 | Q15: 25 | R15: 25
A16: C37MGRAQ30EA3 | B16: =VLOOKUP(A16,'Paste bid here'!A:F,6,FALSE) -> #N/A | C16: 5 | D16: 26000 | E16: 17500 | G16: 30000 | H16: 30600 | I16: 5 @ 1/4" | J16: 3 @ 3/8" + 2 @ 1/2" | L16: 114.8' | M16: 262.5' | N16: 123' | O16: 49.21' | P16: 30.5 | Q16: 35 | R16: 35
A17: C37MGRAQ36EA3 | B17: =VLOOKUP(A17,'Paste bid here'!A:F,6,FALSE) -> #N/A | C17: 5 | D17: 26000 | E17: 17500 | G17: 36000 | H17: 30600 | I17: 5 @ 1/4" | J17: 3 @ 3/8" + 2 @ 1/2" | L17: 114.8' | M17: 262.5' | N17: 123' | O17: 49.21' | P17: 30.5 | Q17: 35 | R17: 35
A18: C37MGRAQ48FA3 | B18: =VLOOKUP(A18,'Paste bid here'!A:F,6,FALSE) -> #N/A | C18: 6 | D18: 36000 | E18: 27000 | G18: 47000 | H18: 42000 | I18: 6 @ 1/4" | J18: 4 @ 3/8" + 2 @ 1/2" | L18: 114.8' | M18: 262.5' | N18: 147.6' | O18: 49.21' | P18: 34 | Q18: 40 | R18: 40
A19: C37MGRAQ55FA3 | B19: =VLOOKUP(A19,'Paste bid here'!A:F,6,FALSE) -> #N/A | C19: 6 | D19: 39000 | E19: 27800 | G19: 60000 | H19: 46000 | I19: 6 @ 1/4" | J19: 4 @ 3/8" + 2 @ 1/2" | L19: 114.8' | M19: 262.5' | N19: 147.6' | O19: 49.21' | P19: 36 | Q19: 40 | R19: 40
A20: Indoor Unit Types, Models, and Approved Btu/hr Combinations
A34: Btu/hr | B34: HIGH WALL | F34: 4-WAY CEILING CASSETTES | I34: ONE-WAY CEILING | K34: STANDARD STATIC | M34: HIGH STATIC | O34: FLOOR / CEILING | Q34: MULTI-POISE AIR HANDLER (AHU)
B35: INFINITY™ | D35: PERFORMANCE™ | I35: CASSETTES | K35: SLIM DUCTED | M35: SLIM DUCTED | O35: CONSOLE
A36: 6K | B36: C45MPHAQ06XA3 | C36: =VLOOKUP(B36,'Paste bid here'!A:F,6,FALSE) -> #N/A | D36: C45MAHAQ06XA3 | E36: =VLOOKUP(D36,'Paste bid here'!A:F,6,FALSE) -> #N/A | I36: C45MCCAQ06XA3 | J36: =VLOOKUP(I36,'Paste bid here'!A:F,6,FALSE) -> #N/A | K36: C45MBDAQ06XA3 | L36: =VLOOKUP(K36,'Paste bid here'!A:F,6,FALSE) -> #N/A
A37: 9K | B37: C45MPHAQ09XA3 | C37: =VLOOKUP(B37,'Paste bid here'!A:F,6,FALSE) -> #N/A | D37: C45MAHAQ09XA3 | E37: =VLOOKUP(D37,'Paste bid here'!A:F,6,FALSE) -> #N/A | F37: C45MBCAQ12XA3 | H37: =VLOOKUP(F37,'Paste bid here'!A:F,6,FALSE) -> #N/A | I37: C45MCCAQ12XA3 | J37: =VLOOKUP(I37,'Paste bid here'!A:F,6,FALSE) -> #N/A | K37: C45MBDAQ12XA3 | L37: =VLOOKUP(K37,'Paste bid here'!A:F,6,FALSE) -> #N/A | M37: C45MBDAQ12XH3 | N37: =VLOOKUP(M37,'Paste bid here'!A:F,6,FALSE) -> #N/A | O37: C45MBFAQ09XA3 | P37: =VLOOKUP(O37,'Paste bid here'!A:F,6,FALSE) -> #N/A
A38: 12K | B38: C45MPHAQ12XA3 | C38: =VLOOKUP(B38,'Paste bid here'!A:F,6,FALSE) -> #N/A | D38: C45MAHAQ12XA3 | E38: =VLOOKUP(D38,'Paste bid here'!A:F,6,FALSE) -> #N/A | F38: C45MBCAQ12XA3 | H38: =VLOOKUP(F38,'Paste bid here'!A:F,6,FALSE) -> #N/A | I38: C45MCCAQ12XA3 | J38: =VLOOKUP(I38,'Paste bid here'!A:F,6,FALSE) -> #N/A | K38: C45MBDAQ12XA3 | L38: =VLOOKUP(K38,'Paste bid here'!A:F,6,FALSE) -> #N/A | M38: C45MBDAQ12XH3 | N38: =VLOOKUP(M38,'Paste bid here'!A:F,6,FALSE) -> #N/A | O38: C45MBFAQ12XA3 | P38: =VLOOKUP(O38,'Paste bid here'!A:F,6,FALSE) -> #N/A
A39: 16K | O39: C45MBFAQ16XA3 | P39: =VLOOKUP(O39,'Paste bid here'!A:F,6,FALSE) -> #N/A
A40: 18K | B40: C45MPHAQ18XA3 | C40: =VLOOKUP(B40,'Paste bid here'!A:F,6,FALSE) -> #N/A | D40: C45MAHAQ18XA3 | E40: =VLOOKUP(D40,'Paste bid here'!A:F,6,FALSE) -> #N/A | F40: C45MBCAQ18XA3 | H40: =VLOOKUP(F40,'Paste bid here'!A:F,6,FALSE) -> #N/A | I40: C45MCCAQ18XA3 | J40: =VLOOKUP(I40,'Paste bid here'!A:F,6,FALSE) -> #N/A | K40: C45MBDAQ18XA3 | L40: =VLOOKUP(K40,'Paste bid here'!A:F,6,FALSE) -> #N/A | M40: C45MBDAQ18XH3 | N40: =VLOOKUP(M40,'Paste bid here'!A:F,6,FALSE) -> #N/A | Q40: C45MBAAQ18XB3 | R40: =VLOOKUP(Q40,'Paste bid here'!A:F,6,FALSE) -> #N/A
A41: 24K | D41: C45MAHAQ24XA3 | E41: =VLOOKUP(D41,'Paste bid here'!A:F,6,FALSE) -> #N/A | F41: C45MBCAQ24XA3 | H41: =VLOOKUP(F41,'Paste bid here'!A:F,6,FALSE) -> #N/A | M41: C45MBDAQ24XH3 | N41: =VLOOKUP(M41,'Paste bid here'!A:F,6,FALSE) -> #N/A | Q41: C45MBAAQ24XB3 | R41: =VLOOKUP(Q41,'Paste bid here'!A:F,6,FALSE) -> #N/A
A42: 30K | D42: C45MAHAQ30XA3 | E42: =VLOOKUP(D42,'Paste bid here'!A:F,6,FALSE) -> #N/A | Q42: C45MBAAQ30XB3 | R42: =VLOOKUP(Q42,'Paste bid here'!A:F,6,FALSE) -> #N/A
A43: 33K | D43: C45MAHAQ33XA3 | E43: =VLOOKUP(D43,'Paste bid here'!A:F,6,FALSE) -> #N/A
A44: 36K | D44: C45MAHAQ36XA3 | E44: =VLOOKUP(D44,'Paste bid here'!A:F,6,FALSE) -> #N/A | Q44: C45MBAAQ36XB3 | R44: =VLOOKUP(Q44,'Paste bid here'!A:F,6,FALSE) -> #N/A
A45: Installation Notes:
A46: Port adaptors included with the outdoor units and no branch boxes required.
A47: 10' minimum line length require per zone.
A48: Minimum 2 zones must be connected.
A49: Up to 2 AHUs can be used for the following combinations only: 18+18, 18+24, 18+30, 18+36, 24+24, 24+30, 24+36. In the case that 2 AHU units are selected, no other units may be connected to the outdoor unit, regardless of remaining ports or capacity availability.
A50: When a 30k or 36k AHU is utilized with a Multi-Zone ODU, 500 grams (17.6 Oz) of additional refrigerant should be added to the system.
A51: One-Way Cassette sizing is determined by capacity rotary swith on IDU.
A52: Wi-Fi Kits and Wire Remote Controllers compatible with single or multi-zone as per IDU compatibility.
R53: =#REF! -> #REF!

Sheet Paste bid here
A1: CARRIER MASTER BID | B1: B069296 | C1: COPY CUSTOMER PRICING FROM THIS BID AND PASTE BID BELOW
